File: samples/m5s1.csv
Time measurement,Displacement,Primary force measurement,Composite strain,Flexure stress
(s),(mm),(N),(mm/mm),(MPa)
"0.00000","0.00000","-0.22820","0.00000","-0.05388"
"0.12000","0.00000","0.05867","0.00000","0.01385"
"0.24000","0.00016","0.81599","0.00001","0.19266"
"0.36000","0.00018","1.30203","0.00001","0.30742"
"0.48000","0.00019","1.01458","0.00001","0.23955"
"0.60000","0.00024","1.46113","0.00001","0.34499"
"0.72000","0.00038","2.34667","0.00001","0.55407"
"0.84000","0.00051","3.21513","0.00002","0.75913"
"0.96000","0.00062","4.13641","0.00002","0.97665"
"1.08000","0.00072","5.13579","0.00002","1.21262"
"1.20000","0.00083","6.10130","0.00003","1.44059"
"1.32000","0.00093","6.96214","0.00003","1.64384"
"1.44000","0.00102","7.69306","0.00003","1.81642"
"1.56000","0.00112","8.70048","0.00004","2.05428"
"1.68000","0.00123","9.54984","0.00004","2.25482"
"1.80000","0.00134","10.45608","0.00004","2.46880"
"1.92000","0.00142","11.95235","0.00004","2.82208"
"2.04000","0.00153","12.98710","0.00005","3.06640"
"2.16000","0.00163","13.89917","0.00005","3.28175"
"2.28000","0.00174","14.58621","0.00005","3.44396"
"2.40000","0.00182","16.04933","0.00006","3.78943"
"2.52000","0.00193","16.95877","0.00006","4.00415"
"2.64000","0.00204","18.20138","0.00006","4.29755"
"2.76000","0.00214","19.58635","0.00007","4.62455"
"2.88000","0.00225","20.23148","0.00007","4.77688"
"3.00000","0.00233","21.27352","0.00007","5.02291"
"3.12000","0.00244","22.32922","0.00008","5.27218"
"3.24000","0.00254","23.44969","0.00008","5.53673"
"3.36000","0.00262","24.62249","0.00008","5.81364"
"3.48000","0.00273","25.33353","0.00009","5.98153"
"3.60000","0.00284","26.58931","0.00009","6.27803"
"3.72000","0.00295","27.71225","0.00009","6.54317"
"3.84000","0.00303","28.79171","0.00009","6.79804"
"3.96000","0.00313","30.06694","0.00010","7.09914"
"4.08000","0.00324","30.96698","0.00010","7.31165"
"4.20000","0.00332","32.02458","0.00010","7.56136"
"4.32000","0.00343","32.72620","0.00011","7.72702"
"4.44000","0.00354","33.82592","0.00011","7.98668"
"4.56000","0.00362","34.73813","0.00011","8.20206"
"4.68000","0.00372","35.97306","0.00012","8.49364"
"4.80000","0.00383","36.85358","0.00012","8.70154"
"4.92000","0.00394","38.11220","0.00012","8.99871"
"5.04000","0.00402","38.73165","0.00013","9.14497"
"5.16000","0.00412","39.82515","0.00013","9.40316"
"5.28000","0.00423","41.16465","0.00013","9.71943"
"5.40000","0.00434","41.70731","0.00014","9.84756"
"5.52000","0.00445","44.00244","0.00014","10.38946"
"5.64000","0.00455","43.88450","0.00014","10.36162"
"5.76000","0.00466","45.86085","0.00015","10.82826"
"5.88000","0.00477","46.23394","0.00015","10.91635"
"6.00000","0.00490","48.42602","0.00015","11.43392"
"6.12000","0.00498","48.76546","0.00016","11.51407"
"6.24000","0.00509","50.32064","0.00016","11.88126"
"6.36000","0.00520","51.20167","0.00016","12.08928"
"6.48000","0.00528","52.60869","0.00016","12.42150"
"6.60000","0.00538","53.73913","0.00017","12.68841"
"6.72000","0.00549","55.09976","0.00017","13.00967"
"6.84000","0.00560","55.74632","0.00017","13.16233"
"6.96000","0.00568","57.06231","0.00018","13.47304"
"7.08000","0.00579","58.19707","0.00018","13.74097"
"7.20000","0.00589","59.51367","0.00018","14.05184"
"7.32000","0.00597","60.12397","0.00019","14.19594"
"7.44000","0.00608","61.65783","0.00019","14.55810"
"7.56000","0.00619","62.27123","0.00019","14.70293"
"7.68000","0.00628","63.85706","0.00020","15.07736"
"7.80000","0.00637","64.75347","0.00020","15.28901"
"7.92000","0.00648","65.89487","0.00020","15.55851"
"8.04000","0.00656","66.99802","0.00020","15.81898"
"8.16000","0.00667","67.70070","0.00021","15.98489"
"8.28000","0.00678","69.16621","0.00021","16.33091"
"8.40000","0.00688","70.49570","0.00021","16.64482"
"8.52000","0.00699","71.52072","0.00022","16.88684"
"8.64000","0.00708","73.06527","0.00022","17.25152"
"8.76000","0.00718","74.17192","0.00022","17.51281"
"8.88000","0.00729","75.38029","0.00023","17.79812"
"9.00000","0.00739","76.35554","0.00023","18.02839"
"9.12000","0.00747","77.80422","0.00023","18.37044"
"9.24000","0.00758","78.70602","0.00024","18.58337"
"9.36000","0.00769","79.85202","0.00024","18.85395"
"9.48000","0.00777","80.98477","0.00024","19.12140"
"9.60000","0.00788","81.96162","0.00025","19.35205"
"9.72000","0.00798","83.35382","0.00025","19.68076"
"9.84000","0.00806","84.57184","0.00025","19.96835"
"9.96000","0.00817","86.23173","0.00025","20.36027"
"10.08000","0.00825","87.07595","0.00026","20.55960"
"10.20000","0.00833","87.62300","0.00026","20.68876"
"10.32000","0.00844","88.61658","0.00026","20.92336"
"10.44000","0.00852","89.65257","0.00027","21.16797"
"10.56000","0.00862","91.26008","0.00027","21.54752"
"10.68000","0.00873","92.43850","0.00027","21.82576"
"10.80000","0.00884","94.18981","0.00028","22.23926"
"10.92000","0.00895","95.33470","0.00028","22.50958"
"11.04000","0.00903","96.61166","0.00028","22.81109"
"11.16000","0.00913","97.46229","0.00028","23.01193"
"11.28000","0.00924","98.83942","0.00029","23.33708"
"11.40000","0.00935","100.32277","0.00029","23.68732"
"11.52000","0.00945","101.41145","0.00029","23.94437"
"11.64000","0.00954","102.75918","0.00030","24.26258"
"11.76000","0.00964","104.17298","0.00030","24.59640"
"11.88000","0.00976","105.50910","0.00030","24.91187"
"12.00000","0.00988","107.01784","0.00031","25.26810"
"12.12000","0.00999","108.29931","0.00031","25.57067"
"12.24000","0.01010","109.51740","0.00031","25.85827"
"12.36000","0.01018","110.77335","0.00032","26.15482"
"12.48000","0.01029","111.86985","0.00032","26.41371"
"12.60000","0.01039","112.85217","0.00032","26.64565"
"12.72000","0.01050","114.14913","0.00033","26.95188"
"12.84000","0.01058","115.72083","0.00033","27.32297"
"12.96000","0.01069","117.07822","0.00033","27.64347"
"13.08000","0.01079","118.26270","0.00034","27.92314"
"13.20000","0.01087","119.45355","0.00034","28.20431"
"13.32000","0.01098","120.81783","0.00034","28.52643"
"13.44000","0.01109","122.04808","0.00035","28.81691"
"13.56000","0.01117","123.22196","0.00035","29.09407"
"13.68000","0.01128","124.42571","0.00035","29.37829"
"13.80000","0.01138","125.57188","0.00035","29.64891"
"13.92000","0.01146","126.74776","0.00036","29.92655"
"14.04000","0.01157","128.23235","0.00036","30.27708"
"14.16000","0.01165","129.28741","0.00036","30.52619"
"14.28000","0.01176","131.02116","0.00037","30.93555"
"14.40000","0.01184","131.82158","0.00037","31.12454"
"14.52000","0.01195","133.34123","0.00037","31.48335"
"14.64000","0.01205","134.22757","0.00038","31.69262"
"14.76000","0.01215","135.80609","0.00038","32.06533"
"14.88000","0.01225","137.22388","0.00038","32.40008"
"15.00000","0.01235","138.58653","0.00038","32.72182"
"15.12000","0.01246","140.13802","0.00039","33.08814"
"15.24000","0.01256","141.38383","0.00039","33.38229"
"15.36000","0.01267","142.69856","0.00039","33.69271"
"15.48000","0.01278","144.40205","0.00040","34.09493"
"15.60000","0.01288","145.83740","0.00040","34.43383"
"15.72000","0.01296","147.07959","0.00040","34.72712"
"15.84000","0.01307","148.36221","0.00041","35.02996"
"15.96000","0.01315","149.80643","0.00041","35.37096"
"16.08000","0.01326","150.40359","0.00041","35.51196"
"16.20000","0.01334","151.85954","0.00042","35.85572"
"16.32000","0.01344","153.33160","0.00042","36.20329"
"16.44000","0.01353","155.00505","0.00042","36.59841"
"16.56000","0.01363","155.49956","0.00042","36.71517"
"16.68000","0.01374","156.91196","0.00043","37.04865"
"16.80000","0.01382","158.69835","0.00043","37.47044"
"16.92000","0.01393","160.08577","0.00043","37.79803"
"17.04000","0.01404","161.53217","0.00044","38.13954"
"17.16000","0.01413","162.58875","0.00044","38.38901"
"17.28000","0.01422","164.17424","0.00044","38.76336"
"17.40000","0.01433","165.28030","0.00045","39.02451"
"17.52000","0.01444","167.22357","0.00045","39.48334"
"17.64000","0.01454","168.79027","0.00045","39.85326"
"17.76000","0.01465","169.30078","0.00046","39.97379"
"17.88000","0.01476","170.85835","0.00046","40.34155"
"18.00000","0.01487","172.39108","0.00046","40.70345"
"18.12000","0.01497","174.62996","0.00047","41.23207"
"18.24000","0.01508","176.34132","0.00047","41.63614"
"18.36000","0.01519","177.43475","0.00047","41.89431"
"18.48000","0.01529","178.96492","0.00048","42.25560"
"18.60000","0.01540","180.18138","0.00048","42.54282"
"18.72000","0.01548","181.60849","0.00048","42.87978"
"18.84000","0.01559","183.06541","0.00049","43.22378"
"18.96000","0.01570","184.31067","0.00049","43.51780"
"19.08000","0.01578","186.19759","0.00049","43.96332"
"19.20000","0.01588","187.42946","0.00049","44.25418"
"19.32000","0.01599","189.17813","0.00050","44.66706"
"19.44000","0.01607","190.15967","0.00050","44.89881"
"19.56000","0.01618","191.93417","0.00050","45.31779"
"19.68000","0.01629","192.80701","0.00051","45.52387"
"19.80000","0.01639","194.46266","0.00051","45.91479"
"19.92000","0.01647","195.44919","0.00051","46.14772"
"20.04000","0.01658","197.02242","0.00052","46.51918"
"20.16000","0.01666","198.03206","0.00052","46.75757"
"20.28000","0.01676","200.30220","0.00052","47.29357"
"20.40000","0.01685","200.61194","0.00052","47.36671"
"20.52000","0.01696","202.86432","0.00053","47.89852"
"20.64000","0.01706","204.14244","0.00053","48.20029"
"20.76000","0.01717","205.45509","0.00053","48.51023"
"20.88000","0.01728","206.62288","0.00054","48.78595"
"21.00000","0.01738","208.69807","0.00054","49.27593"
"21.12000","0.01749","209.74730","0.00054","49.52367"
"21.24000","0.01760","211.73700","0.00055","49.99345"
"21.36000","0.01768","212.92984","0.00055","50.27510"
"21.48000","0.01779","214.52594","0.00055","50.65195"
"21.60000","0.01789","215.87006","0.00056","50.96931"
"21.72000","0.01797","217.56982","0.00056","51.37065"
"21.84000","0.01808","218.51234","0.00056","51.59319"
"21.96000","0.01819","220.47148","0.00057","52.05576"
"22.08000","0.01827","221.51924","0.00057","52.30315"
"22.20000","0.01835","223.03050","0.00057","52.65998"
"22.32000","0.01846","224.03656","0.00057","52.89752"
"22.44000","0.01854","225.39911","0.00058","53.21923"
"22.56000","0.01864","226.74106","0.00058","53.53608"
"22.68000","0.01872","228.36569","0.00058","53.91967"
"22.80000","0.01883","230.04063","0.00059","54.31515"
"22.92000","0.01894","231.23370","0.00059","54.59684"
"23.04000","0.01902","232.49821","0.00059","54.89541"
"23.16000","0.01912","234.10176","0.00060","55.27402"
"23.28000","0.01923","235.80629","0.00060","55.67648"
"23.40000","0.01934","237.21184","0.00060","56.00835"
"23.52000","0.01945","239.16347","0.00061","56.46915"
"23.64000","0.01953","240.53868","0.00061","56.79385"
"23.76000","0.01963","241.89970","0.00061","57.11520"
"23.88000","0.01974","243.60837","0.00061","57.51864"
"24.00000","0.01985","244.99356","0.00062","57.84570"
"24.12000","0.01998","247.21278","0.00062","58.36968"
"24.24000","0.02009","248.83952","0.00063","58.75377"
"24.36000","0.02020","250.34357","0.00063","59.10889"
"24.48000","0.02030","251.97821","0.00063","59.49485"
"24.60000","0.02038","253.84145","0.00063","59.93478"
"24.72000","0.02049","255.28723","0.00064","60.27615"
"24.84000","0.02060","256.91663","0.00064","60.66087"
"24.96000","0.02069","258.18613","0.00064","60.96061"
"25.08000","0.02079","259.95831","0.00065","61.37904"
"25.20000","0.02089","261.44061","0.00065","61.72903"
"25.32000","0.02099","262.86240","0.00065","62.06473"
"25.44000","0.02108","264.21518","0.00066","62.38414"
"25.56000","0.02119","265.86478","0.00066","62.77362"
"25.68000","0.02130","267.50357","0.00066","63.16056"
"25.80000","0.02138","269.01093","0.00067","63.51646"
"25.92000","0.02148","270.59497","0.00067","63.89048"
"26.04000","0.02159","271.86246","0.00067","64.18974"
"26.16000","0.02167","273.55124","0.00067","64.58849"
"26.28000","0.02178","275.00058","0.00068","64.93069"
"26.40000","0.02186","276.23288","0.00068","65.22165"
"26.52000","0.02196","278.03281","0.00068","65.64663"
"26.64000","0.02204","279.37320","0.00069","65.96311"
"26.76000","0.02215","280.79736","0.00069","66.29938"
"26.88000","0.02225","282.43906","0.00069","66.68700"
"27.00000","0.02234","283.81107","0.00070","67.01094"
"27.12000","0.02245","285.78424","0.00070","67.47683"
"27.24000","0.02255","287.23233","0.00070","67.81874"
"27.36000","0.02266","288.97565","0.00071","68.23035"
"27.48000","0.02277","290.73950","0.00071","68.64682"
"27.60000","0.02288","291.92764","0.00071","68.92735"
"27.72000","0.02298","293.87708","0.00072","69.38764"
"27.84000","0.02309","295.33841","0.00072","69.73267"
"27.96000","0.02317","296.39438","0.00072","69.98200"
"28.08000","0.02328","298.45187","0.00072","70.46780"
"28.20000","0.02336","299.72214","0.00073","70.76772"
"28.32000","0.02346","301.53705","0.00073","71.19624"
"28.44000","0.02354","302.79370","0.00073","71.49295"
"28.56000","0.02362","303.95831","0.00074","71.76793"
"28.68000","0.02373","305.42871","0.00074","72.11510"
"28.80000","0.02384","306.97083","0.00074","72.47922"
"28.92000","0.02392","308.10782","0.00074","72.74767"
"29.04000","0.02403","309.93112","0.00075","73.17818"
"29.16000","0.02413","311.40762","0.00075","73.52679"
"29.28000","0.02424","313.29514","0.00075","73.97246"
"29.40000","0.02434","314.66687","0.00076","74.29634"
"29.52000","0.02443","316.44208","0.00076","74.71548"
"29.64000","0.02454","318.02127","0.00076","75.08835"
"29.76000","0.02464","319.70563","0.00077","75.48605"
"29.88000","0.02475","320.96036","0.00077","75.78230"
"30.00000","0.02486","322.63525","0.00077","76.17776"
"30.12000","0.02497","324.15643","0.00078","76.53693"
"30.24000","0.02507","326.01999","0.00078","76.97694"
"30.36000","0.02518","328.11792","0.00078","77.47228"
"30.48000","0.02530","329.79694","0.00079","77.86871"
"30.60000","0.02539","331.52475","0.00079","78.27667"
"30.72000","0.02549","332.77228","0.00079","78.57123"
"30.84000","0.02558","334.53262","0.00080","78.98686"
"30.96000","0.02569","336.04248","0.00080","79.34336"
"31.08000","0.02579","337.67502","0.00080","79.72882"
"31.20000","0.02589","339.10965","0.00081","80.06755"
"31.32000","0.02598","341.01337","0.00081","80.51704"
"31.44000","0.02609","342.45593","0.00081","80.85764"
"31.56000","0.02620","343.96432","0.00082","81.21379"
"31.68000","0.02628","345.67722","0.00082","81.61823"
"31.80000","0.02638","347.12009","0.00082","81.95891"
"31.92000","0.02649","348.83966","0.00082","82.36491"
"32.04000","0.02657","350.52621","0.00083","82.76313"
"32.16000","0.02668","352.26163","0.00083","83.17288"
"32.28000","0.02679","353.74988","0.00083","83.52427"
"32.40000","0.02689","355.20557","0.00084","83.86797"
"32.52000","0.02697","356.70380","0.00084","84.22173"
"32.64000","0.02708","358.82047","0.00084","84.72150"
"32.76000","0.02719","360.14243","0.00085","85.03362"
"32.88000","0.02730","361.97156","0.00085","85.46550"
"33.00000","0.02738","363.93573","0.00085","85.92927"
"33.12000","0.02748","365.42801","0.00086","86.28161"
"33.24000","0.02759","367.23843","0.00086","86.70907"
"33.36000","0.02769","368.95599","0.00086","87.11461"
"33.48000","0.02778","370.27631","0.00087","87.42635"
"33.60000","0.02788","372.07376","0.00087","87.85075"
"33.72000","0.02799","373.53943","0.00087","88.19681"
"33.84000","0.02807","375.35532","0.00087","88.62556"
"33.96000","0.02818","377.32953","0.00088","89.09169"
"34.08000","0.02829","378.56848","0.00088","89.38422"
"34.20000","0.02837","380.63098","0.00088","89.87120"
"34.32000","0.02847","381.98120","0.00089","90.19000"
"34.44000","0.02855","383.33038","0.00089","90.50856"
"34.56000","0.02863","384.58224","0.00089","90.80414"
"34.68000","0.02874","386.33704","0.00090","91.21846"
"34.80000","0.02882","387.93198","0.00090","91.59505"
"34.92000","0.02893","389.80441","0.00090","92.03715"
"35.04000","0.02904","391.49588","0.00090","92.43652"
"35.16000","0.02914","393.15698","0.00091","92.82873"
"35.28000","0.02922","393.96854","0.00091","93.02035"
"35.40000","0.02933","395.82724","0.00091","93.45921"
"35.52000","0.02944","397.89496","0.00092","93.94742"
"35.64000","0.02955","399.43289","0.00092","94.31054"
"35.76000","0.02963","401.47308","0.00092","94.79225"
"35.88000","0.02973","402.96945","0.00093","95.14556"
"36.00000","0.02984","404.78207","0.00093","95.57354"
"36.12000","0.02995","406.55759","0.00093","95.99276"
"36.24000","0.03005","408.13321","0.00094","96.36478"
"36.36000","0.03019","410.38278","0.00094","96.89593"
"36.48000","0.03029","412.28287","0.00094","97.34456"
"36.60000","0.03038","413.98770","0.00095","97.74709"
"36.72000","0.03048","415.38324","0.00095","98.07659"
"36.84000","0.03059","417.22287","0.00095","98.51095"
"36.96000","0.03070","418.97266","0.00096","98.92410"
"37.08000","0.03080","420.59180","0.00096","99.30639"
"37.20000","0.03088","422.07941","0.00096","99.65763"
"37.32000","0.03099","423.72089","0.00097","100.04520"
"37.44000","0.03110","425.61606","0.00097","100.49268"
"37.56000","0.03118","426.74957","0.00097","100.76031"
"37.68000","0.03129","428.81235","0.00097","101.24735"
"37.80000","0.03139","430.43903","0.00098","101.63143"
"37.92000","0.03147","431.68951","0.00098","101.92669"
"38.04000","0.03158","433.86057","0.00098","102.43929"
"38.16000","0.03169","435.24387","0.00099","102.76591"
"38.28000","0.03177","436.88742","0.00099","103.15397"
"38.40000","0.03188","438.42780","0.00099","103.51767"
"38.52000","0.03196","440.18066","0.00100","103.93154"
"38.64000","0.03206","441.46906","0.00100","104.23574"
"38.76000","0.03214","443.13916","0.00100","104.63007"
"38.88000","0.03225","444.81158","0.00100","105.02495"
"39.00000","0.03236","446.67590","0.00101","105.46514"
"39.12000","0.03246","448.15591","0.00101","105.81458"
"39.24000","0.03257","449.81619","0.00101","106.20660"
"39.36000","0.03268","451.75116","0.00102","106.66346"
"39.48000","0.03279","453.70810","0.00102","107.12552"
"39.60000","0.03289","455.25784","0.00102","107.49143"
"39.72000","0.03297","456.98196","0.00103","107.89851"
"39.84000","0.03308","458.81201","0.00103","108.33060"
"39.96000","0.03319","460.20328","0.00103","108.65910"
"40.08000","0.03327","462.28091","0.00104","109.14966"
"40.20000","0.03337","463.84735","0.00104","109.51951"
"40.32000","0.03348","465.31335","0.00104","109.86565"
"40.44000","0.03356","467.43256","0.00105","110.36601"
"40.56000","0.03367","468.76501","0.00105","110.68063"
"40.68000","0.03375","470.37430","0.00105","111.06059"
"40.80000","0.03383","471.72882","0.00105","111.38041"
"40.92000","0.03394","473.32645","0.00106","111.75763"
"41.04000","0.03403","475.04517","0.00106","112.16344"
"41.16000","0.03413","476.96741","0.00106","112.61730"
"41.28000","0.03423","478.20862","0.00107","112.91036"
"41.40000","0.03434","480.08017","0.00107","113.35226"
"41.52000","0.03444","482.15482","0.00107","113.84210"
"41.64000","0.03453","484.06894","0.00108","114.29405"
"41.76000","0.03463","485.46957","0.00108","114.62476"
"41.88000","0.03474","487.14337","0.00108","115.01996"
"42.00000","0.03485","488.93228","0.00109","115.44234"
"42.12000","0.03496","490.77780","0.00109","115.87808"
"42.24000","0.03506","492.93005","0.00109","116.38625"
"42.36000","0.03517","494.85486","0.00110","116.84072"
"42.48000","0.03528","496.52643","0.00110","117.23540"
"42.60000","0.03538","498.58340","0.00110","117.72108"
"42.72000","0.03549","500.39120","0.00111","118.14792"
"42.84000","0.03560","502.16141","0.00111","118.56588"
"42.96000","0.03570","503.81638","0.00111","118.95663"
"43.08000","0.03579","505.46667","0.00111","119.34629"
"43.20000","0.03589","507.29312","0.00112","119.77753"
"43.32000","0.03600","509.20764","0.00112","120.22958"
"43.44000","0.03608","510.95349","0.00112","120.64179"
"43.56000","0.03619","512.84167","0.00113","121.08761"
"43.68000","0.03629","514.36957","0.00113","121.44836"
"43.80000","0.03638","516.20953","0.00113","121.88280"
"43.92000","0.03648","517.83240","0.00114","122.26598"
"44.04000","0.03659","519.87689","0.00114","122.74870"
"44.16000","0.03668","521.24963","0.00114","123.07282"
"44.28000","0.03678","523.05811","0.00115","123.49982"
"44.40000","0.03688","524.59247","0.00115","123.86211"
"44.52000","0.03698","526.42487","0.00115","124.29475"
"44.64000","0.03707","528.20587","0.00115","124.71527"
"44.76000","0.03718","530.25208","0.00116","125.19840"
"44.88000","0.03726","531.28326","0.00116","125.44187"
"45.00000","0.03737","533.56628","0.00116","125.98092"
"45.12000","0.03747","535.67963","0.00117","126.47990"
"45.24000","0.03758","537.29889","0.00117","126.86223"
"45.36000","0.03769","538.85754","0.00117","127.23025"
"45.48000","0.03779","540.90356","0.00118","127.71333"
"45.60000","0.03788","542.63525","0.00118","128.12221"
"45.72000","0.03798","544.28741","0.00118","128.51230"
"45.84000","0.03809","546.43427","0.00119","129.01920"
"45.96000","0.03818","547.66400","0.00119","129.30956"
"46.08000","0.03828","549.92633","0.00119","129.84370"
"46.20000","0.03838","551.23840","0.00120","130.15350"
"46.32000","0.03846","553.04053","0.00120","130.57901"
"46.44000","0.03857","554.66699","0.00120","130.96303"
"46.56000","0.03865","556.06348","0.00120","131.29276"
"46.68000","0.03876","558.17969","0.00121","131.79242"
"46.80000","0.03884","559.24768","0.00121","132.04459"
"46.92000","0.03892","561.09064","0.00121","132.47972"
"47.04000","0.03903","563.16351","0.00122","132.96916"
"47.16000","0.03913","564.75879","0.00122","133.34583"
"47.28000","0.03924","566.59357","0.00122","133.77902"
"47.40000","0.03932","568.25800","0.00122","134.17201"
"47.52000","0.03943","569.89661","0.00123","134.55891"
"47.64000","0.03954","571.93054","0.00123","135.03915"
"47.76000","0.03964","573.87292","0.00123","135.49777"
"47.88000","0.03972","575.55463","0.00124","135.89484"
"48.00000","0.03983","577.75598","0.00124","136.41460"
"48.12000","0.03994","579.55023","0.00124","136.83824"
"48.24000","0.04004","581.40656","0.00125","137.27654"
"48.36000","0.04015","583.36279","0.00125","137.73843"
"48.48000","0.04026","585.22638","0.00125","138.17844"
"48.60000","0.04037","587.37042","0.00126","138.68468"
"48.72000","0.04050","589.50104","0.00126","139.18774"
"48.84000","0.04058","591.19373","0.00126","139.58740"
"48.96000","0.04069","592.69574","0.00127","139.94205"
"49.08000","0.04079","594.36865","0.00127","140.33704"
"49.20000","0.04090","596.18787","0.00127","140.76657"
"49.32000","0.04098","598.25055","0.00128","141.25360"
"49.44000","0.04109","599.87927","0.00128","141.63815"
"49.56000","0.04120","601.29797","0.00128","141.97313"
"49.68000","0.04128","603.20093","0.00129","142.42244"
"49.80000","0.04138","604.87805","0.00129","142.81842"
"49.92000","0.04149","606.72650","0.00129","143.25487"
"50.04000","0.04157","608.85254","0.00129","143.75684"
"50.16000","0.04168","610.28516","0.00130","144.09509"
"50.28000","0.04179","612.17712","0.00130","144.54181"
"50.40000","0.04188","613.90503","0.00130","144.94978"
"50.52000","0.04197","615.44092","0.00131","145.31242"
"50.64000","0.04208","617.10529","0.00131","145.70541"
"50.76000","0.04218","619.23889","0.00131","146.20917"
"50.88000","0.04227","620.78821","0.00132","146.57498"
"51.00000","0.04235","622.31891","0.00132","146.93640"
"51.12000","0.04246","624.25177","0.00132","147.39278"
"51.24000","0.04256","625.73035","0.00133","147.74188"
"51.36000","0.04265","627.89832","0.00133","148.25375"
"51.48000","0.04275","629.55585","0.00133","148.64513"
"51.60000","0.04286","631.33820","0.00133","149.06595"
"51.72000","0.04296","633.30023","0.00134","149.52922"
"51.84000","0.04307","635.08807","0.00134","149.95134"
"51.96000","0.04318","637.03143","0.00134","150.41019"
"52.08000","0.04329","638.76703","0.00135","150.81999"
"52.20000","0.04338","640.61285","0.00135","151.25580"
"52.32000","0.04347","642.32440","0.00135","151.65993"
"52.44000","0.04358","644.49280","0.00136","152.17191"
"52.56000","0.04366","645.91821","0.00136","152.50845"
"52.68000","0.04377","647.86023","0.00136","152.96700"
"52.80000","0.04385","649.60614","0.00137","153.37923"
"52.92000","0.04393","650.73621","0.00137","153.64604"
"53.04000","0.04404","652.76605","0.00137","154.12531"
"53.16000","0.04414","654.37244","0.00137","154.50459"
"53.28000","0.04422","656.22473","0.00138","154.94194"
"53.40000","0.04433","658.15637","0.00138","155.39803"
"53.52000","0.04444","660.04669","0.00138","155.84435"
"53.64000","0.04452","661.68176","0.00139","156.23041"
"53.76000","0.04463","663.50616","0.00139","156.66116"
"53.88000","0.04473","665.44379","0.00139","157.11867"
"54.00000","0.04484","667.63989","0.00140","157.63719"
"54.12000","0.04495","669.26721","0.00140","158.02142"
"54.24000","0.04504","671.31354","0.00140","158.50458"
"54.36000","0.04513","673.27917","0.00141","158.96869"
"54.48000","0.04524","675.39282","0.00141","159.46774"
"54.60000","0.04535","677.23499","0.00141","159.90269"
"54.72000","0.04546","679.32806","0.00142","160.39690"
"54.84000","0.04557","681.58594","0.00142","160.93001"
"54.96000","0.04570","683.56641","0.00142","161.39761"
"55.08000","0.04580","685.58990","0.00143","161.87538"
"55.20000","0.04588","687.28448","0.00143","162.27550"
"55.32000","0.04599","689.25806","0.00143","162.74147"
"55.44000","0.04610","690.92792","0.00144","163.13574"
"55.56000","0.04620","693.09546","0.00144","163.64754"
"55.68000","0.04629","694.52979","0.00144","163.98619"
"55.80000","0.04639","696.48248","0.00144","164.44725"
"55.92000","0.04650","698.31757","0.00145","164.88052"
"56.04000","0.04658","700.21643","0.00145","165.32887"
"56.16000","0.04669","701.78253","0.00145","165.69864"
"56.28000","0.04680","703.81964","0.00146","166.17963"
"56.40000","0.04688","705.82751","0.00146","166.65372"
"56.52000","0.04698","707.39484","0.00146","167.02377"
"56.64000","0.04709","709.37073","0.00147","167.49030"
"56.76000","0.04717","711.38690","0.00147","167.96634"
"56.88000","0.04728","713.24744","0.00147","168.40564"
"57.00000","0.04736","714.75836","0.00147","168.76237"
"57.12000","0.04746","716.47668","0.00148","169.16809"
"57.24000","0.04757","718.18878","0.00148","169.57234"
"57.36000","0.04767","720.42932","0.00148","170.10136"
"57.48000","0.04779","722.23828","0.00149","170.52847"
"57.60000","0.04789","724.44928","0.00149","171.05052"
"57.72000","0.04800","725.85016","0.00149","171.38127"
"57.84000","0.04808","727.90527","0.00150","171.86652"
"57.96000","0.04819","729.69025","0.00150","172.28796"
"58.08000","0.04829","731.49658","0.00150","172.71446"
"58.20000","0.04837","733.23346","0.00151","173.12456"
"58.32000","0.04848","734.85846","0.00151","173.50824"
"58.44000","0.04859","736.63513","0.00151","173.92773"
"58.56000","0.04867","738.55872","0.00152","174.38191"
"58.68000","0.04878","740.24890","0.00152","174.78098"
"58.80000","0.04886","742.01392","0.00152","175.19772"
"58.92000","0.04894","743.76038","0.00152","175.61008"
"59.04000","0.04905","745.16980","0.00153","175.94286"
"59.16000","0.04913","747.03418","0.00153","176.38306"
"59.28000","0.04923","748.55066","0.00153","176.74112"
"59.40000","0.04934","751.07587","0.00154","177.33734"
"59.52000","0.04944","752.92804","0.00154","177.77467"
"59.64000","0.04953","754.48260","0.00154","178.14172"
"59.76000","0.04963","756.43005","0.00155","178.60153"
"59.88000","0.04974","758.20135","0.00155","179.01976"
"60.00000","0.04982","760.14392","0.00155","179.47841"
"60.12000","0.04993","761.86438","0.00155","179.88463"
"60.24000","0.05004","764.15387","0.00156","180.42522"
"60.36000","0.05014","766.03986","0.00156","180.87051"
"60.48000","0.05025","767.83777","0.00156","181.29501"
"60.60000","0.05035","769.78558","0.00157","181.75491"
"60.72000","0.05044","771.62903","0.00157","182.19017"
"60.84000","0.05055","773.57428","0.00157","182.64948"
"60.96000","0.05068","775.30652","0.00158","183.05847"
"61.08000","0.05079","777.74725","0.00158","183.63477"
"61.20000","0.05089","779.67957","0.00158","184.09100"
"61.32000","0.05100","781.44751","0.00159","184.50842"
"61.44000","0.05108","783.32635","0.00159","184.95204"
"61.56000","0.05119","785.63177","0.00159","185.49638"
"61.68000","0.05129","787.59186","0.00160","185.95918"
"61.80000","0.05140","789.20898","0.00160","186.34100"
"61.92000","0.05148","791.14447","0.00160","186.79799"
"62.04000","0.05159","792.70087","0.00161","187.16547"
"62.16000","0.05167","794.86517","0.00161","187.67648"
"62.28000","0.05178","796.60748","0.00161","188.08788"
"62.40000","0.05188","798.43567","0.00162","188.51952"
"62.52000","0.05199","800.46625","0.00162","188.99896"
"62.64000","0.05207","802.06653","0.00162","189.37682"
"62.76000","0.05218","804.09802","0.00162","189.85646"
"62.88000","0.05226","805.81653","0.00163","190.26222"
"63.00000","0.05237","807.68719","0.00163","190.70392"
"63.12000","0.05245","809.32898","0.00163","191.09155"
"63.24000","0.05255","811.19171","0.00164","191.53137"
"63.36000","0.05266","813.01984","0.00164","191.96301"
"63.48000","0.05274","814.98285","0.00164","192.42650"
"63.60000","0.05285","817.02295","0.00165","192.90819"
"63.72000","0.05296","819.32794","0.00165","193.45242"
"63.84000","0.05306","821.35742","0.00165","193.93161"
"63.96000","0.05317","822.83374","0.00166","194.28018"
"64.08000","0.05325","824.58362","0.00166","194.69334"
"64.20000","0.05336","826.70172","0.00166","195.19345"
"64.32000","0.05346","828.87628","0.00166","195.70689"
"64.44000","0.05357","830.97357","0.00167","196.20209"
"64.56000","0.05368","832.50610","0.00167","196.56393"
"64.68000","0.05379","834.43207","0.00168","197.01868"
"64.80000","0.05387","836.28900","0.00168","197.45711"
"64.92000","0.05397","838.12994","0.00168","197.89178"
"65.04000","0.05405","839.84985","0.00168","198.29787"
"65.16000","0.05413","841.47723","0.00169","198.68211"
"65.28000","0.05424","843.29181","0.00169","199.11055"
"65.40000","0.05432","845.06964","0.00169","199.53032"
"65.52000","0.05443","846.98621","0.00170","199.98285"
"65.64000","0.05454","848.73016","0.00170","200.39461"
"65.76000","0.05463","850.71661","0.00170","200.86363"
"65.88000","0.05472","852.53278","0.00170","201.29245"
"66.00000","0.05483","854.66846","0.00171","201.79671"
"66.12000","0.05494","856.19781","0.00171","202.15781"
"66.24000","0.05504","858.26221","0.00171","202.64523"
"66.36000","0.05512","860.17035","0.00172","203.09576"
"66.48000","0.05523","861.83575","0.00172","203.48898"
"66.60000","0.05534","864.10266","0.00172","204.02423"
"66.72000","0.05545","866.21753","0.00173","204.52357"
"66.84000","0.05555","868.42474","0.00173","205.04472"
"66.96000","0.05566","870.21484","0.00173","205.46738"
"67.08000","0.05577","872.50964","0.00174","206.00922"
"67.20000","0.05590","874.61749","0.00174","206.50690"
"67.32000","0.05598","876.67572","0.00174","206.99287"
"67.44000","0.05609","878.57013","0.00175","207.44016"
"67.56000","0.05620","880.45599","0.00175","207.88544"
"67.68000","0.05629","882.73224","0.00175","208.42288"
"67.80000","0.05638","884.43353","0.00176","208.82457"
"67.92000","0.05649","886.36877","0.00176","209.28151"
"68.04000","0.05660","888.51471","0.00176","209.78818"
"68.16000","0.05668","890.21997","0.00177","210.19081"
"68.28000","0.05679","892.23627","0.00177","210.66689"
"68.40000","0.05689","893.92865","0.00177","211.06648"
"68.52000","0.05697","896.02087","0.00177","211.56047"
"68.64000","0.05708","897.98608","0.00178","212.02448"
"68.76000","0.05719","899.97638","0.00178","212.49442"
"68.88000","0.05729","901.83942","0.00178","212.93430"
"69.00000","0.05738","903.50916","0.00179","213.32854"
"69.12000","0.05748","905.20551","0.00179","213.72906"
"69.24000","0.05758","907.49683","0.00179","214.27007"
"69.36000","0.05767","909.34747","0.00180","214.70703"
"69.48000","0.05775","911.01483","0.00180","215.10071"
"69.60000","0.05786","913.18256","0.00180","215.61253"
"69.72000","0.05796","915.02142","0.00181","216.04671"
"69.84000","0.05807","917.36957","0.00181","216.60114"
"69.96000","0.05818","919.58453","0.00181","217.12411"
"70.08000","0.05829","921.18365","0.00182","217.50168"
"70.20000","0.05839","922.90503","0.00182","217.90813"
"70.32000","0.05847","925.04553","0.00182","218.41351"
"70.44000","0.05858","927.01318","0.00182","218.87810"
"70.56000","0.05869","929.00482","0.00183","219.34834"
"70.68000","0.05877","930.77301","0.00183","219.76584"
"70.80000","0.05887","932.29718","0.00183","220.12572"
"70.92000","0.05898","934.32898","0.00184","220.60544"
"71.04000","0.05906","936.23846","0.00184","221.05629"
"71.16000","0.05914","937.85291","0.00184","221.43748"
"71.28000","0.05922","938.98914","0.00184","221.70575"
"71.40000","0.05933","941.02991","0.00185","222.18761"
"71.52000","0.05944","943.64948","0.00185","222.80612"
"71.64000","0.05955","945.07056","0.00185","223.14165"
"71.76000","0.05962","946.83075","0.00186","223.55725"
"71.88000","0.05973","948.77698","0.00186","224.01677"
"72.00000","0.05984","951.06226","0.00186","224.55635"
"72.12000","0.05992","952.74384","0.00187","224.95340"
"72.24000","0.06003","954.68201","0.00187","225.41101"
"72.36000","0.06013","956.44659","0.00187","225.82765"
"72.48000","0.06024","958.56085","0.00188","226.32686"
"72.60000","0.06035","960.60632","0.00188","226.80981"
"72.72000","0.06046","962.92877","0.00188","227.35817"
"72.84000","0.06054","964.79596","0.00189","227.79903"
"72.96000","0.06064","966.73120","0.00189","228.25597"
"73.08000","0.06077","969.07245","0.00189","228.80876"
"73.20000","0.06088","971.12842","0.00190","229.29420"
"73.32000","0.06099","973.49762","0.00190","229.85359"
"73.44000","0.06110","975.74640","0.00190","230.38455"
"73.56000","0.06119","977.61115","0.00191","230.82484"
"73.68000","0.06129","979.59033","0.00191","231.29214"
"73.80000","0.06139","981.64899","0.00191","231.77821"
"73.92000","0.06150","983.19647","0.00192","232.14360"
"74.04000","0.06158","985.25073","0.00192","232.62863"
"74.16000","0.06169","987.12286","0.00192","233.07066"
"74.28000","0.06180","988.87177","0.00192","233.48360"
"74.40000","0.06189","991.09552","0.00193","234.00865"
"74.52000","0.06198","992.90887","0.00193","234.43680"
"74.64000","0.06209","995.57166","0.00193","235.06552"
"74.76000","0.06217","997.28058","0.00194","235.46901"
"74.88000","0.06228","999.07031","0.00194","235.89159"
"75.00000","0.06238","1000.85095","0.00194","236.31201"
"75.12000","0.06246","1002.81091","0.00195","236.77478"
"75.24000","0.06257","1004.72949","0.00195","237.22778"
"75.36000","0.06265","1006.66052","0.00195","237.68372"
"75.48000","0.06276","1008.18982","0.00195","238.04480"
"75.60000","0.06286","1010.65283","0.00196","238.62636"
"75.72000","0.06295","1012.11908","0.00196","238.97255"
"75.84000","0.06305","1014.69012","0.00196","239.57961"
"75.96000","0.06316","1016.45721","0.00197","239.99683"
"76.08000","0.06327","1018.57642","0.00197","240.49719"
"76.20000","0.06337","1020.93433","0.00197","241.05392"
"76.32000","0.06348","1022.53229","0.00198","241.43123"
"76.44000","0.06359","1024.75977","0.00198","241.95715"
"76.56000","0.06369","1026.57800","0.00198","242.38646"
"76.68000","0.06378","1028.69263","0.00199","242.88574"
"76.80000","0.06388","1030.77502","0.00199","243.37743"
"76.92000","0.06397","1032.65491","0.00199","243.82129"
"77.04000","0.06407","1034.44092","0.00200","244.24298"
"77.16000","0.06418","1036.54419","0.00200","244.73959"
"77.28000","0.06426","1038.18079","0.00200","245.12601"
"77.40000","0.06434","1039.79529","0.00200","245.50720"
"77.52000","0.06442","1041.61597","0.00201","245.93709"
"77.64000","0.06453","1043.28052","0.00201","246.33011"
"77.76000","0.06463","1045.39978","0.00201","246.83049"
"77.88000","0.06474","1046.90906","0.00202","247.18684"
"78.00000","0.06482","1049.08875","0.00202","247.70149"
"78.12000","0.06493","1051.15552","0.00202","248.18948"
"78.24000","0.06504","1053.46497","0.00203","248.73477"
"78.36000","0.06512","1054.93994","0.00203","249.08302"
"78.48000","0.06524","1057.24060","0.00203","249.62624"
"78.60000","0.06533","1059.21851","0.00203","250.09325"
"78.72000","0.06544","1061.37341","0.00204","250.60204"
"78.84000","0.06554","1063.37793","0.00204","251.07533"
"78.96000","0.06565","1065.52087","0.00204","251.58130"
"79.08000","0.06576","1067.53662","0.00205","252.05725"
"79.20000","0.06587","1069.74304","0.00205","252.57820"
"79.32000","0.06597","1071.89246","0.00205","253.08571"
"79.44000","0.06608","1074.49243","0.00206","253.69958"
"79.56000","0.06619","1076.46313","0.00206","254.16489"
"79.68000","0.06629","1078.40405","0.00206","254.62317"
"79.80000","0.06640","1080.48975","0.00207","255.11562"
"79.92000","0.06648","1082.60229","0.00207","255.61441"
"80.04000","0.06659","1084.39026","0.00207","256.03656"
"80.16000","0.06670","1086.48413","0.00208","256.53098"
"80.28000","0.06679","1088.39795","0.00208","256.98285"
"80.40000","0.06688","1090.20020","0.00208","257.40836"
"80.52000","0.06699","1092.43542","0.00209","257.93613"
"80.64000","0.06707","1094.41772","0.00209","258.40417"
"80.76000","0.06718","1096.59668","0.00209","258.91864"
"80.88000","0.06729","1098.44275","0.00210","259.35452"
"81.00000","0.06739","1100.50574","0.00210","259.84161"
"81.12000","0.06747","1102.43872","0.00210","260.29800"
"81.24000","0.06758","1104.29370","0.00210","260.73599"
"81.36000","0.06769","1106.55151","0.00211","261.26910"
"81.48000","0.06777","1108.05652","0.00211","261.62445"
"81.60000","0.06787","1109.97607","0.00211","262.07767"
"81.72000","0.06796","1111.82581","0.00212","262.51440"
"81.84000","0.06806","1113.50256","0.00212","262.91031"
"81.96000","0.06817","1115.38770","0.00212","263.35541"
"82.08000","0.06828","1117.78235","0.00213","263.92081"
"82.20000","0.06839","1120.09436","0.00213","264.46671"
"82.32000","0.06849","1122.24841","0.00213","264.97531"
"82.44000","0.06858","1124.30408","0.00214","265.46066"
"82.56000","0.06868","1126.28345","0.00214","265.92801"
"82.68000","0.06879","1127.90271","0.00214","266.31033"
"82.80000","0.06889","1130.25159","0.00215","266.86493"
"82.92000","0.06897","1132.11902","0.00215","267.30588"
"83.04000","0.06908","1133.86023","0.00215","267.71698"
"83.16000","0.06916","1135.99658","0.00215","268.22141"
"83.28000","0.06927","1137.65894","0.00216","268.61389"
"83.40000","0.06935","1139.48950","0.00216","269.04611"
"83.52000","0.06943","1141.29883","0.00216","269.47333"
"83.64000","0.06954","1143.00171","0.00217","269.87540"
"83.76000","0.06964","1144.71741","0.00217","270.28049"
"83.88000","0.06974","1147.15173","0.00217","270.85526"
"84.00000","0.06983","1148.77136","0.00217","271.23767"
"84.12000","0.06994","1150.68579","0.00218","271.68970"
"84.24000","0.07002","1152.81299","0.00218","272.19196"
"84.36000","0.07013","1154.99500","0.00218","272.70712"
"84.48000","0.07023","1156.74731","0.00219","273.12088"
"84.60000","0.07034","1158.92688","0.00219","273.63550"
"84.72000","0.07045","1161.32251","0.00219","274.20114"
"84.84000","0.07053","1163.21301","0.00220","274.64749"
"84.96000","0.07063","1165.69299","0.00220","275.23306"
"85.08000","0.07074","1167.43970","0.00220","275.64548"
"85.20000","0.07085","1169.78064","0.00221","276.19818"
"85.32000","0.07096","1171.82227","0.00221","276.68024"
"85.44000","0.07106","1174.15466","0.00221","277.23096"
"85.56000","0.07120","1176.51208","0.00222","277.78757"
"85.68000","0.07128","1178.79749","0.00222","278.32718"
"85.80000","0.07138","1180.61169","0.00222","278.75552"
"85.92000","0.07149","1183.13538","0.00223","279.35138"
"86.04000","0.07160","1185.14526","0.00223","279.82596"
"86.16000","0.07169","1186.96802","0.00223","280.25632"
"86.28000","0.07179","1189.22119","0.00224","280.78833"
"86.40000","0.07189","1191.26648","0.00224","281.27124"
"86.52000","0.07200","1193.22766","0.00224","281.73428"
"86.64000","0.07208","1195.37488","0.00224","282.24127"
"86.76000","0.07219","1197.76624","0.00225","282.80591"
"86.88000","0.07230","1199.76880","0.00225","283.27872"
"87.00000","0.07237","1201.68298","0.00225","283.73068"
"87.12000","0.07248","1204.02747","0.00226","284.28424"
"87.24000","0.07256","1205.66992","0.00226","284.67206"
"87.36000","0.07267","1207.32629","0.00226","285.06314"
"87.48000","0.07275","1209.31604","0.00227","285.53293"
"87.60000","0.07285","1211.18250","0.00227","285.97363"
"87.72000","0.07294","1213.34033","0.00227","286.48312"
"87.84000","0.07304","1215.07751","0.00227","286.89328"
"87.96000","0.07315","1217.23315","0.00228","287.40225"
"88.08000","0.07326","1219.44165","0.00228","287.92371"
"88.20000","0.07337","1221.75256","0.00228","288.46933"
"88.32000","0.07347","1223.89026","0.00229","288.97406"
"88.44000","0.07358","1226.05103","0.00229","289.48425"
"88.56000","0.07369","1228.07080","0.00229","289.96115"
"88.68000","0.07380","1230.29150","0.00230","290.48547"
"88.80000","0.07388","1232.13135","0.00230","290.91989"
"88.92000","0.07398","1234.59143","0.00230","291.50073"
"89.04000","0.07409","1236.46814","0.00231","291.94385"
"89.16000","0.07417","1238.46741","0.00231","292.41589"
"89.28000","0.07428","1240.41675","0.00231","292.87616"
"89.40000","0.07436","1241.92773","0.00232","293.23291"
"89.52000","0.07444","1243.86572","0.00232","293.69049"
"89.64000","0.07454","1245.75305","0.00232","294.13611"
"89.76000","0.07463","1247.32300","0.00232","294.50681"
"89.88000","0.07473","1249.30273","0.00233","294.97424"
"90.00000","0.07484","1251.55249","0.00233","295.50543"
"90.12000","0.07492","1253.23352","0.00233","295.90234"
"90.24000","0.07503","1255.29114","0.00234","296.38818"
"90.36000","0.07514","1257.16492","0.00234","296.83060"
"90.48000","0.07524","1259.33337","0.00234","297.34259"
"90.60000","0.07532","1261.46912","0.00235","297.84686"
"90.72000","0.07543","1263.51208","0.00235","298.32922"
"90.84000","0.07554","1265.58105","0.00235","298.81772"
"90.96000","0.07564","1267.94006","0.00236","299.37473"
"91.08000","0.07575","1269.82483","0.00236","299.81973"
"91.20000","0.07586","1271.94897","0.00236","300.32126"
"91.32000","0.07596","1274.28796","0.00237","300.87354"
"91.44000","0.07607","1276.32019","0.00237","301.35336"
"91.56000","0.07618","1278.97510","0.00237","301.98022"
"91.68000","0.07629","1281.37000","0.00238","302.54568"
"91.80000","0.07639","1283.26831","0.00238","302.99390"
"91.92000","0.07650","1285.38904","0.00238","303.49463"
"92.04000","0.07658","1287.34521","0.00238","303.95648"
"92.16000","0.07669","1289.33679","0.00239","304.42673"
"92.28000","0.07679","1291.51599","0.00239","304.94125"
"92.40000","0.07690","1293.66150","0.00239","305.44785"
"92.52000","0.07699","1295.65088","0.00240","305.91754"
"92.64000","0.07709","1297.62317","0.00240","306.38324"
"92.76000","0.07720","1299.89929","0.00240","306.92065"
"92.88000","0.07728","1301.64941","0.00241","307.33386"
"93.00000","0.07738","1303.98474","0.00241","307.88528"
"93.12000","0.07749","1306.17102","0.00241","308.40149"
"93.24000","0.07757","1307.76819","0.00242","308.77859"
"93.36000","0.07768","1309.97375","0.00242","309.29935"
"93.48000","0.07779","1311.84241","0.00242","309.74054"
"93.60000","0.07787","1313.95190","0.00242","310.23862"
"93.72000","0.07797","1316.09863","0.00243","310.74548"
"93.84000","0.07805","1317.87268","0.00243","311.16437"
"93.96000","0.07816","1320.01599","0.00243","311.67044"
"94.08000","0.07827","1322.23230","0.00244","312.19373"
"94.20000","0.07837","1324.19434","0.00244","312.65698"
"94.32000","0.07848","1326.49902","0.00244","313.20114"
"94.44000","0.07859","1328.88940","0.00245","313.76553"
"94.56000","0.07870","1331.02710","0.00245","314.27026"
"94.68000","0.07878","1332.75525","0.00245","314.67831"
"94.80000","0.07888","1334.98657","0.00246","315.20514"
"94.92000","0.07899","1337.32507","0.00246","315.75729"
"95.04000","0.07907","1339.16382","0.00246","316.19144"
"95.16000","0.07918","1340.96375","0.00247","316.61642"
"95.28000","0.07929","1343.41089","0.00247","317.19421"
"95.40000","0.07937","1345.27820","0.00247","317.63510"
"95.52000","0.07947","1346.93237","0.00247","318.02570"
"95.64000","0.07955","1348.91760","0.00248","318.49442"
"95.76000","0.07963","1350.37317","0.00248","318.83810"
"95.88000","0.07974","1352.39868","0.00248","319.31635"
"96.00000","0.07984","1354.30249","0.00249","319.76584"
"96.12000","0.07993","1356.32617","0.00249","320.24365"
"96.24000","0.08004","1357.95544","0.00249","320.62836"
"96.26000","0.08021","807.63751","0.00250","190.69218"