File: samples/m5s2.csv
Time measurement,Displacement,Primary force measurement,Composite strain,Flexure stress
(s),(mm),(N),(mm/mm),(MPa)
"0.00000","0.00000","-0.48592","0.00000","-0.11473"
"0.14000","0.00000","-0.09352","0.00000","-0.02208"
"0.28000","0.00027","2.01778","0.00001","0.47642"
"0.42000","0.00024","1.98618","0.00001","0.46896"
"0.56000","0.00024","1.90873","0.00001","0.45067"
"0.70000","0.00027","1.70430","0.00001","0.40240"
"0.84000","0.00042","3.53578","0.00001","0.83484"
"0.98000","0.00056","4.79406","0.00002","1.13193"
"1.12000","0.00070","6.05508","0.00002","1.42967"
"1.26000","0.00083","7.40620","0.00003","1.74869"
"1.40000","0.00096","9.18241","0.00003","2.16807"
"1.54000","0.00107","9.97179","0.00003","2.35445"
"1.68000","0.00121","11.48100","0.00004","2.71079"
"1.82000","0.00131","13.33893","0.00004","3.14947"
"1.96000","0.00143","14.15895","0.00004","3.34309"
"2.10000","0.00155","15.26645","0.00005","3.60458"
"2.24000","0.00166","16.67131","0.00005","3.93628"
"2.38000","0.00179","18.25804","0.00006","4.31093"
"2.52000","0.00190","19.51737","0.00006","4.60827"
"2.66000","0.00201","20.74028","0.00006","4.89701"
"2.80000","0.00212","22.53575","0.00007","5.32094"
"2.94000","0.00225","23.31781","0.00007","5.50559"
"3.08000","0.00236","25.38135","0.00007","5.99282"
"3.22000","0.00246","26.64403","0.00008","6.29095"
"3.36000","0.00260","28.27625","0.00008","6.67634"
"3.50000","0.00271","29.35931","0.00008","6.93206"
"3.64000","0.00284","31.19819","0.00009","7.36624"
"3.78000","0.00295","32.61714","0.00009","7.70127"
"3.92000","0.00305","34.20908","0.00010","8.07714"
"4.06000","0.00319","35.25001","0.00010","8.32292"
"4.20000","0.00330","37.28138","0.00010","8.80255"
"4.34000","0.00343","38.73241","0.00011","9.14515"
"4.48000","0.00354","40.00151","0.00011","9.44480"
"4.62000","0.00367","41.44784","0.00011","9.78629"
"4.76000","0.00380","43.11100","0.00012","10.17898"
"4.90000","0.00394","44.66035","0.00012","10.54480"
"5.04000","0.00407","46.22711","0.00013","10.91473"
"5.18000","0.00418","47.93598","0.00013","11.31822"
"5.32000","0.00429","49.27186","0.00013","11.63363"
"5.46000","0.00442","50.37359","0.00014","11.89376"
"5.60000","0.00453","52.07763","0.00014","12.29611"
"5.74000","0.00463","53.41914","0.00014","12.61285"
"5.88000","0.00476","54.61989","0.00015","12.89636"
"6.02000","0.00488","56.27805","0.00015","13.28787"
"6.16000","0.00498","57.65953","0.00016","13.61405"
"6.30000","0.00509","58.95331","0.00016","13.91953"
"6.44000","0.00520","60.39712","0.00016","14.26043"
"6.58000","0.00533","61.96669","0.00017","14.63102"
"6.72000","0.00544","62.81115","0.00017","14.83041"
"6.86000","0.00552","64.33613","0.00017","15.19047"
"7.00000","0.00565","65.54903","0.00018","15.47685"
"7.14000","0.00576","67.23318","0.00018","15.87450"
"7.28000","0.00589","68.36661","0.00018","16.14211"
"7.42000","0.00600","70.03776","0.00019","16.53669"
"7.56000","0.00611","71.39048","0.00019","16.85608"
"7.70000","0.00624","72.63265","0.00019","17.14938"
"7.84000","0.00635","74.03310","0.00020","17.48004"
"7.98000","0.00648","75.50878","0.00020","17.82846"
"8.12000","0.00659","77.18837","0.00021","18.22503"
"8.26000","0.00672","78.62149","0.00021","18.56341"
"8.40000","0.00683","80.22150","0.00021","18.94119"
"8.54000","0.00694","81.56263","0.00022","19.25784"
"8.68000","0.00704","82.95574","0.00022","19.58677"
"8.82000","0.00715","84.16572","0.00022","19.87246"
"8.96000","0.00727","85.42038","0.00023","20.16870"
"9.10000","0.00739","86.66202","0.00023","20.46186"
"9.24000","0.00750","88.25300","0.00023","20.83751"
"9.38000","0.00761","89.49798","0.00024","21.13147"
"9.52000","0.00774","91.09314","0.00024","21.50810"
"9.66000","0.00785","92.07116","0.00024","21.73902"
"9.80000","0.00796","93.88777","0.00025","22.16794"
"9.94000","0.00809","95.16039","0.00025","22.46843"
"10.08000","0.00820","97.07485","0.00026","22.92045"
"10.22000","0.00833","98.19750","0.00026","23.18552"
"10.36000","0.00844","99.53687","0.00026","23.50176"
"10.50000","0.00857","101.41830","0.00027","23.94599"
"10.64000","0.00870","102.75319","0.00027","24.26117"
"10.78000","0.00884","104.39935","0.00028","24.64985"
"10.92000","0.00897","106.02058","0.00028","25.03264"
"11.06000","0.00908","107.90981","0.00028","25.47870"
"11.20000","0.00919","109.21880","0.00029","25.78777"
"11.34000","0.00932","109.68280","0.00029","25.89733"
"11.48000","0.00943","111.76567","0.00029","26.38911"
"11.62000","0.00954","113.00835","0.00030","26.68253"
"11.76000","0.00965","113.78555","0.00030","26.86603"
"11.90000","0.00978","116.06371","0.00030","27.40393"
"12.04000","0.00988","117.60556","0.00031","27.76798"
"12.18000","0.00999","118.90158","0.00031","28.07398"
"12.32000","0.01012","120.18434","0.00032","28.37686"
"12.46000","0.01023","121.08719","0.00032","28.59003"
"12.60000","0.01034","122.40468","0.00032","28.90110"
"12.74000","0.01047","124.79883","0.00033","29.46639"
"12.88000","0.01058","125.06470","0.00033","29.52916"
"13.02000","0.01069","127.73148","0.00033","30.15882"
"13.16000","0.01079","128.98058","0.00034","30.45374"
"13.30000","0.01093","130.41666","0.00034","30.79282"
"13.44000","0.01104","131.66078","0.00034","31.08657"
"13.58000","0.01117","133.60197","0.00035","31.54491"
"13.72000","0.01128","135.27158","0.00035","31.93912"
"13.86000","0.01141","136.08894","0.00036","32.13211"
"14.00000","0.01152","137.87584","0.00036","32.55402"
"14.14000","0.01164","139.78871","0.00036","33.00566"
"14.28000","0.01176","141.86072","0.00037","33.49489"
"14.42000","0.01187","142.90294","0.00037","33.74097"
"14.56000","0.01197","143.20508","0.00037","33.81231"
"14.70000","0.01208","146.54747","0.00038","34.60148"
"14.84000","0.01219","145.69223","0.00038","34.39955"
"14.98000","0.01229","148.32039","0.00038","35.02009"
"15.12000","0.01240","149.14278","0.00039","35.21426"
"15.26000","0.01251","151.09122","0.00039","35.67431"
"15.40000","0.01264","151.69196","0.00039","35.81615"
"15.54000","0.01275","154.09644","0.00040","36.38388"
"15.68000","0.01286","155.74385","0.00040","36.77285"
"15.82000","0.01299","154.91048","0.00040","36.57608"
"15.96000","0.01310","159.71042","0.00041","37.70940"
"16.10000","0.01321","160.24269","0.00041","37.83508"
"16.24000","0.01334","160.91360","0.00042","37.99349"
"16.38000","0.01347","163.97623","0.00042","38.71661"
"16.52000","0.01358","165.08325","0.00042","38.97799"
"16.66000","0.01371","166.61792","0.00043","39.34034"
"16.80000","0.01382","166.91380","0.00043","39.41020"
"16.94000","0.01398","171.01147","0.00044","40.37771"
"17.08000","0.01409","171.02403","0.00044","40.38067"
"17.22000","0.01422","173.61533","0.00044","40.99250"
"17.36000","0.01433","175.56941","0.00045","41.45389"
"17.50000","0.01444","176.64993","0.00045","41.70901"
"17.64000","0.01455","178.57849","0.00045","42.16436"
"17.78000","0.01468","179.43407","0.00046","42.36637"
"17.92000","0.01479","181.37523","0.00046","42.82470"
"18.06000","0.01489","182.45499","0.00046","43.07965"
"18.20000","0.01503","184.42424","0.00047","43.54461"
"18.34000","0.01513","185.94196","0.00047","43.90296"
"18.48000","0.01524","187.44730","0.00047","44.25839"
"18.62000","0.01537","189.32019","0.00048","44.70060"
"18.76000","0.01548","190.21484","0.00048","44.91183"
"18.90000","0.01559","191.95657","0.00049","45.32308"
"19.04000","0.01570","193.33299","0.00049","45.64806"
"19.18000","0.01580","194.61731","0.00049","45.95131"
"19.32000","0.01591","196.17961","0.00050","46.32018"
"19.46000","0.01604","197.97301","0.00050","46.74363"
"19.60000","0.01615","199.68781","0.00050","47.14851"
"19.74000","0.01627","200.91446","0.00051","47.43813"
"19.88000","0.01639","202.67558","0.00051","47.85395"
"20.02000","0.01651","204.57845","0.00051","48.30324"
"20.16000","0.01663","206.24069","0.00052","48.69572"
"20.30000","0.01674","207.62314","0.00052","49.02213"
"20.44000","0.01687","209.22232","0.00053","49.39971"
"20.58000","0.01698","210.93948","0.00053","49.80515"
"20.72000","0.01709","212.15254","0.00053","50.09157"
"20.86000","0.01720","213.85240","0.00054","50.49292"
"21.00000","0.01730","215.08141","0.00054","50.78311"
"21.14000","0.01741","216.45680","0.00054","51.10785"
"21.28000","0.01755","218.03647","0.00055","51.48083"
"21.42000","0.01765","219.52635","0.00055","51.83261"
"21.56000","0.01776","221.18727","0.00055","52.22477"
"21.70000","0.01789","222.58041","0.00056","52.55371"
"21.84000","0.01800","224.43910","0.00056","52.99256"
"21.98000","0.01811","225.68808","0.00056","53.28746"
"22.12000","0.01824","227.31177","0.00057","53.67083"
"22.26000","0.01835","229.03343","0.00057","54.07734"
"22.40000","0.01848","230.62311","0.00058","54.45267"
"22.54000","0.01859","232.28882","0.00058","54.84597"
"22.68000","0.01872","233.89287","0.00058","55.22470"
"22.82000","0.01883","235.67648","0.00059","55.64583"
"22.96000","0.01896","237.14185","0.00059","55.99182"
"23.10000","0.01910","239.25980","0.00059","56.49189"
"23.24000","0.01923","240.96100","0.00060","56.89357"
"23.38000","0.01934","242.18944","0.00060","57.18361"
"23.52000","0.01945","244.15283","0.00061","57.64719"
"23.66000","0.01958","245.42122","0.00061","57.94667"
"23.80000","0.01969","247.24640","0.00061","58.37762"
"23.94000","0.01979","248.76997","0.00062","58.73735"
"24.08000","0.01993","250.07639","0.00062","59.04581"
"24.22000","0.02004","251.92807","0.00062","59.48301"
"24.36000","0.02014","253.31627","0.00063","59.81078"
"24.50000","0.02028","255.30273","0.00063","60.27981"
"24.64000","0.02038","256.90771","0.00063","60.65876"
"24.78000","0.02049","258.45792","0.00064","61.02478"
"24.92000","0.02063","259.90396","0.00064","61.36621"
"25.06000","0.02073","261.62888","0.00065","61.77348"
"25.20000","0.02084","263.89062","0.00065","62.30751"
"25.34000","0.02095","264.79288","0.00065","62.52054"
"25.48000","0.02108","266.66959","0.00066","62.96365"
"25.62000","0.02121","268.60068","0.00066","63.41960"
"25.76000","0.02132","270.16339","0.00066","63.78857"
"25.90000","0.02143","271.76688","0.00067","64.16718"
"26.04000","0.02156","272.22433","0.00067","64.27518"
"26.18000","0.02167","275.18823","0.00067","64.97500"
"26.32000","0.02178","276.73123","0.00068","65.33932"
"26.46000","0.02191","278.39368","0.00068","65.73183"
"26.60000","0.02202","279.77249","0.00069","66.05739"
"26.74000","0.02213","281.40039","0.00069","66.44176"
"26.88000","0.02223","283.54977","0.00069","66.94925"
"27.02000","0.02234","284.51538","0.00070","67.17724"
"27.16000","0.02245","286.50955","0.00070","67.64809"
"27.30000","0.02255","287.56467","0.00070","67.89721"
"27.44000","0.02266","289.51083","0.00071","68.35672"
"27.58000","0.02278","291.19357","0.00071","68.75404"
"27.72000","0.02290","292.87048","0.00071","69.14997"
"27.86000","0.02301","294.59280","0.00072","69.55663"
"28.00000","0.02314","296.03387","0.00072","69.89688"
"28.14000","0.02325","298.05588","0.00072","70.37430"
"28.28000","0.02336","299.60919","0.00073","70.74106"
"28.42000","0.02349","301.24762","0.00073","71.12791"
"28.56000","0.02360","302.95956","0.00074","71.53211"
"28.70000","0.02373","304.82358","0.00074","71.97223"
"28.84000","0.02387","306.71185","0.00074","72.41808"
"28.98000","0.02397","308.20746","0.00075","72.77120"
"29.12000","0.02411","310.51382","0.00075","73.31576"
"29.26000","0.02424","312.40628","0.00075","73.76259"
"29.40000","0.02435","313.77182","0.00076","74.08501"
"29.54000","0.02448","315.60889","0.00076","74.51876"
"29.68000","0.02459","316.92993","0.00077","74.83067"
"29.82000","0.02472","319.16342","0.00077","75.35802"
"29.96000","0.02483","320.52133","0.00077","75.67864"
"30.10000","0.02494","322.46078","0.00078","76.13657"
"30.24000","0.02504","324.17014","0.00078","76.54017"
"30.38000","0.02518","325.51514","0.00078","76.85773"
"30.52000","0.02529","327.30652","0.00079","77.28070"
"30.66000","0.02539","328.74161","0.00079","77.61954"
"30.80000","0.02550","330.45346","0.00079","78.02373"
"30.94000","0.02563","331.87234","0.00080","78.35874"
"31.08000","0.02574","333.80295","0.00080","78.81458"
"31.22000","0.02585","335.32147","0.00080","79.17312"
"31.36000","0.02596","336.93781","0.00081","79.55476"
"31.50000","0.02606","338.53421","0.00081","79.93169"
"31.64000","0.02618","340.50739","0.00082","80.39758"
"31.78000","0.02630","341.83569","0.00082","80.71120"
"31.92000","0.02644","343.67148","0.00082","81.14465"
"32.06000","0.02654","345.84006","0.00083","81.65668"
"32.20000","0.02668","347.32654","0.00083","82.00765"
"32.34000","0.02681","349.36877","0.00084","82.48985"
"32.48000","0.02692","350.79752","0.00084","82.82719"
"32.62000","0.02703","352.76859","0.00084","83.29258"
"32.76000","0.02713","354.55444","0.00085","83.71424"
"32.90000","0.02727","356.39264","0.00085","84.14825"
"33.04000","0.02737","357.47263","0.00085","84.40325"
"33.18000","0.02748","359.09216","0.00086","84.78564"
"33.32000","0.02758","360.47482","0.00086","85.11211"
"33.46000","0.02770","362.41138","0.00086","85.56935"
"33.60000","0.02780","363.55713","0.00087","85.83987"
"33.74000","0.02791","365.69681","0.00087","86.34508"
"33.88000","0.02805","367.19342","0.00087","86.69844"
"34.02000","0.02815","369.30890","0.00088","87.19793"
"34.16000","0.02826","370.78391","0.00088","87.54620"
"34.30000","0.02839","372.83038","0.00088","88.02939"
"34.44000","0.02850","374.71716","0.00089","88.47488"
"34.58000","0.02863","376.31207","0.00089","88.85146"
"34.72000","0.02874","378.18387","0.00090","89.29341"
"34.86000","0.02888","380.08716","0.00090","89.74280"
"35.00000","0.02899","381.58807","0.00090","90.09718"
"35.14000","0.02912","384.12073","0.00091","90.69517"
"35.28000","0.02925","386.17780","0.00091","91.18086"
"35.42000","0.02938","387.39856","0.00091","91.46910"
"35.56000","0.02949","389.86365","0.00092","92.05113"
"35.70000","0.02962","391.38440","0.00092","92.41020"
"35.84000","0.02973","393.03891","0.00093","92.80085"
"35.98000","0.02984","394.96222","0.00093","93.25497"
"36.12000","0.02995","396.53326","0.00093","93.62591"
"36.26000","0.03008","398.21481","0.00094","94.02293"
"36.40000","0.03019","400.18494","0.00094","94.48811"
"36.54000","0.03029","402.05441","0.00094","94.92951"
"36.68000","0.03043","403.54059","0.00095","95.28041"
"36.82000","0.03054","405.58353","0.00095","95.76277"
"36.96000","0.03064","407.22556","0.00095","96.15047"
"37.10000","0.03078","408.87753","0.00096","96.54052"
"37.24000","0.03088","410.80316","0.00096","96.99519"
"37.38000","0.03099","412.49435","0.00097","97.39449"
"37.52000","0.03110","414.14471","0.00097","97.78416"
"37.66000","0.03121","416.05368","0.00097","98.23489"
"37.80000","0.03134","417.88043","0.00098","98.66621"
"37.94000","0.03145","419.98447","0.00098","99.16299"
"38.08000","0.03158","421.79022","0.00098","99.58936"
"38.22000","0.03171","423.98450","0.00099","100.10744"
"38.36000","0.03182","425.68274","0.00099","100.50842"
"38.50000","0.03193","427.50809","0.00099","100.93941"
"38.64000","0.03206","429.22107","0.00100","101.34386"
"38.78000","0.03217","431.18411","0.00100","101.80736"
"38.92000","0.03228","432.89444","0.00101","102.21118"
"39.06000","0.03238","434.45508","0.00101","102.57967"
"39.20000","0.03249","436.11325","0.00101","102.97118"
"39.34000","0.03260","437.83478","0.00102","103.37765"
"39.48000","0.03271","439.20734","0.00102","103.70173"
"39.62000","0.03281","441.12521","0.00102","104.15456"
"39.76000","0.03294","443.24017","0.00103","104.65392"
"39.90000","0.03305","444.71085","0.00103","105.00117"
"40.04000","0.03316","446.88931","0.00103","105.51553"
"40.18000","0.03330","448.90143","0.00104","105.99061"
"40.32000","0.03340","450.64600","0.00104","106.40252"
"40.46000","0.03351","452.48117","0.00104","106.83582"
"40.60000","0.03364","454.12564","0.00105","107.22411"
"40.74000","0.03375","456.43134","0.00105","107.76850"
"40.88000","0.03388","458.27130","0.00106","108.20294"
"41.02000","0.03399","459.99863","0.00106","108.61078"
"41.16000","0.03413","462.36035","0.00106","109.16841"
"41.30000","0.03426","464.35226","0.00107","109.63873"
"41.44000","0.03439","466.50470","0.00107","110.14693"
"41.58000","0.03450","468.45883","0.00107","110.60833"
"41.72000","0.03463","470.32028","0.00108","111.04784"
"41.86000","0.03474","472.40915","0.00108","111.54105"
"42.00000","0.03485","474.11792","0.00109","111.94450"
"42.14000","0.03498","475.95450","0.00109","112.37814"
"42.28000","0.03509","477.96237","0.00109","112.85222"
"42.42000","0.03520","479.76913","0.00110","113.27882"
"42.56000","0.03533","481.65097","0.00110","113.72314"
"42.70000","0.03544","483.50546","0.00110","114.16100"
"42.84000","0.03554","485.53500","0.00111","114.64021"
"42.98000","0.03566","487.58881","0.00111","115.12513"
"43.12000","0.03579","489.44974","0.00111","115.56451"
"43.26000","0.03589","491.02255","0.00112","115.93587"
"43.40000","0.03600","492.91443","0.00112","116.38257"
"43.54000","0.03611","494.68378","0.00112","116.80033"
"43.68000","0.03621","496.33704","0.00113","117.19068"
"43.82000","0.03633","498.24054","0.00113","117.64012"
"43.96000","0.03646","500.10529","0.00114","118.08041"
"44.10000","0.03659","502.26965","0.00114","118.59144"
"44.24000","0.03670","504.25125","0.00114","119.05932"
"44.38000","0.03683","506.29977","0.00115","119.54300"
"44.52000","0.03697","508.41129","0.00115","120.04155"
"44.66000","0.03707","510.34113","0.00115","120.49720"
"44.80000","0.03718","511.92575","0.00116","120.87135"
"44.94000","0.03731","513.89996","0.00116","121.33749"
"45.08000","0.03742","515.79492","0.00117","121.78490"
"45.22000","0.03753","517.72809","0.00117","122.24135"
"45.36000","0.03763","519.09729","0.00117","122.56463"
"45.50000","0.03774","521.01190","0.00118","123.01669"
"45.64000","0.03785","522.66992","0.00118","123.40817"
"45.78000","0.03796","524.32245","0.00118","123.79835"
"45.92000","0.03806","526.21222","0.00119","124.24454"
"46.06000","0.03817","528.09192","0.00119","124.68836"
"46.20000","0.03830","530.11627","0.00119","125.16634"
"46.34000","0.03841","531.74432","0.00120","125.55074"
"46.48000","0.03855","533.81085","0.00120","126.03867"
"46.62000","0.03865","535.62524","0.00120","126.46706"
"46.76000","0.03879","537.68896","0.00121","126.95433"
"46.90000","0.03889","539.91968","0.00121","127.48103"
"47.04000","0.03903","541.87634","0.00122","127.94302"
"47.18000","0.03913","543.92743","0.00122","128.42731"
"47.32000","0.03927","545.75726","0.00122","128.85934"
"47.46000","0.03940","548.10327","0.00123","129.41327"
"47.60000","0.03954","550.17102","0.00123","129.90149"
"47.74000","0.03964","552.19122","0.00123","130.37848"
"47.88000","0.03975","554.55988","0.00124","130.93774"
"48.02000","0.03988","556.64575","0.00124","131.43024"
"48.16000","0.03999","558.12451","0.00125","131.77939"
"48.30000","0.04010","560.11206","0.00125","132.24867"
"48.44000","0.04023","562.17847","0.00125","132.73657"
"48.58000","0.04034","564.05652","0.00126","133.18001"
"48.72000","0.04045","565.71735","0.00126","133.57214"
"48.86000","0.04058","568.18878","0.00126","134.15567"
"49.00000","0.04069","569.95667","0.00127","134.57309"
"49.14000","0.04079","571.72302","0.00127","134.99016"
"49.28000","0.04093","573.91095","0.00127","135.50674"
"49.42000","0.04104","575.84155","0.00128","135.96259"
"49.56000","0.04114","577.79004","0.00128","136.42264"
"49.70000","0.04126","580.06903","0.00128","136.96074"
"49.84000","0.04138","582.11896","0.00129","137.44475"
"49.98000","0.04149","583.74377","0.00129","137.82838"
"50.12000","0.04160","586.20789","0.00130","138.41019"
"50.26000","0.04173","587.82050","0.00130","138.79094"
"50.40000","0.04184","589.76288","0.00130","139.24956"
"50.54000","0.04197","592.30768","0.00131","139.85042"
"50.68000","0.04208","594.01746","0.00131","140.25412"
"50.82000","0.04221","596.81372","0.00131","140.91434"
"50.96000","0.04232","598.03864","0.00132","141.20355"
"51.10000","0.04243","600.37726","0.00132","141.75574"
"51.24000","0.04254","602.03015","0.00132","142.14600"
"51.38000","0.04267","603.88867","0.00133","142.58482"
"51.52000","0.04275","605.91022","0.00133","143.06213"
"51.66000","0.04286","607.45477","0.00133","143.42682"
"51.80000","0.04296","609.43060","0.00134","143.89333"
"51.94000","0.04307","611.52435","0.00134","144.38768"
"52.08000","0.04321","613.51544","0.00135","144.85780"
"52.22000","0.04331","615.45416","0.00135","145.31555"
"52.36000","0.04345","617.32062","0.00135","145.75626"
"52.50000","0.04355","619.42719","0.00136","146.25363"
"52.64000","0.04366","621.47412","0.00136","146.73694"
"52.78000","0.04379","623.54498","0.00136","147.22589"
"52.92000","0.04390","625.51544","0.00137","147.69113"
"53.06000","0.04404","627.72052","0.00137","148.21178"
"53.20000","0.04414","629.74237","0.00137","148.68916"
"53.34000","0.04428","631.63361","0.00138","149.13571"
"53.48000","0.04441","633.72662","0.00138","149.62988"
"53.62000","0.04454","636.38177","0.00139","150.25681"
"53.76000","0.04465","638.29205","0.00139","150.70784"
"53.90000","0.04479","640.37939","0.00139","151.20068"
"54.04000","0.04489","642.35193","0.00140","151.66641"
"54.18000","0.04500","643.99860","0.00140","152.05522"
"54.32000","0.04513","646.07184","0.00141","152.54474"
"54.46000","0.04524","648.11090","0.00141","153.02618"
"54.60000","0.04535","650.08716","0.00141","153.49280"
"54.74000","0.04548","652.42633","0.00142","154.04510"
"54.88000","0.04559","654.17706","0.00142","154.45847"
"55.02000","0.04570","656.11548","0.00142","154.91615"
"55.16000","0.04581","658.26453","0.00143","155.42355"
"55.30000","0.04594","660.00952","0.00143","155.83557"
"55.44000","0.04604","662.24255","0.00143","156.36282"
"55.58000","0.04615","664.11658","0.00144","156.80530"
"55.72000","0.04626","665.90558","0.00144","157.22769"
"55.86000","0.04637","668.03033","0.00144","157.72937"
"56.00000","0.04650","669.66895","0.00145","158.11627"
"56.14000","0.04661","671.90643","0.00145","158.64456"
"56.28000","0.04674","674.24188","0.00146","159.19600"
"56.42000","0.04688","676.17676","0.00146","159.65283"
"56.56000","0.04698","678.60498","0.00146","160.22617"
"56.70000","0.04709","680.28516","0.00147","160.62288"
"56.84000","0.04722","682.45465","0.00147","161.13512"
"56.98000","0.04733","684.27924","0.00147","161.56592"
"57.12000","0.04745","686.39136","0.00148","162.06462"
"57.26000","0.04757","688.10406","0.00148","162.46901"
"57.40000","0.04768","690.38092","0.00148","163.00659"
"57.54000","0.04779","692.28809","0.00149","163.45689"
"57.68000","0.04789","694.04742","0.00149","163.87230"
"57.82000","0.04800","695.99896","0.00149","164.33308"
"57.96000","0.04811","697.73492","0.00150","164.74297"
"58.10000","0.04821","700.10614","0.00150","165.30283"
"58.24000","0.04832","701.82849","0.00150","165.70950"
"58.38000","0.04846","703.82019","0.00151","166.17976"
"58.52000","0.04856","706.20447","0.00151","166.74271"
"58.66000","0.04867","708.00208","0.00152","167.16714"
"58.80000","0.04880","710.00970","0.00152","167.64117"
"58.94000","0.04891","712.56055","0.00152","168.24345"
"59.08000","0.04904","714.65405","0.00153","168.73775"
"59.22000","0.04915","716.68652","0.00153","169.21764"
"59.36000","0.04929","718.89471","0.00153","169.73901"
"59.50000","0.04941","721.02148","0.00154","170.24118"
"59.64000","0.04955","723.23059","0.00154","170.76277"
"59.78000","0.04968","725.86554","0.00155","171.38490"
"59.92000","0.04979","727.86115","0.00155","171.85609"
"60.06000","0.04990","729.74597","0.00155","172.30112"
"60.20000","0.05004","732.20526","0.00156","172.88179"
"60.34000","0.05014","734.10931","0.00156","173.33136"
"60.48000","0.05025","736.18640","0.00156","173.82178"
"60.62000","0.05037","738.22571","0.00157","174.30328"
"60.76000","0.05049","739.90710","0.00157","174.70029"
"60.90000","0.05060","742.05670","0.00158","175.20782"
"61.04000","0.05071","743.87622","0.00158","175.63744"
"61.18000","0.05084","746.12317","0.00158","176.16795"
"61.32000","0.05095","748.12811","0.00159","176.64136"
"61.46000","0.05107","750.46594","0.00159","177.19334"
"61.60000","0.05119","752.42480","0.00159","177.65585"
"61.74000","0.05129","754.41302","0.00160","178.12529"
"61.88000","0.05143","756.79187","0.00160","178.68697"
"62.02000","0.05154","758.65442","0.00160","179.12672"
"62.16000","0.05164","760.57159","0.00161","179.57939"
"62.30000","0.05178","762.71680","0.00161","180.08591"
"62.44000","0.05188","764.95953","0.00162","180.61543"
"62.58000","0.05199","766.63190","0.00162","181.01030"
"62.72000","0.05213","768.90247","0.00162","181.54640"
"62.86000","0.05223","770.88342","0.00163","182.01413"
"63.00000","0.05236","773.25757","0.00163","182.57469"
"63.14000","0.05247","774.84290","0.00163","182.94901"
"63.28000","0.05258","777.49097","0.00164","183.57425"
"63.42000","0.05269","779.14886","0.00164","183.96570"
"63.56000","0.05282","781.54413","0.00164","184.53125"
"63.70000","0.05293","783.42334","0.00165","184.97495"
"63.84000","0.05301","785.02411","0.00165","185.35291"
"63.98000","0.05312","786.54791","0.00165","185.71269"
"64.12000","0.05324","788.84717","0.00166","186.25557"
"64.26000","0.05336","791.00531","0.00166","186.76514"
"64.40000","0.05346","793.27820","0.00166","187.30179"
"64.54000","0.05359","795.34558","0.00167","187.78992"
"64.68000","0.05371","797.61987","0.00167","188.32690"
"64.82000","0.05381","799.58856","0.00168","188.79173"
"64.96000","0.05394","801.88104","0.00168","189.33301"
"65.10000","0.05405","803.85059","0.00168","189.79805"
"65.24000","0.05419","806.04700","0.00169","190.31664"
"65.38000","0.05429","808.24048","0.00169","190.83455"
"65.52000","0.05443","810.40448","0.00170","191.34549"
"65.66000","0.05456","812.91980","0.00170","191.93939"
"65.80000","0.05470","815.04834","0.00170","192.44196"
"65.94000","0.05480","817.18524","0.00171","192.94650"
"66.08000","0.05492","819.52197","0.00171","193.49823"
"66.22000","0.05504","821.47736","0.00171","193.95992"
"66.36000","0.05515","823.86462","0.00172","194.52357"
"66.50000","0.05529","825.76898","0.00172","194.97322"
"66.64000","0.05539","827.81128","0.00173","195.45543"
"66.78000","0.05550","829.98108","0.00173","195.96774"
"66.92000","0.05562","831.75830","0.00173","196.38736"
"67.06000","0.05574","834.12360","0.00174","196.94583"
"67.20000","0.05585","836.06934","0.00174","197.40524"
"67.34000","0.05596","838.17944","0.00174","197.90347"
"67.48000","0.05609","840.07739","0.00175","198.35159"
"67.62000","0.05620","842.12189","0.00175","198.83432"
"67.76000","0.05630","844.32581","0.00175","199.35469"
"67.90000","0.05642","846.16748","0.00176","199.78954"
"68.04000","0.05652","848.05823","0.00176","200.23596"
"68.18000","0.05663","849.94684","0.00176","200.68188"
"68.32000","0.05676","851.92163","0.00177","201.14815"
"68.46000","0.05687","853.91870","0.00177","201.61969"
"68.60000","0.05699","856.22119","0.00177","202.16333"
"68.74000","0.05711","858.41028","0.00178","202.68019"
"68.88000","0.05723","860.46606","0.00178","203.16559"
"69.02000","0.05735","863.02032","0.00179","203.76868"
"69.16000","0.05748","865.17761","0.00179","204.27803"
"69.30000","0.05759","867.52271","0.00179","204.83174"
"69.44000","0.05772","869.44818","0.00180","205.28636"
"69.58000","0.05783","871.43762","0.00180","205.75609"
"69.72000","0.05794","873.25348","0.00180","206.18484"
"69.86000","0.05804","875.26245","0.00181","206.65918"
"70.00000","0.05815","876.81360","0.00181","207.02542"
"70.14000","0.05826","879.02362","0.00181","207.54723"
"70.28000","0.05837","880.96436","0.00182","208.00546"
"70.42000","0.05848","883.25012","0.00182","208.54515"
"70.56000","0.05860","885.46301","0.00182","209.06764"
"70.70000","0.05871","887.40234","0.00183","209.52554"
"70.84000","0.05882","889.62866","0.00183","210.05119"
"70.98000","0.05896","891.66022","0.00184","210.53087"
"71.12000","0.05906","893.96069","0.00184","211.07404"
"71.26000","0.05920","895.93939","0.00184","211.54123"
"71.40000","0.05930","898.27545","0.00185","212.09280"
"71.54000","0.05944","900.73718","0.00185","212.67404"
"71.68000","0.05954","902.78729","0.00185","213.15810"
"71.82000","0.05968","905.05908","0.00186","213.69449"
"71.96000","0.05981","907.48053","0.00186","214.26622"
"72.10000","0.05995","910.17664","0.00187","214.90280"
"72.24000","0.06005","912.10968","0.00187","215.35922"
"72.38000","0.06019","914.31506","0.00187","215.87993"
"72.52000","0.06029","916.20001","0.00188","216.32500"
"72.66000","0.06040","918.48981","0.00188","216.86563"
"72.80000","0.06053","920.53290","0.00189","217.34804"
"72.94000","0.06064","923.14819","0.00189","217.96553"
"73.08000","0.06075","924.49097","0.00189","218.28258"
"73.22000","0.06088","926.84656","0.00190","218.83876"
"73.36000","0.06099","928.90887","0.00190","219.32570"
"73.50000","0.06110","930.87292","0.00190","219.78943"
"73.64000","0.06121","933.06274","0.00191","220.30647"
"73.78000","0.06134","935.11511","0.00191","220.79106"
"73.92000","0.06145","937.41498","0.00191","221.33408"
"74.06000","0.06155","939.43011","0.00192","221.80988"
"74.20000","0.06169","941.41467","0.00192","222.27846"
"74.34000","0.06179","943.92224","0.00192","222.87051"
"74.48000","0.06192","945.89771","0.00193","223.33694"
"74.62000","0.06204","948.07709","0.00193","223.85152"
"74.76000","0.06214","949.98328","0.00194","224.30159"
"74.90000","0.06227","952.13678","0.00194","224.81006"
"75.04000","0.06238","954.44293","0.00194","225.35457"
"75.18000","0.06249","956.47864","0.00195","225.83522"
"75.32000","0.06263","958.60596","0.00195","226.33751"
"75.46000","0.06273","960.42938","0.00195","226.76804"
"75.60000","0.06284","962.65881","0.00196","227.29443"
"75.74000","0.06297","964.64130","0.00196","227.76251"
"75.88000","0.06308","966.68256","0.00196","228.24448"
"76.02000","0.06318","968.74060","0.00197","228.73041"
"76.16000","0.06327","970.37402","0.00197","229.11607"
"76.30000","0.06338","972.46497","0.00197","229.60977"
"76.44000","0.06351","974.57654","0.00198","230.10834"
"76.58000","0.06362","976.70062","0.00198","230.60986"
"76.72000","0.06372","978.98083","0.00198","231.14824"
"76.86000","0.06386","980.86066","0.00199","231.59209"
"77.00000","0.06396","983.15973","0.00199","232.13492"
"77.14000","0.06407","985.49377","0.00200","232.68602"
"77.28000","0.06421","987.63110","0.00200","233.19066"
"77.42000","0.06431","989.73120","0.00200","233.68652"
"77.56000","0.06445","992.27429","0.00201","234.28697"
"77.70000","0.06457","994.69812","0.00201","234.85927"
"77.84000","0.06469","996.89404","0.00201","235.37775"
"77.98000","0.06482","999.32654","0.00202","235.95209"
"78.12000","0.06496","1001.55554","0.00202","236.47838"
"78.26000","0.06507","1003.87146","0.00203","237.02519"
"78.40000","0.06520","1006.08832","0.00203","237.54861"
"78.54000","0.06530","1008.26447","0.00203","238.06242"
"78.68000","0.06544","1010.27478","0.00204","238.53709"
"78.82000","0.06554","1012.34772","0.00204","239.02654"
"78.96000","0.06565","1014.47345","0.00204","239.52844"
"79.10000","0.06577","1016.59790","0.00205","240.03004"
"79.24000","0.06589","1018.88953","0.00205","240.57112"
"79.38000","0.06600","1020.89362","0.00206","241.04431"
"79.52000","0.06611","1022.86975","0.00206","241.51089"
"79.66000","0.06624","1025.05408","0.00206","242.02664"
"79.80000","0.06635","1027.03528","0.00207","242.49443"
"79.94000","0.06646","1029.25586","0.00207","243.01874"
"80.08000","0.06656","1031.04272","0.00207","243.44063"
"80.22000","0.06667","1033.16394","0.00208","243.94147"
"80.36000","0.06678","1034.83667","0.00208","244.33643"
"80.50000","0.06691","1037.31262","0.00208","244.92102"
"80.64000","0.06702","1039.26611","0.00209","245.38226"
"80.78000","0.06713","1041.63794","0.00209","245.94228"
"80.92000","0.06726","1043.91248","0.00209","246.47932"
"81.06000","0.06737","1045.97498","0.00210","246.96629"
"81.20000","0.06750","1048.24060","0.00210","247.50124"
"81.34000","0.06763","1050.60120","0.00211","248.05861"
"81.48000","0.06774","1052.72961","0.00211","248.56114"
"81.62000","0.06788","1055.04504","0.00211","249.10785"
"81.76000","0.06798","1057.13037","0.00212","249.60022"
"81.90000","0.06809","1059.12390","0.00212","250.07091"
"82.04000","0.06820","1061.11841","0.00212","250.54184"
"82.18000","0.06830","1063.06409","0.00213","251.00124"
"82.32000","0.06841","1064.82605","0.00213","251.41725"
"82.46000","0.06852","1066.85205","0.00213","251.89561"
"82.60000","0.06862","1069.17773","0.00214","252.44473"
"82.74000","0.06875","1071.34009","0.00214","252.95529"
"82.88000","0.06887","1073.82263","0.00214","253.54144"
"83.02000","0.06897","1075.46631","0.00215","253.92953"
"83.16000","0.06911","1077.57422","0.00215","254.42723"
"83.30000","0.06921","1079.94055","0.00216","254.98595"
"83.44000","0.06934","1081.93848","0.00216","255.45769"
"83.58000","0.06946","1084.87146","0.00216","256.15018"
"83.72000","0.06959","1086.74817","0.00217","256.59329"
"83.86000","0.06970","1089.05054","0.00217","257.13693"
"84.00000","0.06983","1090.95764","0.00217","257.58722"
"84.14000","0.06996","1094.19006","0.00218","258.35040"
"84.28000","0.07010","1096.58740","0.00218","258.91644"
"84.42000","0.07021","1098.75867","0.00219","259.42911"
"84.56000","0.07032","1101.36060","0.00219","260.04346"
"84.70000","0.07045","1103.14246","0.00219","260.46417"
"84.84000","0.07055","1105.68469","0.00220","261.06442"
"84.98000","0.07069","1107.70752","0.00220","261.54205"
"85.12000","0.07079","1109.72559","0.00220","262.01852"
"85.26000","0.07090","1112.18005","0.00221","262.59805"
"85.40000","0.07102","1114.30920","0.00221","263.10077"
"85.54000","0.07114","1116.62427","0.00222","263.64737"
"85.68000","0.07125","1118.80615","0.00222","264.16254"
"85.82000","0.07136","1120.69629","0.00222","264.60883"
"85.96000","0.07149","1122.36377","0.00223","265.00253"
"86.10000","0.07160","1125.05420","0.00223","265.63779"
"86.24000","0.07171","1126.84839","0.00223","266.06140"
"86.38000","0.07181","1129.04846","0.00224","266.58087"
"86.52000","0.07192","1131.28052","0.00224","267.10788"
"86.66000","0.07203","1133.50586","0.00224","267.63330"
"86.80000","0.07216","1135.09021","0.00225","268.00739"
"86.94000","0.07227","1137.56189","0.00225","268.59097"
"87.08000","0.07240","1140.02698","0.00225","269.17303"
"87.22000","0.07254","1142.56091","0.00226","269.77130"
"87.36000","0.07264","1144.95190","0.00226","270.33585"
"87.50000","0.07278","1146.81799","0.00227","270.77646"
"87.64000","0.07288","1149.55432","0.00227","271.42255"
"87.78000","0.07299","1151.01501","0.00227","271.76743"
"87.92000","0.07313","1153.11768","0.00228","272.26389"
"88.06000","0.07323","1155.23865","0.00228","272.76468"
"88.20000","0.07334","1156.88147","0.00228","273.15256"
"88.34000","0.07342","1159.29883","0.00229","273.72333"
"88.48000","0.07353","1160.62476","0.00229","274.03638"
"88.62000","0.07366","1163.09790","0.00229","274.62033"
"88.76000","0.07377","1165.11328","0.00230","275.09619"
"88.90000","0.07388","1167.33093","0.00230","275.61978"
"89.04000","0.07401","1169.69116","0.00230","276.17706"
"89.18000","0.07412","1171.23755","0.00231","276.54218"
"89.32000","0.07422","1174.14343","0.00231","277.22830"
"89.46000","0.07436","1175.60388","0.00232","277.57312"
"89.60000","0.07446","1178.69604","0.00232","278.30322"
"89.74000","0.07460","1180.76196","0.00232","278.79102"
"89.88000","0.07471","1182.86780","0.00233","279.28821"
"90.02000","0.07484","1185.28333","0.00233","279.85855"
"90.16000","0.07495","1187.49426","0.00233","280.38058"
"90.30000","0.07508","1190.16882","0.00234","281.01205"
"90.44000","0.07521","1192.73853","0.00234","281.61880"
"90.58000","0.07535","1194.99365","0.00235","282.15128"
"90.72000","0.07546","1197.07190","0.00235","282.64197"
"90.86000","0.07559","1199.45117","0.00235","283.20374"
"91.00000","0.07570","1201.54968","0.00236","283.69922"
"91.14000","0.07580","1203.68176","0.00236","284.20264"
"91.28000","0.07594","1205.89246","0.00236","284.72458"
"91.42000","0.07605","1208.17395","0.00237","285.26328"
"91.56000","0.07615","1210.54578","0.00237","285.82330"
"91.70000","0.07626","1212.38940","0.00237","286.25861"
"91.84000","0.07639","1214.85437","0.00238","286.84061"
"91.98000","0.07650","1217.29590","0.00238","287.41708"
"92.12000","0.07661","1219.23450","0.00239","287.87479"
"92.26000","0.07674","1221.58240","0.00239","288.42917"
"92.40000","0.07682","1223.68958","0.00239","288.92670"
"92.54000","0.07693","1225.75537","0.00240","289.41446"
"92.68000","0.07706","1227.82397","0.00240","289.90286"
"92.82000","0.07717","1230.00513","0.00240","290.41785"
"92.96000","0.07730","1232.64087","0.00241","291.04019"
"93.10000","0.07741","1234.70813","0.00241","291.52829"
"93.24000","0.07755","1237.46130","0.00241","292.17834"
"93.38000","0.07765","1239.70715","0.00242","292.70862"
"93.52000","0.07779","1241.76184","0.00242","293.19376"
"93.66000","0.07789","1244.11279","0.00243","293.74884"
"93.80000","0.07802","1246.61609","0.00243","294.33990"
"93.94000","0.07813","1248.67175","0.00243","294.82526"
"94.08000","0.07824","1250.88940","0.00244","295.34888"
"94.22000","0.07835","1252.76880","0.00244","295.79260"
"94.36000","0.07846","1254.68042","0.00244","296.24396"
"94.50000","0.07856","1257.20605","0.00245","296.84030"
"94.64000","0.07867","1257.99988","0.00245","297.02774"
"94.78000","0.07878","1260.75854","0.00245","297.67908"
"94.92000","0.07891","1263.09509","0.00246","298.23077"
"95.06000","0.07902","1265.29407","0.00246","298.74997"
"95.20000","0.07913","1267.25732","0.00246","299.21353"
"95.34000","0.07926","1269.52600","0.00247","299.74918"
"95.48000","0.07937","1272.19568","0.00247","300.37952"
"95.62000","0.07950","1274.18030","0.00248","300.84811"
"95.76000","0.07961","1276.77075","0.00248","301.45975"
"95.90000","0.07971","1278.52441","0.00248","301.87381"
"96.04000","0.07985","1280.96118","0.00249","302.44916"
"96.18000","0.07998","1283.43420","0.00249","303.03305"
"96.32000","0.08009","1285.55725","0.00249","303.53433"
"96.46000","0.08022","1288.39539","0.00250","304.20444"
"96.60000","0.08036","1290.58423","0.00250","304.72125"
"96.74000","0.08046","1293.31238","0.00251","305.36542"
"96.88000","0.08060","1295.35144","0.00251","305.84686"
"97.02000","0.08071","1297.63623","0.00251","306.38632"
"97.16000","0.08083","1299.71521","0.00252","306.87720"
"97.30000","0.08095","1301.45923","0.00252","307.28897"
"97.44000","0.08105","1303.87268","0.00252","307.85883"
"97.58000","0.08118","1306.15637","0.00253","308.39801"
"97.72000","0.08129","1308.65479","0.00253","308.98792"
"97.86000","0.08140","1310.76807","0.00254","309.48688"
"98.00000","0.08151","1313.06104","0.00254","310.02829"
"98.14000","0.08163","1315.22327","0.00254","310.53882"
"98.28000","0.08175","1317.12671","0.00255","310.98822"
"98.42000","0.08186","1319.66821","0.00255","311.58832"
"98.56000","0.08199","1322.26306","0.00255","312.20099"
"98.70000","0.08207","1323.84607","0.00256","312.57474"
"98.84000","0.08219","1325.85767","0.00256","313.04971"
"98.98000","0.08231","1328.28687","0.00256","313.62326"
"99.12000","0.08245","1330.47681","0.00257","314.14035"
"99.26000","0.08255","1332.95544","0.00257","314.72559"
"99.40000","0.08269","1335.17249","0.00258","315.24905"
"99.54000","0.08279","1337.55676","0.00258","315.81201"
"99.68000","0.08293","1339.80237","0.00258","316.34222"
"99.82000","0.08304","1341.95715","0.00259","316.85098"
"99.96000","0.08314","1344.25171","0.00259","317.39276"
"100.10000","0.08327","1346.32629","0.00259","317.88257"
"100.24000","0.08338","1348.50842","0.00260","318.39780"
"100.38000","0.08349","1350.65295","0.00260","318.90414"
"100.52000","0.08360","1352.64233","0.00260","319.37387"
"100.66000","0.08369","1354.66162","0.00261","319.85065"
"100.80000","0.08381","1356.69922","0.00261","320.33176"
"100.94000","0.08392","1358.85608","0.00261","320.84100"
"101.08000","0.08403","1360.96973","0.00262","321.34006"
"101.22000","0.08416","1363.30139","0.00262","321.89059"
"101.36000","0.08427","1365.28113","0.00262","322.35803"
"101.50000","0.08438","1368.14038","0.00263","323.03314"
"101.64000","0.08451","1369.87952","0.00263","323.44376"
"101.78000","0.08462","1372.14075","0.00264","323.97766"
"101.92000","0.08475","1374.93958","0.00264","324.63849"
"102.06000","0.08486","1376.63684","0.00264","325.03925"
"102.20000","0.08499","1379.53687","0.00265","325.72397"
"102.34000","0.08510","1381.48499","0.00265","326.18393"
"102.48000","0.08523","1384.34961","0.00265","326.86032"
"102.62000","0.08537","1386.62927","0.00266","327.39856"
"102.76000","0.08550","1389.56714","0.00266","328.09222"
"102.90000","0.08561","1391.69482","0.00267","328.59460"
"103.04000","0.08571","1393.78479","0.00267","329.08804"
"103.18000","0.08585","1396.37048","0.00267","329.69858"
"103.32000","0.08596","1398.55359","0.00268","330.21402"
"103.46000","0.08607","1400.56104","0.00268","330.68802"
"103.60000","0.08620","1402.75244","0.00268","331.20541"
"103.74000","0.08630","1405.06909","0.00269","331.75241"
"103.88000","0.08641","1407.35571","0.00269","332.29230"
"104.02000","0.08654","1409.39026","0.00270","332.77267"
"104.16000","0.08665","1411.96021","0.00270","333.37949"
"104.30000","0.08676","1414.00159","0.00270","333.86148"
"104.44000","0.08687","1415.71875","0.00271","334.26691"
"104.58000","0.08697","1417.90259","0.00271","334.78253"
"104.72000","0.08708","1420.17896","0.00271","335.32001"
"104.86000","0.08720","1422.46973","0.00272","335.86090"
"105.00000","0.08732","1424.90466","0.00272","336.43579"
"105.14000","0.08743","1426.82507","0.00272","336.88922"
"105.28000","0.08756","1429.33069","0.00273","337.48083"
"105.42000","0.08770","1431.87915","0.00273","338.08255"
"105.56000","0.08780","1434.37036","0.00273","338.67078"
"105.70000","0.08794","1436.59412","0.00274","339.19580"
"105.84000","0.08804","1439.16040","0.00274","339.80176"
"105.98000","0.08816","1441.46423","0.00275","340.34570"
"106.12000","0.08829","1443.59924","0.00275","340.84979"
"106.26000","0.08839","1445.68115","0.00275","341.34137"
"106.40000","0.08851","1447.97168","0.00276","341.88217"
"106.54000","0.08863","1449.65015","0.00276","342.27850"
"106.68000","0.08871","1452.17651","0.00276","342.87500"
"106.82000","0.08882","1454.31567","0.00277","343.38007"
"106.96000","0.08893","1455.83362","0.00277","343.73846"
"107.10000","0.08906","1458.39832","0.00277","344.34402"
"107.24000","0.08917","1460.26062","0.00278","344.78375"
"107.38000","0.08928","1462.92749","0.00278","345.41342"
"107.52000","0.08940","1465.07385","0.00278","345.92020"
"107.66000","0.08952","1467.21436","0.00279","346.42560"
"107.80000","0.08963","1470.05688","0.00279","347.09674"
"107.94000","0.08976","1471.88855","0.00280","347.52924"
"108.08000","0.08987","1474.03931","0.00280","348.03705"
"108.22000","0.09000","1476.55701","0.00280","348.63150"
"108.36000","0.09011","1478.69080","0.00281","349.13531"
"108.50000","0.09024","1481.58203","0.00281","349.81796"
"108.64000","0.09038","1484.23877","0.00281","350.44525"
"108.78000","0.09051","1486.95911","0.00282","351.08755"
"108.92000","0.09064","1489.24817","0.00282","351.62802"
"109.06000","0.09075","1491.52087","0.00283","352.16464"
"109.20000","0.09086","1493.88013","0.00283","352.72168"
"109.34000","0.09099","1496.36316","0.00283","353.30795"
"109.48000","0.09110","1498.47034","0.00284","353.80548"
"109.62000","0.09121","1500.72449","0.00284","354.33771"
"109.76000","0.09132","1503.07373","0.00284","354.89240"
"109.90000","0.09145","1505.32300","0.00285","355.42346"
"110.04000","0.09155","1507.46619","0.00285","355.92950"
"110.18000","0.09166","1509.98889","0.00285","356.52515"
"110.32000","0.09180","1511.68823","0.00286","356.92636"
"110.46000","0.09190","1513.81738","0.00286","357.42908"
"110.60000","0.09201","1516.54626","0.00287","358.07339"
"110.74000","0.09214","1519.10181","0.00287","358.67679"
"110.88000","0.09225","1521.07849","0.00287","359.14352"
"111.02000","0.09233","1522.97595","0.00288","359.59152"
"111.16000","0.09246","1525.54675","0.00288","360.19852"
"111.30000","0.09257","1527.51892","0.00288","360.66418"
"111.44000","0.09271","1530.43811","0.00289","361.35342"
"111.58000","0.09284","1532.74536","0.00289","361.89819"
"111.72000","0.09295","1535.30542","0.00289","362.50266"
"111.86000","0.09308","1537.50720","0.00290","363.02252"
"112.00000","0.09319","1539.49048","0.00290","363.49078"
"112.14000","0.09329","1542.33765","0.00291","364.16302"
"112.28000","0.09342","1544.41089","0.00291","364.65256"
"112.42000","0.09354","1546.53210","0.00291","365.15338"
"112.56000","0.09364","1548.69849","0.00292","365.66489"
"112.70000","0.09375","1550.74316","0.00292","366.14767"
"112.84000","0.09386","1552.83228","0.00292","366.64093"
"112.98000","0.09396","1554.78564","0.00293","367.10214"
"113.12000","0.09407","1557.19373","0.00293","367.67072"
"113.26000","0.09418","1559.25574","0.00293","368.15759"
"113.40000","0.09431","1561.35254","0.00294","368.65265"
"113.54000","0.09442","1564.03333","0.00294","369.28561"
"113.68000","0.09453","1566.06177","0.00294","369.76456"
"113.82000","0.09466","1568.76465","0.00295","370.40274"
"113.96000","0.09477","1570.92664","0.00295","370.91321"
"114.10000","0.09488","1572.92212","0.00295","371.38437"
"114.24000","0.09501","1575.47571","0.00296","371.98730"
"114.38000","0.09512","1577.62939","0.00296","372.49582"
"114.52000","0.09525","1580.50281","0.00297","373.17426"
"114.66000","0.09538","1582.62402","0.00297","373.67511"
"114.80000","0.09552","1585.65210","0.00297","374.39005"
"114.94000","0.09565","1588.23462","0.00298","374.99982"
"115.08000","0.09576","1590.39783","0.00298","375.51059"
"115.22000","0.09587","1592.75085","0.00299","376.06616"
"115.36000","0.09600","1595.04712","0.00299","376.60834"
"115.50000","0.09611","1597.43237","0.00299","377.17151"
"115.64000","0.09621","1599.74231","0.00300","377.71692"
"115.78000","0.09635","1602.27917","0.00300","378.31589"
"115.92000","0.09646","1604.60718","0.00300","378.86557"
"116.06000","0.09656","1606.83508","0.00301","379.39160"
"116.20000","0.09670","1609.05518","0.00301","379.91577"
"116.34000","0.09680","1611.19177","0.00301","380.42026"
"116.48000","0.09691","1613.95422","0.00302","381.07251"
"116.62000","0.09702","1615.54053","0.00302","381.44705"
"116.76000","0.09715","1618.76282","0.00303","382.20786"
"116.90000","0.09723","1619.88440","0.00303","382.47269"
"117.04000","0.09734","1622.80981","0.00303","383.16342"
"117.18000","0.09745","1624.76697","0.00303","383.62552"
"117.32000","0.09758","1626.74707","0.00304","384.09305"
"117.46000","0.09772","1629.68286","0.00304","384.78622"
"117.60000","0.09782","1632.16980","0.00305","385.37341"
"117.74000","0.09796","1634.87195","0.00305","386.01141"
"117.88000","0.09809","1636.75342","0.00305","386.45566"
"118.02000","0.09820","1639.97766","0.00306","387.21692"
"118.16000","0.09832","1641.76379","0.00306","387.63864"
"118.30000","0.09844","1644.37354","0.00307","388.25485"
"118.44000","0.09854","1646.97046","0.00307","388.86801"
"118.58000","0.09865","1648.72668","0.00307","389.28265"
"118.72000","0.09879","1651.06165","0.00308","389.83398"
"118.86000","0.09889","1653.22437","0.00308","390.34464"
"119.00000","0.09900","1655.81653","0.00308","390.95667"
"119.14000","0.09909","1657.43896","0.00309","391.33972"
"119.28000","0.09921","1659.54492","0.00309","391.83698"
"119.42000","0.09932","1661.70862","0.00309","392.34784"
"119.56000","0.09943","1664.15796","0.00310","392.92618"
"119.70000","0.09956","1666.53247","0.00310","393.48682"
"119.84000","0.09967","1668.42383","0.00310","393.93338"
"119.98000","0.09978","1670.65491","0.00311","394.46017"
"120.12000","0.09991","1673.00256","0.00311","395.01447"
"120.26000","0.10002","1675.46313","0.00311","395.59543"
"120.40000","0.10015","1677.79480","0.00312","396.14597"
"120.54000","0.10026","1680.23999","0.00312","396.72330"
"120.68000","0.10039","1682.69983","0.00313","397.30411"
"120.82000","0.10050","1685.28613","0.00313","397.91476"
"120.96000","0.10066","1688.09839","0.00313","398.57877"
"121.10000","0.10077","1690.68970","0.00314","399.19061"
"121.24000","0.10090","1692.96484","0.00314","399.72778"
"121.38000","0.10101","1695.20178","0.00315","400.25595"
"121.52000","0.10113","1697.23682","0.00315","400.73645"
"121.66000","0.10125","1699.74548","0.00315","401.32877"
"121.80000","0.10136","1702.13000","0.00316","401.89178"
"121.94000","0.10146","1704.37512","0.00316","402.42188"
"122.08000","0.10160","1706.68359","0.00316","402.96695"
"122.10900","0.10184","992.52130","0.00317","234.34529"