File: samples/m5s3.csv
Time measurement,Displacement,Primary force measurement,Composite strain,Flexure stress
(s),(mm),(N),(mm/mm),(MPa)
"0.00000","0.00000","-0.00043","0.00000","-0.00010"
"0.12000","0.00000","-0.18222","0.00000","-0.04302"
"0.24000","0.00016","1.08489","0.00001","0.25615"
"0.36000","0.00016","1.10243","0.00001","0.26030"
"0.48000","0.00016","0.89635","0.00001","0.21164"
"0.60000","0.00021","1.32800","0.00001","0.31356"
"0.72000","0.00035","2.36540","0.00001","0.55850"
"0.84000","0.00048","3.71410","0.00002","0.87694"
"0.96000","0.00062","5.03141","0.00002","1.18797"
"1.08000","0.00072","5.86894","0.00002","1.38572"
"1.20000","0.00083","6.94173","0.00003","1.63902"
"1.32000","0.00091","8.17371","0.00003","1.92990"
"1.44000","0.00102","9.11629","0.00003","2.15246"
"1.56000","0.00112","10.47298","0.00004","2.47279"
"1.68000","0.00123","11.60940","0.00004","2.74111"
"1.80000","0.00134","12.58399","0.00004","2.97122"
"1.92000","0.00142","13.74668","0.00004","3.24574"
"2.04000","0.00153","15.19516","0.00005","3.58774"
"2.16000","0.00163","16.00484","0.00005","3.77892"
"2.28000","0.00171","17.39431","0.00005","4.10699"
"2.40000","0.00182","18.57123","0.00006","4.38487"
"2.52000","0.00193","19.54428","0.00006","4.61462"
"2.64000","0.00201","20.84973","0.00006","4.92285"
"2.76000","0.00212","22.43168","0.00007","5.29637"
"2.88000","0.00222","23.45007","0.00007","5.53682"
"3.00000","0.00233","24.63922","0.00007","5.81759"
"3.12000","0.00244","25.80070","0.00008","6.09183"
"3.24000","0.00252","27.18597","0.00008","6.41891"
"3.36000","0.00262","28.19320","0.00008","6.65673"
"3.48000","0.00273","29.64156","0.00009","6.99870"
"3.60000","0.00284","30.87102","0.00009","7.28899"
"3.72000","0.00292","32.00261","0.00009","7.55617"
"3.84000","0.00303","32.82368","0.00009","7.75004"
"3.96000","0.00313","34.20415","0.00010","8.07598"
"4.08000","0.00324","35.36636","0.00010","8.35039"
"4.20000","0.00335","36.98631","0.00010","8.73288"
"4.32000","0.00343","37.68161","0.00011","8.89705"
"4.44000","0.00354","39.09233","0.00011","9.23013"
"4.56000","0.00364","40.04555","0.00011","9.45520"
"4.68000","0.00372","41.45058","0.00012","9.78694"
"4.80000","0.00383","42.59135","0.00012","10.05629"
"4.92000","0.00394","43.70037","0.00012","10.31814"
"5.04000","0.00402","44.98575","0.00013","10.62163"
"5.16000","0.00412","46.50242","0.00013","10.97974"
"5.28000","0.00423","47.24121","0.00013","11.15417"
"5.40000","0.00431","48.59954","0.00013","11.47489"
"5.52000","0.00442","49.71552","0.00014","11.73839"
"5.64000","0.00453","50.95531","0.00014","12.03111"
"5.76000","0.00463","52.11626","0.00014","12.30523"
"5.88000","0.00471","53.59178","0.00015","12.65361"
"6.00000","0.00482","54.69624","0.00015","12.91439"
"6.12000","0.00493","56.05204","0.00015","13.23451"
"6.24000","0.00504","57.23680","0.00016","13.51424"
"6.36000","0.00514","58.50321","0.00016","13.81326"
"6.48000","0.00525","59.59528","0.00016","14.07111"
"6.60000","0.00536","60.94996","0.00017","14.39096"
"6.72000","0.00546","61.87595","0.00017","14.60960"
"6.84000","0.00557","63.96992","0.00017","15.10401"
"6.96000","0.00568","64.40230","0.00018","15.20610"
"7.08000","0.00579","66.08334","0.00018","15.60301"
"7.20000","0.00588","67.28393","0.00018","15.88648"
"7.32000","0.00597","68.31376","0.00019","16.12964"
"7.44000","0.00608","69.89798","0.00019","16.50369"
"7.56000","0.00619","70.76958","0.00019","16.70948"
"7.68000","0.00627","71.92927","0.00020","16.98330"
"7.80000","0.00637","72.99088","0.00020","17.23396"
"7.92000","0.00648","74.74173","0.00020","17.64735"
"8.04000","0.00657","76.24384","0.00020","18.00202"
"8.16000","0.00667","77.49420","0.00021","18.29724"
"8.28000","0.00678","78.98348","0.00021","18.64888"
"8.40000","0.00688","80.02854","0.00021","18.89563"
"8.52000","0.00696","81.84212","0.00022","19.32383"
"8.64000","0.00707","82.85025","0.00022","19.56186"
"8.76000","0.00718","84.33813","0.00022","19.91317"
"8.88000","0.00727","85.24338","0.00023","20.12691"
"9.00000","0.00737","87.05771","0.00023","20.55529"
"9.12000","0.00747","87.80678","0.00023","20.73215"
"9.24000","0.00758","89.36372","0.00024","21.09977"
"9.36000","0.00766","90.80486","0.00024","21.44003"
"9.48000","0.00777","91.91409","0.00024","21.70193"
"9.60000","0.00787","93.24979","0.00025","22.01731"
"9.72000","0.00798","94.89576","0.00025","22.40594"
"9.84000","0.00809","96.17935","0.00025","22.70901"
"9.96000","0.00817","97.43863","0.00025","23.00634"
"10.08000","0.00828","98.64061","0.00026","23.29014"
"10.20000","0.00836","99.88585","0.00026","23.58416"
"10.32000","0.00846","101.34932","0.00026","23.92970"
"10.44000","0.00857","102.78033","0.00027","24.26758"
"10.56000","0.00867","104.01742","0.00027","24.55967"
"10.68000","0.00876","105.66700","0.00027","24.94915"
"10.80000","0.00884","106.20403","0.00028","25.07595"
"10.92000","0.00892","107.55061","0.00028","25.39389"
"11.04000","0.00903","108.69054","0.00028","25.66304"
"11.16000","0.00914","109.60607","0.00028","25.87921"
"11.28000","0.00921","111.59824","0.00029","26.34958"
"11.40000","0.00932","112.68859","0.00029","26.60703"
"11.52000","0.00943","114.15716","0.00029","26.95377"
"11.64000","0.00953","115.47789","0.00030","27.26561"
"11.76000","0.00962","116.90881","0.00030","27.60347"
"11.88000","0.00972","118.19276","0.00030","27.90662"
"12.00000","0.00983","119.51833","0.00031","28.21960"
"12.12000","0.00994","121.09933","0.00031","28.59290"
"12.24000","0.01004","122.41550","0.00031","28.90366"
"12.36000","0.01013","123.88367","0.00032","29.25031"
"12.48000","0.01023","125.42934","0.00032","29.61526"
"12.60000","0.01034","127.00642","0.00032","29.98763"
"12.72000","0.01047","128.74374","0.00033","30.39783"
"12.84000","0.01058","130.24815","0.00033","30.75303"
"12.96000","0.01069","131.27734","0.00033","30.99604"
"13.08000","0.01077","133.13092","0.00034","31.43369"
"13.20000","0.01087","134.19162","0.00034","31.68413"
"13.32000","0.01098","135.49524","0.00034","31.99193"
"13.44000","0.01109","137.16925","0.00035","32.38718"
"13.56000","0.01117","138.49809","0.00035","32.70094"
"13.68000","0.01128","140.08672","0.00035","33.07603"
"13.80000","0.01138","141.17378","0.00035","33.33270"
"13.92000","0.01149","142.62253","0.00036","33.67476"
"14.04000","0.01157","144.10812","0.00036","34.02553"
"14.16000","0.01168","145.40929","0.00036","34.33274"
"14.28000","0.01178","146.58702","0.00037","34.61082"
"14.40000","0.01187","148.10785","0.00037","34.96991"
"14.52000","0.01197","149.58665","0.00037","35.31907"
"14.64000","0.01206","150.70914","0.00038","35.58410"
"14.76000","0.01216","152.18694","0.00038","35.93303"
"14.88000","0.01227","153.38641","0.00038","36.21624"
"15.00000","0.01235","154.94313","0.00038","36.58379"
"15.12000","0.01244","156.06297","0.00039","36.84820"
"15.24000","0.01254","157.33928","0.00039","37.14955"
"15.36000","0.01264","158.60344","0.00039","37.44803"
"15.48000","0.01275","159.96828","0.00040","37.77029"
"15.60000","0.01283","161.62970","0.00040","38.16257"
"15.72000","0.01294","162.82953","0.00040","38.44586"
"15.84000","0.01304","164.04237","0.00041","38.73222"
"15.96000","0.01315","166.10913","0.00041","39.22021"
"16.08000","0.01326","166.92889","0.00041","39.41376"
"16.20000","0.01337","168.72604","0.00042","39.83809"
"16.32000","0.01347","169.76154","0.00042","40.08258"
"16.44000","0.01358","171.75740","0.00042","40.55383"
"16.56000","0.01366","172.96130","0.00043","40.83809"
"16.68000","0.01377","173.98560","0.00043","41.07993"
"16.80000","0.01385","175.18985","0.00043","41.36427"
"16.92000","0.01393","176.07181","0.00043","41.57251"
"17.04000","0.01404","177.70055","0.00044","41.95707"
"17.16000","0.01412","178.61768","0.00044","42.17361"
"17.28000","0.01422","180.58109","0.00044","42.63720"
"17.40000","0.01433","182.12082","0.00045","43.00075"
"17.52000","0.01441","183.18628","0.00045","43.25232"
"17.64000","0.01452","185.19981","0.00045","43.72773"
"17.76000","0.01463","186.15091","0.00046","43.95230"
"17.88000","0.01473","187.83934","0.00046","44.35095"
"18.00000","0.01481","189.02058","0.00046","44.62986"
"18.12000","0.01492","190.67259","0.00046","45.01992"
"18.24000","0.01503","192.31142","0.00047","45.40686"
"18.36000","0.01513","193.54016","0.00047","45.69698"
"18.48000","0.01524","195.09654","0.00047","46.06446"
"18.60000","0.01535","196.66606","0.00048","46.43504"
"18.72000","0.01543","197.95419","0.00048","46.73918"
"18.84000","0.01556","199.67924","0.00048","47.14648"
"18.96000","0.01567","201.45512","0.00049","47.56579"
"19.08000","0.01578","203.29370","0.00049","47.99990"
"19.20000","0.01588","204.27310","0.00049","48.23115"
"19.32000","0.01599","206.08632","0.00050","48.65927"
"19.44000","0.01607","207.61955","0.00050","49.02128"
"19.56000","0.01618","208.72350","0.00050","49.28193"
"19.68000","0.01629","210.10529","0.00051","49.60819"
"19.80000","0.01639","211.83067","0.00051","50.01557"
"19.92000","0.01647","213.51636","0.00051","50.41358"
"20.04000","0.01658","214.94611","0.00052","50.75116"
"20.16000","0.01668","216.41333","0.00052","51.09759"
"20.28000","0.01677","217.59288","0.00052","51.37609"
"20.40000","0.01688","219.38991","0.00053","51.80039"
"20.52000","0.01698","220.76880","0.00053","52.12597"
"20.64000","0.01706","222.37799","0.00053","52.50591"
"20.76000","0.01717","223.79359","0.00053","52.84015"
"20.88000","0.01728","225.02420","0.00054","53.13071"
"21.00000","0.01736","226.52161","0.00054","53.48426"
"21.12000","0.01746","228.27129","0.00054","53.89738"
"21.24000","0.01757","229.68723","0.00055","54.23170"
"21.36000","0.01768","230.88832","0.00055","54.51530"
"21.48000","0.01776","232.39844","0.00055","54.87185"
"21.60000","0.01787","234.03526","0.00056","55.25832"
"21.72000","0.01797","235.47650","0.00056","55.59861"
"21.84000","0.01808","237.05418","0.00056","55.97112"
"21.96000","0.01816","238.89639","0.00057","56.40609"
"22.08000","0.01827","239.93196","0.00057","56.65060"
"22.20000","0.01838","241.78651","0.00057","57.08848"
"22.32000","0.01848","243.31854","0.00058","57.45021"
"22.44000","0.01856","244.56708","0.00058","57.74500"
"22.56000","0.01867","246.06100","0.00058","58.09773"
"22.68000","0.01878","247.47015","0.00058","58.43045"
"22.80000","0.01886","248.75679","0.00059","58.73424"
"22.92000","0.01894","249.96513","0.00059","59.01954"
"23.04000","0.01904","251.46886","0.00059","59.37459"
"23.16000","0.01912","252.96835","0.00060","59.72864"
"23.28000","0.01923","254.20287","0.00060","60.02012"
"23.40000","0.01931","255.66650","0.00060","60.36570"
"23.52000","0.01942","257.41525","0.00060","60.77860"
"23.64000","0.01953","258.95297","0.00061","61.14167"
"23.76000","0.01963","260.13513","0.00061","61.42079"
"23.88000","0.01971","261.86346","0.00061","61.82887"
"24.00000","0.01982","263.24481","0.00062","62.15502"
"24.12000","0.01993","264.68030","0.00062","62.49396"
"24.24000","0.02001","266.27676","0.00062","62.87090"
"24.36000","0.02012","267.89807","0.00063","63.25371"
"24.48000","0.02022","269.22153","0.00063","63.56619"
"24.60000","0.02033","270.80435","0.00063","63.93991"
"24.72000","0.02044","272.42838","0.00064","64.32336"
"24.84000","0.02054","274.19373","0.00064","64.74018"
"24.96000","0.02068","275.56253","0.00064","65.06337"
"25.08000","0.02079","277.32800","0.00065","65.48022"
"25.20000","0.02089","279.01370","0.00065","65.87823"
"25.32000","0.02097","280.41782","0.00065","66.20975"
"25.44000","0.02108","281.85126","0.00066","66.54821"
"25.56000","0.02119","283.63486","0.00066","66.96934"
"25.68000","0.02130","285.07419","0.00066","67.30918"
"25.80000","0.02137","286.47635","0.00067","67.64024"
"25.92000","0.02148","288.14944","0.00067","68.03528"
"26.04000","0.02159","289.57837","0.00067","68.37267"
"26.16000","0.02167","291.14874","0.00067","68.74345"
"26.28000","0.02178","292.89954","0.00068","69.15683"
"26.40000","0.02188","293.85669","0.00068","69.38283"
"26.52000","0.02196","295.71451","0.00068","69.82148"
"26.64000","0.02207","297.23779","0.00069","70.18114"
"26.76000","0.02218","298.88220","0.00069","70.56940"
"26.88000","0.02226","299.91968","0.00069","70.81436"
"27.00000","0.02237","301.45670","0.00070","71.17727"
"27.12000","0.02245","302.93958","0.00070","71.52740"
"27.24000","0.02253","304.45795","0.00070","71.88590"
"27.36000","0.02263","305.86304","0.00070","72.21766"
"27.48000","0.02274","307.53506","0.00071","72.61244"
"27.60000","0.02285","309.33957","0.00071","73.03851"
"27.72000","0.02293","310.84302","0.00071","73.39349"
"27.84000","0.02304","312.41675","0.00072","73.76506"
"27.96000","0.02314","313.92557","0.00072","74.12131"
"28.08000","0.02325","315.50073","0.00072","74.49323"
"28.20000","0.02336","317.07651","0.00073","74.86528"
"28.32000","0.02346","318.92325","0.00073","75.30132"
"28.44000","0.02357","320.62143","0.00073","75.70228"
"28.56000","0.02368","322.40027","0.00074","76.12228"
"28.68000","0.02376","324.24655","0.00074","76.55821"
"28.80000","0.02387","325.69379","0.00074","76.89992"
"28.92000","0.02397","327.12271","0.00075","77.23730"
"29.04000","0.02405","329.02292","0.00075","77.68597"
"29.16000","0.02413","330.22198","0.00075","77.96908"
"29.28000","0.02423","331.61935","0.00075","78.29901"
"29.40000","0.02432","333.03558","0.00076","78.63340"
"29.52000","0.02443","334.56143","0.00076","78.99367"
"29.64000","0.02453","336.16898","0.00076","79.37323"
"29.76000","0.02462","337.75162","0.00077","79.74690"
"29.88000","0.02472","339.29166","0.00077","80.11053"
"30.00000","0.02481","341.31229","0.00077","80.58762"
"30.12000","0.02491","342.81720","0.00078","80.94295"
"30.24000","0.02502","344.32236","0.00078","81.29833"
"30.36000","0.02513","346.10562","0.00078","81.71938"
"30.48000","0.02523","347.46869","0.00079","82.04121"
"30.60000","0.02534","349.30316","0.00079","82.47435"
"30.72000","0.02544","350.94672","0.00079","82.86241"
"30.84000","0.02554","352.64386","0.00080","83.26313"
"30.96000","0.02563","354.32700","0.00080","83.66054"
"31.08000","0.02576","355.89322","0.00080","84.03034"
"31.20000","0.02588","357.97821","0.00081","84.52263"
"31.32000","0.02598","360.15677","0.00081","85.03701"
"31.44000","0.02609","361.59897","0.00081","85.37753"
"31.56000","0.02617","363.22977","0.00081","85.76258"
"31.68000","0.02628","364.78598","0.00082","86.13002"
"31.80000","0.02638","366.62592","0.00082","86.56445"
"31.92000","0.02649","367.94675","0.00082","86.87631"
"32.04000","0.02657","369.68805","0.00083","87.28745"
"32.16000","0.02668","371.42801","0.00083","87.69827"
"32.28000","0.02679","372.66486","0.00083","87.99031"
"32.40000","0.02687","374.16891","0.00084","88.34544"
"32.52000","0.02697","376.17300","0.00084","88.81862"
"32.64000","0.02708","377.58813","0.00084","89.15275"
"32.76000","0.02717","379.10632","0.00085","89.51121"
"32.88000","0.02727","380.76669","0.00085","89.90324"
"33.00000","0.02737","382.47873","0.00085","90.30747"
"33.12000","0.02748","383.97559","0.00086","90.66090"
"33.24000","0.02756","385.50626","0.00086","91.02231"
"33.36000","0.02767","387.14099","0.00086","91.40829"
"33.48000","0.02775","388.48209","0.00086","91.72493"
"33.60000","0.02786","390.04819","0.00087","92.09470"
"33.72000","0.02794","391.80414","0.00087","92.50931"
"33.84000","0.02804","393.50162","0.00087","92.91010"
"33.96000","0.02815","395.10681","0.00088","93.28910"
"34.08000","0.02826","396.98877","0.00088","93.73345"
"34.20000","0.02837","398.80942","0.00088","94.16333"
"34.32000","0.02847","400.44855","0.00089","94.55035"
"34.44000","0.02858","401.89828","0.00089","94.89265"
"34.56000","0.02868","403.75781","0.00089","95.33170"
"34.68000","0.02877","405.48825","0.00090","95.74028"
"34.80000","0.02887","407.32687","0.00090","96.17439"
"34.92000","0.02896","408.69540","0.00090","96.49752"
"35.04000","0.02906","410.23193","0.00091","96.86031"
"35.16000","0.02914","411.57150","0.00091","97.17660"
"35.28000","0.02925","413.19202","0.00091","97.55922"
"35.40000","0.02933","414.73965","0.00091","97.92464"
"35.52000","0.02943","415.87613","0.00092","98.19297"
"35.64000","0.02952","417.68033","0.00092","98.61896"
"35.76000","0.02963","419.94577","0.00092","99.15385"
"35.88000","0.02973","420.96707","0.00093","99.39500"
"36.00000","0.02981","422.64413","0.00093","99.79097"
"36.12000","0.02992","424.75018","0.00093","100.28823"
"36.24000","0.03003","426.23425","0.00094","100.63864"
"36.36000","0.03011","428.02179","0.00094","101.06069"
"36.48000","0.03021","429.90479","0.00094","101.50529"
"36.60000","0.03032","431.56808","0.00094","101.89802"
"36.72000","0.03043","433.31064","0.00095","102.30945"
"36.84000","0.03054","434.74930","0.00095","102.64913"
"36.96000","0.03064","437.18857","0.00095","103.22507"
"37.08000","0.03075","438.41080","0.00096","103.51366"
"37.20000","0.03086","440.88354","0.00096","104.09750"
"37.32000","0.03096","442.44449","0.00096","104.46606"
"37.44000","0.03107","444.97565","0.00097","105.06369"
"37.56000","0.03118","446.59003","0.00097","105.44486"
"37.68000","0.03129","448.06641","0.00097","105.79345"
"37.80000","0.03139","449.73331","0.00098","106.18703"
"37.92000","0.03147","451.63004","0.00098","106.63486"
"38.04000","0.03158","453.07498","0.00098","106.97603"
"38.16000","0.03169","454.81641","0.00099","107.38720"
"38.28000","0.03177","456.72879","0.00099","107.83874"
"38.40000","0.03188","458.48032","0.00099","108.25229"
"38.52000","0.03198","459.96857","0.00100","108.60368"
"38.64000","0.03206","461.76385","0.00100","109.02757"
"38.76000","0.03217","463.15781","0.00100","109.35670"
"38.88000","0.03228","465.09247","0.00101","109.81349"
"39.00000","0.03236","466.65039","0.00101","110.18134"
"39.12000","0.03246","468.62973","0.00101","110.64868"
"39.24000","0.03257","470.08664","0.00101","110.99268"
"39.36000","0.03265","471.94482","0.00102","111.43141"
"39.48000","0.03276","473.33716","0.00102","111.76015"
"39.60000","0.03284","475.05200","0.00102","112.16505"
"39.72000","0.03295","476.93484","0.00103","112.60961"
"39.84000","0.03304","478.41138","0.00103","112.95824"
"39.96000","0.03313","480.55789","0.00103","113.46505"
"40.08000","0.03324","481.88287","0.00104","113.77789"
"40.20000","0.03335","483.88638","0.00104","114.25095"
"40.32000","0.03346","485.84564","0.00104","114.71355"
"40.44000","0.03356","487.50079","0.00105","115.10435"
"40.56000","0.03367","489.20215","0.00105","115.50606"
"40.68000","0.03378","491.21045","0.00105","115.98024"
"40.80000","0.03388","493.11658","0.00106","116.43030"
"40.92000","0.03396","494.68478","0.00106","116.80057"
"41.04000","0.03407","496.38144","0.00106","117.20116"
"41.16000","0.03418","498.46341","0.00106","117.69274"
"41.28000","0.03426","500.17056","0.00107","118.09582"
"41.40000","0.03436","501.62372","0.00107","118.43893"
"41.52000","0.03445","503.40170","0.00107","118.85873"
"41.64000","0.03453","504.86255","0.00108","119.20365"
"41.76000","0.03463","506.48688","0.00108","119.58717"
"41.88000","0.03471","508.11035","0.00108","119.97050"
"42.00000","0.03482","509.65497","0.00108","120.33520"
"42.12000","0.03493","511.64078","0.00109","120.80407"
"42.24000","0.03501","513.12598","0.00109","121.15474"
"42.36000","0.03512","515.21521","0.00109","121.64803"
"42.48000","0.03522","517.22852","0.00110","122.12339"
"42.60000","0.03533","518.88824","0.00110","122.51527"
"42.72000","0.03544","520.57916","0.00110","122.91452"
"42.84000","0.03553","522.64960","0.00111","123.40337"
"42.96000","0.03563","524.22064","0.00111","123.77431"
"43.08000","0.03573","526.21167","0.00111","124.24442"
"43.20000","0.03584","528.03687","0.00112","124.67536"
"43.32000","0.03595","530.21570","0.00112","125.18981"
"43.44000","0.03608","532.20886","0.00112","125.66042"
"43.56000","0.03619","534.45697","0.00113","126.19122"
"43.68000","0.03627","536.20801","0.00113","126.60466"
"43.80000","0.03638","537.81213","0.00113","126.98341"
"43.92000","0.03648","539.66742","0.00114","127.42147"
"44.04000","0.03659","541.80762","0.00114","127.92679"
"44.16000","0.03669","543.52356","0.00114","128.33194"
"44.28000","0.03678","545.33545","0.00115","128.75975"
"44.40000","0.03688","546.95746","0.00115","129.14273"
"44.52000","0.03696","548.43903","0.00115","129.49254"
"44.64000","0.03707","550.58112","0.00115","129.99831"
"44.76000","0.03718","552.07410","0.00116","130.35081"
"44.88000","0.03729","554.10242","0.00116","130.82973"
"45.00000","0.03737","555.57855","0.00116","131.17827"
"45.12000","0.03747","557.50995","0.00117","131.63429"
"45.24000","0.03758","559.00006","0.00117","131.98611"
"45.36000","0.03766","560.91998","0.00117","132.43944"
"45.48000","0.03777","562.69244","0.00118","132.85793"
"45.60000","0.03785","564.31573","0.00118","133.24121"
"45.72000","0.03796","565.69238","0.00118","133.56625"
"45.84000","0.03804","567.59076","0.00118","134.01448"
"45.96000","0.03814","569.26660","0.00119","134.41016"
"46.08000","0.03825","571.23907","0.00119","134.87589"
"46.20000","0.03836","572.81494","0.00119","135.24797"
"46.32000","0.03846","575.24615","0.00120","135.82201"
"46.44000","0.03857","576.61792","0.00120","136.14589"
"46.56000","0.03868","578.59814","0.00120","136.61345"
"46.68000","0.03878","580.43701","0.00121","137.04762"
"46.80000","0.03887","582.22058","0.00121","137.46873"
"46.92000","0.03897","584.06421","0.00121","137.90404"
"47.04000","0.03908","585.69928","0.00122","138.29010"
"47.16000","0.03916","587.49542","0.00122","138.71419"
"47.28000","0.03927","589.52893","0.00122","139.19432"
"47.40000","0.03937","590.84448","0.00123","139.50494"
"47.52000","0.03946","593.17169","0.00123","140.05441"
"47.64000","0.03954","594.05292","0.00123","140.26248"
"47.76000","0.03964","595.87860","0.00123","140.69356"
"47.88000","0.03972","597.53156","0.00124","141.08383"
"48.00000","0.03983","598.96588","0.00124","141.42249"
"48.12000","0.03991","601.33057","0.00124","141.98082"
"48.24000","0.04002","603.02899","0.00125","142.38184"
"48.36000","0.04012","605.20709","0.00125","142.89612"
"48.48000","0.04023","606.55273","0.00125","143.21384"
"48.60000","0.04031","608.57990","0.00126","143.69247"
"48.72000","0.04042","610.55090","0.00126","144.15784"
"48.84000","0.04053","612.23956","0.00126","144.55655"
"48.96000","0.04063","614.15094","0.00127","145.00786"
"49.08000","0.04074","616.03046","0.00127","145.45163"
"49.20000","0.04084","618.29492","0.00127","145.98630"
"49.32000","0.04093","619.75385","0.00127","146.33076"
"49.44000","0.04104","621.74530","0.00128","146.80096"
"49.56000","0.04117","623.79803","0.00128","147.28564"
"49.68000","0.04128","626.10114","0.00129","147.82942"
"49.80000","0.04138","628.13428","0.00129","148.30948"
"49.92000","0.04149","629.79480","0.00129","148.70154"
"50.04000","0.04157","632.14117","0.00129","149.25555"
"50.16000","0.04168","634.18616","0.00130","149.73839"
"50.28000","0.04179","636.00104","0.00130","150.16690"
"50.40000","0.04189","637.63226","0.00130","150.55205"
"50.52000","0.04197","639.93774","0.00131","151.09641"
"50.64000","0.04208","641.67407","0.00131","151.50636"
"50.76000","0.04219","643.51538","0.00131","151.94112"
"50.88000","0.04227","645.61298","0.00132","152.43639"
"51.00000","0.04238","647.19183","0.00132","152.80917"
"51.12000","0.04248","649.02948","0.00132","153.24306"
"51.24000","0.04256","650.96252","0.00133","153.69948"
"51.36000","0.04267","652.73816","0.00133","154.11873"
"51.48000","0.04275","654.65167","0.00133","154.57053"
"51.60000","0.04286","656.12701","0.00133","154.91887"
"51.72000","0.04294","657.80304","0.00134","155.31461"
"51.84000","0.04304","659.52136","0.00134","155.72031"
"51.96000","0.04315","661.54346","0.00134","156.19775"
"52.08000","0.04323","663.25891","0.00135","156.60278"
"52.20000","0.04334","665.14288","0.00135","157.04762"
"52.32000","0.04345","667.07123","0.00135","157.50291"
"52.44000","0.04355","669.21179","0.00136","158.00833"
"52.56000","0.04363","670.48462","0.00136","158.30885"
"52.68000","0.04374","672.89868","0.00136","158.87885"
"52.80000","0.04385","674.41742","0.00137","159.23744"
"52.92000","0.04396","676.72864","0.00137","159.78314"
"53.04000","0.04409","678.78674","0.00137","160.26909"
"53.16000","0.04417","680.86755","0.00138","160.76039"
"53.28000","0.04428","682.63446","0.00138","161.17757"
"53.40000","0.04436","684.35388","0.00138","161.58354"
"53.52000","0.04446","685.88348","0.00138","161.94470"
"53.64000","0.04454","687.60028","0.00139","162.35005"
"53.76000","0.04465","688.97394","0.00139","162.67439"
"53.88000","0.04473","690.77411","0.00139","163.09943"
"54.00000","0.04484","692.58716","0.00140","163.52751"
"54.12000","0.04492","694.35730","0.00140","163.94547"
"54.24000","0.04503","696.07324","0.00140","164.35062"
"54.36000","0.04511","697.91620","0.00140","164.78577"
"54.48000","0.04521","699.68689","0.00141","165.20384"
"54.60000","0.04532","701.65167","0.00141","165.66774"
"54.72000","0.04543","703.70490","0.00141","166.15254"
"54.84000","0.04554","705.84888","0.00142","166.65875"
"54.96000","0.04562","707.65704","0.00142","167.08568"
"55.08000","0.04572","709.48669","0.00142","167.51768"
"55.20000","0.04583","711.54999","0.00143","168.00485"
"55.32000","0.04594","713.21863","0.00143","168.39883"
"55.44000","0.04604","715.51587","0.00143","168.94124"
"55.56000","0.04615","717.33136","0.00144","169.36989"
"55.68000","0.04626","719.28931","0.00144","169.83218"
"55.80000","0.04639","721.79327","0.00144","170.42340"
"55.92000","0.04650","723.56750","0.00145","170.84232"
"56.04000","0.04658","725.59088","0.00145","171.32005"
"56.16000","0.04669","727.50049","0.00145","171.77094"
"56.28000","0.04679","729.36780","0.00146","172.21184"
"56.40000","0.04688","731.00787","0.00146","172.59908"
"56.52000","0.04698","732.70312","0.00146","172.99934"
"56.64000","0.04709","734.52008","0.00147","173.42834"
"56.76000","0.04717","736.61871","0.00147","173.92386"
"56.88000","0.04728","738.22961","0.00147","174.30420"
"57.00000","0.04738","740.21570","0.00148","174.77315"
"57.12000","0.04746","742.22815","0.00148","175.24831"
"57.24000","0.04757","743.91461","0.00148","175.64650"
"57.36000","0.04768","745.76288","0.00148","176.08289"
"57.48000","0.04779","747.77350","0.00149","176.55762"
"57.60000","0.04787","749.95819","0.00149","177.07346"
"57.72000","0.04797","752.12091","0.00149","177.58409"
"57.84000","0.04805","753.40381","0.00150","177.88699"
"57.96000","0.04814","755.10199","0.00150","178.28796"
"58.08000","0.04824","757.08984","0.00150","178.75731"
"58.20000","0.04835","758.86810","0.00151","179.17719"
"58.32000","0.04846","760.98517","0.00151","179.67705"
"58.44000","0.04856","762.82941","0.00151","180.11249"
"58.56000","0.04867","764.98706","0.00152","180.62193"
"58.68000","0.04878","767.04413","0.00152","181.10764"
"58.80000","0.04888","769.14252","0.00152","181.60309"
"58.92000","0.04897","771.12128","0.00152","182.07030"
"59.04000","0.04907","772.87555","0.00153","182.48450"
"59.16000","0.04918","774.48993","0.00153","182.86566"
"59.28000","0.04928","776.69653","0.00153","183.38667"
"59.40000","0.04937","778.50458","0.00154","183.81357"
"59.52000","0.04947","780.57007","0.00154","184.30125"
"59.64000","0.04955","782.23499","0.00154","184.69437"
"59.76000","0.04965","783.94751","0.00155","185.09871"
"59.88000","0.04974","785.53986","0.00155","185.47469"
"60.00000","0.04982","786.90778","0.00155","185.79765"
"60.12000","0.04993","789.26776","0.00155","186.35487"
"60.24000","0.05004","790.70312","0.00156","186.69379"
"60.36000","0.05012","792.75861","0.00156","187.17911"
"60.48000","0.05022","794.73358","0.00156","187.64542"
"60.60000","0.05033","796.59766","0.00157","188.08554"
"60.72000","0.05044","798.83130","0.00157","188.61293"
"60.84000","0.05052","800.37042","0.00157","188.97633"
"60.96000","0.05063","802.34387","0.00158","189.44229"
"61.08000","0.05073","804.55371","0.00158","189.96407"
"61.20000","0.05081","805.96472","0.00158","190.29721"
"61.32000","0.05092","808.14038","0.00159","190.81091"
"61.44000","0.05103","810.13098","0.00159","191.28091"
"61.56000","0.05113","812.44928","0.00159","191.82829"
"61.68000","0.05124","814.64026","0.00160","192.34561"
"61.80000","0.05138","816.60785","0.00160","192.81018"
"61.92000","0.05148","819.12073","0.00160","193.40349"
"62.04000","0.05159","820.64246","0.00161","193.76279"
"62.16000","0.05167","822.94037","0.00161","194.30536"
"62.28000","0.05178","824.65588","0.00161","194.71040"
"62.40000","0.05188","826.93762","0.00162","195.24915"
"62.52000","0.05199","828.49908","0.00162","195.61783"
"62.64000","0.05207","830.27289","0.00162","196.03664"
"62.76000","0.05218","832.61847","0.00162","196.59045"
"62.88000","0.05229","834.14825","0.00163","196.95166"
"63.00000","0.05237","836.24487","0.00163","197.44670"
"63.12000","0.05247","838.24921","0.00163","197.91994"
"63.24000","0.05258","839.85730","0.00164","198.29964"
"63.36000","0.05269","842.08044","0.00164","198.82454"
"63.48000","0.05277","844.21783","0.00164","199.32919"
"63.60000","0.05287","846.01117","0.00165","199.75262"
"63.72000","0.05296","847.51770","0.00165","200.10834"
"63.84000","0.05306","849.77045","0.00165","200.64023"
"63.96000","0.05314","851.33398","0.00165","201.00940"
"64.08000","0.05322","853.11755","0.00166","201.43053"
"64.20000","0.05333","854.67639","0.00166","201.79858"
"64.32000","0.05344","856.97687","0.00166","202.34175"
"64.44000","0.05354","858.81250","0.00167","202.77516"
"64.56000","0.05365","860.80048","0.00167","203.24455"
"64.68000","0.05376","863.07489","0.00167","203.78156"
"64.80000","0.05386","865.25836","0.00168","204.29710"
"64.92000","0.05397","867.30670","0.00168","204.78073"
"65.04000","0.05408","869.44318","0.00168","205.28519"
"65.16000","0.05417","871.38153","0.00169","205.74284"
"65.28000","0.05427","873.30835","0.00169","206.19780"
"65.40000","0.05438","875.09894","0.00169","206.62057"
"65.52000","0.05448","877.08038","0.00170","207.08841"
"65.64000","0.05456","879.23029","0.00170","207.59602"
"65.76000","0.05467","881.00610","0.00170","208.01532"
"65.88000","0.05478","882.78333","0.00171","208.43494"
"66.00000","0.05486","884.71167","0.00171","208.89024"
"66.12000","0.05494","886.37573","0.00171","209.28314"
"66.24000","0.05502","887.92108","0.00171","209.64803"
"66.36000","0.05513","889.88794","0.00172","210.11241"
"66.48000","0.05523","891.53156","0.00172","210.50049"
"66.60000","0.05531","893.38031","0.00172","210.93701"
"66.72000","0.05542","894.98468","0.00173","211.31581"
"66.84000","0.05553","897.09454","0.00173","211.81398"
"66.96000","0.05561","899.21448","0.00173","212.31451"
"67.08000","0.05571","901.20331","0.00174","212.78410"
"67.20000","0.05582","903.42535","0.00174","213.30875"
"67.32000","0.05593","905.03979","0.00174","213.68994"
"67.44000","0.05604","907.12231","0.00175","214.18164"
"67.56000","0.05614","909.22882","0.00175","214.67902"
"67.68000","0.05625","911.44720","0.00175","215.20280"
"67.80000","0.05636","913.37183","0.00176","215.65723"
"67.92000","0.05646","915.21741","0.00176","216.09299"
"68.04000","0.05657","918.01062","0.00176","216.75250"
"68.16000","0.05668","919.92487","0.00177","217.20447"
"68.28000","0.05679","921.61932","0.00177","217.60455"
"68.40000","0.05689","923.96185","0.00177","218.15765"
"68.52000","0.05697","925.72931","0.00177","218.57497"
"68.64000","0.05708","926.94226","0.00178","218.86136"
"68.76000","0.05719","929.27954","0.00178","219.41321"
"68.88000","0.05727","931.55438","0.00178","219.95033"
"69.00000","0.05738","933.24438","0.00179","220.34935"
"69.12000","0.05748","935.49530","0.00179","220.88083"
"69.24000","0.05759","937.57751","0.00179","221.37245"
"69.36000","0.05767","939.37274","0.00180","221.79633"
"69.48000","0.05778","941.29089","0.00180","222.24922"
"69.60000","0.05788","943.41644","0.00180","222.75110"
"69.72000","0.05796","945.21112","0.00181","223.17484"
"69.84000","0.05807","946.89624","0.00181","223.57271"
"69.96000","0.05818","948.94946","0.00181","224.05750"
"70.08000","0.05826","951.50824","0.00181","224.66165"
"70.20000","0.05837","952.88495","0.00182","224.98671"
"70.32000","0.05845","954.38446","0.00182","225.34076"
"70.44000","0.05855","956.59869","0.00182","225.86357"
"70.56000","0.05866","958.42670","0.00183","226.29518"
"70.68000","0.05877","960.77362","0.00183","226.84932"
"70.80000","0.05887","962.73425","0.00183","227.31224"
"70.92000","0.05898","965.09338","0.00184","227.86926"
"71.04000","0.05909","967.04578","0.00184","228.33025"
"71.16000","0.05917","969.05920","0.00184","228.80563"
"71.28000","0.05928","970.87964","0.00185","229.23546"
"71.40000","0.05938","972.87775","0.00185","229.70723"
"71.52000","0.05946","974.70752","0.00185","230.13927"
"71.64000","0.05957","977.03693","0.00186","230.68925"
"71.76000","0.05968","978.75464","0.00186","231.09483"
"71.88000","0.05976","980.95776","0.00186","231.61502"
"72.00000","0.05987","982.48541","0.00186","231.97571"
"72.12000","0.05995","984.55402","0.00187","232.46413"
"72.24000","0.06003","985.93494","0.00187","232.79018"
"72.36000","0.06013","987.90948","0.00187","233.25639"
"72.48000","0.06021","989.94037","0.00188","233.73590"
"72.60000","0.06032","991.60150","0.00188","234.12811"
"72.72000","0.06043","994.00708","0.00188","234.69611"
"72.84000","0.06054","995.95160","0.00189","235.15523"
"72.96000","0.06062","997.61102","0.00189","235.54703"
"73.08000","0.06072","999.53601","0.00189","236.00154"
"73.20000","0.06083","1001.20074","0.00189","236.39461"
"73.32000","0.06093","1003.43823","0.00190","236.92290"
"73.44000","0.06102","1005.28235","0.00190","237.35832"
"73.56000","0.06112","1007.04639","0.00190","237.77483"
"73.68000","0.06123","1008.99188","0.00191","238.23418"
"73.80000","0.06134","1011.23779","0.00191","238.76447"
"73.92000","0.06145","1013.42053","0.00191","239.27983"
"74.04000","0.06155","1015.54443","0.00192","239.78131"
"74.16000","0.06166","1017.87653","0.00192","240.33194"
"74.28000","0.06180","1020.29492","0.00192","240.90295"
"74.40000","0.06188","1022.41132","0.00193","241.40266"
"74.52000","0.06198","1023.93164","0.00193","241.76163"
"74.64000","0.06209","1026.22070","0.00193","242.30209"
"74.76000","0.06217","1028.13208","0.00194","242.75339"
"74.88000","0.06228","1029.99365","0.00194","243.19293"
"75.00000","0.06238","1031.86914","0.00194","243.63576"
"75.12000","0.06246","1034.08521","0.00195","244.15900"
"75.24000","0.06257","1035.88123","0.00195","244.58305"
"75.36000","0.06268","1037.85095","0.00195","245.04813"
"75.48000","0.06279","1039.91199","0.00196","245.53476"
"75.60000","0.06287","1041.51208","0.00196","245.91257"
"75.72000","0.06297","1043.75793","0.00196","246.44283"
"75.84000","0.06308","1045.63403","0.00196","246.88580"
"75.96000","0.06316","1047.35327","0.00197","247.29173"
"76.08000","0.06324","1049.70532","0.00197","247.84708"
"76.20000","0.06335","1051.20923","0.00197","248.20216"
"76.32000","0.06343","1053.29883","0.00198","248.69554"
"76.44000","0.06354","1055.39722","0.00198","249.19099"
"76.56000","0.06364","1057.07910","0.00198","249.58810"
"76.68000","0.06375","1058.97510","0.00199","250.03577"
"76.80000","0.06383","1061.01208","0.00199","250.51672"
"76.92000","0.06394","1063.22266","0.00199","251.03867"
"77.04000","0.06404","1064.94897","0.00199","251.44627"
"77.16000","0.06415","1067.24219","0.00200","251.98773"
"77.28000","0.06426","1069.36169","0.00200","252.48816"
"77.40000","0.06437","1071.77893","0.00200","253.05890"
"77.52000","0.06447","1073.41504","0.00201","253.44521"
"77.64000","0.06458","1075.60864","0.00201","253.96313"
"77.76000","0.06468","1077.56213","0.00201","254.42438"
"77.88000","0.06477","1079.58313","0.00202","254.90157"
"78.00000","0.06488","1081.43640","0.00202","255.33914"
"78.12000","0.06496","1082.96936","0.00202","255.70108"
"78.24000","0.06506","1084.83362","0.00203","256.14127"
"78.36000","0.06514","1086.66370","0.00203","256.57336"
"78.48000","0.06522","1088.31567","0.00203","256.96341"
"78.60000","0.06533","1090.29211","0.00203","257.43005"
"78.72000","0.06544","1092.45361","0.00204","257.94043"
"78.84000","0.06552","1094.14209","0.00204","258.33908"
"78.96000","0.06562","1096.47095","0.00204","258.88895"
"79.08000","0.06571","1098.27295","0.00205","259.31442"
"79.20000","0.06581","1099.76184","0.00205","259.66599"
"79.32000","0.06592","1102.01831","0.00205","260.19876"
"79.44000","0.06603","1103.75061","0.00206","260.60776"
"79.56000","0.06613","1105.91785","0.00206","261.11948"
"79.68000","0.06624","1107.93359","0.00206","261.59543"
"79.80000","0.06635","1110.07593","0.00207","262.10126"
"79.92000","0.06643","1112.11523","0.00207","262.58276"
"80.04000","0.06654","1114.44336","0.00207","263.13245"
"80.16000","0.06664","1116.44629","0.00208","263.60535"
"80.28000","0.06675","1118.89307","0.00208","264.18307"
"80.40000","0.06688","1120.89807","0.00208","264.65646"
"80.52000","0.06699","1123.42957","0.00209","265.25418"
"80.64000","0.06709","1125.38818","0.00209","265.71664"
"80.76000","0.06718","1127.28577","0.00209","266.16467"
"80.88000","0.06729","1129.33020","0.00210","266.64740"
"81.00000","0.06739","1130.97070","0.00210","267.03473"
"81.12000","0.06747","1133.28821","0.00210","267.58191"
"81.24000","0.06758","1135.68774","0.00210","268.14847"
"81.36000","0.06769","1137.20752","0.00211","268.50732"
"81.48000","0.06777","1139.18945","0.00211","268.97528"
"81.60000","0.06788","1141.30139","0.00211","269.47394"
"81.72000","0.06798","1143.26184","0.00212","269.93680"
"81.84000","0.06806","1145.48535","0.00212","270.46179"
"81.96000","0.06817","1147.29431","0.00212","270.88892"
"82.08000","0.06828","1149.35278","0.00213","271.37494"
"82.20000","0.06837","1151.45337","0.00213","271.87091"
"82.32000","0.06846","1153.59436","0.00213","272.37643"
"82.44000","0.06857","1155.87415","0.00214","272.91470"
"82.56000","0.06865","1157.38281","0.00214","273.27094"
"82.68000","0.06873","1159.65784","0.00214","273.80807"
"82.80000","0.06884","1161.53894","0.00214","274.25223"
"82.92000","0.06895","1163.33594","0.00215","274.67651"
"83.04000","0.06905","1165.59192","0.00215","275.20920"
"83.16000","0.06916","1167.85962","0.00215","275.74463"
"83.28000","0.06927","1170.17603","0.00216","276.29153"
"83.40000","0.06938","1172.19531","0.00216","276.76831"
"83.52000","0.06948","1174.18604","0.00216","277.23834"
"83.64000","0.06956","1176.19763","0.00217","277.71332"
"83.76000","0.06967","1178.56543","0.00217","278.27237"
"83.88000","0.06978","1179.91467","0.00217","278.59094"
"84.00000","0.06986","1181.91809","0.00218","279.06396"
"84.12000","0.06996","1183.99377","0.00218","279.55408"
"84.24000","0.07007","1185.63989","0.00218","279.94275"
"84.36000","0.07015","1187.67932","0.00218","280.42426"
"84.48000","0.07023","1189.22205","0.00219","280.78851"
"84.60000","0.07032","1191.20703","0.00219","281.25720"
"84.72000","0.07042","1193.21704","0.00219","281.73178"
"84.84000","0.07053","1195.37634","0.00220","282.24161"
"84.96000","0.07063","1197.17664","0.00220","282.66669"
"85.08000","0.07071","1199.02490","0.00220","283.10309"
"85.20000","0.07082","1201.02148","0.00221","283.57449"
"85.32000","0.07093","1203.01636","0.00221","284.04550"
"85.44000","0.07103","1204.95996","0.00221","284.50443"
"85.56000","0.07112","1206.75244","0.00221","284.92764"
"85.68000","0.07122","1209.11853","0.00222","285.48630"
"85.80000","0.07133","1210.91785","0.00222","285.91113"
"85.92000","0.07144","1212.87280","0.00222","286.37274"
"86.04000","0.07154","1214.94897","0.00223","286.86295"
"86.16000","0.07164","1217.11279","0.00223","287.37384"
"86.28000","0.07173","1218.79492","0.00223","287.77100"
"86.40000","0.07185","1221.20813","0.00224","288.34079"
"86.52000","0.07197","1223.36780","0.00224","288.85071"
"86.64000","0.07208","1225.72644","0.00224","289.40762"
"86.76000","0.07219","1227.96228","0.00225","289.93552"
"86.88000","0.07227","1229.79321","0.00225","290.36783"
"87.00000","0.07237","1231.83984","0.00225","290.85104"
"87.12000","0.07248","1233.67798","0.00226","291.28506"
"87.24000","0.07259","1235.84094","0.00226","291.79578"
"87.36000","0.07267","1237.37891","0.00226","292.15891"
"87.48000","0.07278","1239.97449","0.00227","292.77173"
"87.60000","0.07288","1242.01599","0.00227","293.25375"
"87.72000","0.07296","1243.58313","0.00227","293.62378"
"87.84000","0.07307","1245.73071","0.00228","294.13086"
"87.96000","0.07318","1247.53052","0.00228","294.55579"
"88.08000","0.07326","1249.72046","0.00228","295.07288"
"88.20000","0.07337","1251.60498","0.00228","295.51782"
"88.32000","0.07347","1253.70667","0.00229","296.01407"
"88.44000","0.07355","1255.25366","0.00229","296.37933"
"88.56000","0.07363","1257.50793","0.00229","296.91159"
"88.68000","0.07374","1259.40881","0.00230","297.36041"
"88.80000","0.07385","1261.36389","0.00230","297.82202"
"88.92000","0.07394","1263.19531","0.00230","298.25443"
"89.04000","0.07404","1265.41870","0.00231","298.77939"
"89.16000","0.07414","1267.78735","0.00231","299.33865"
"89.28000","0.07425","1269.58875","0.00231","299.76401"
"89.40000","0.07436","1271.98743","0.00232","300.33035"
"89.52000","0.07446","1274.06213","0.00232","300.82022"
"89.64000","0.07457","1276.37866","0.00232","301.36716"
"89.76000","0.07468","1278.47192","0.00233","301.86142"
"89.88000","0.07477","1280.77979","0.00233","302.40631"
"90.00000","0.07487","1282.65894","0.00233","302.85001"
"90.12000","0.07497","1284.52930","0.00233","303.29163"
"90.24000","0.07508","1286.22571","0.00234","303.69217"
"90.36000","0.07516","1288.68958","0.00234","304.27393"
"90.48000","0.07526","1290.29956","0.00234","304.65405"
"90.60000","0.07535","1292.21387","0.00235","305.10605"
"90.72000","0.07543","1293.80139","0.00235","305.48087"
"90.84000","0.07554","1295.71619","0.00235","305.93298"
"90.96000","0.07562","1297.92090","0.00235","306.45352"
"91.08000","0.07572","1299.38379","0.00236","306.79892"
"91.20000","0.07583","1301.82349","0.00236","307.37497"
"91.32000","0.07591","1303.76184","0.00236","307.83264"
"91.44000","0.07602","1305.51416","0.00237","308.24637"
"91.56000","0.07613","1307.71301","0.00237","308.76556"
"91.68000","0.07623","1309.94958","0.00237","309.29364"
"91.80000","0.07634","1312.28040","0.00238","309.84396"
"91.92000","0.07642","1314.28796","0.00238","310.31796"
"92.04000","0.07653","1316.18762","0.00238","310.76651"
"92.16000","0.07663","1318.17444","0.00239","311.23563"
"92.28000","0.07674","1320.14368","0.00239","311.70056"
"92.40000","0.07685","1322.41077","0.00239","312.23587"
"92.52000","0.07696","1324.95215","0.00240","312.83591"
"92.64000","0.07709","1327.42224","0.00240","313.41913"
"92.76000","0.07718","1329.71411","0.00240","313.96027"
"92.88000","0.07728","1331.72498","0.00241","314.43506"
"93.00000","0.07738","1333.53149","0.00241","314.86157"
"93.12000","0.07749","1335.81067","0.00241","315.39972"
"93.24000","0.07757","1337.77844","0.00242","315.86435"
"93.36000","0.07768","1339.83911","0.00242","316.35089"
"93.48000","0.07779","1341.62512","0.00242","316.77258"
"93.60000","0.07788","1343.77649","0.00243","317.28055"
"93.72000","0.07797","1345.77014","0.00243","317.75128"
"93.84000","0.07808","1347.73901","0.00243","318.21613"
"93.96000","0.07816","1349.50842","0.00243","318.63391"
"94.08000","0.07827","1351.64563","0.00244","319.13855"
"94.20000","0.07837","1353.82532","0.00244","319.65320"
"94.32000","0.07848","1356.07129","0.00244","320.18347"
"94.44000","0.07856","1358.25122","0.00245","320.69818"
"94.56000","0.07867","1360.43652","0.00245","321.21417"
"94.68000","0.07878","1362.29382","0.00245","321.65268"
"94.80000","0.07886","1364.46021","0.00246","322.16418"
"94.92000","0.07896","1366.47083","0.00246","322.63892"
"95.04000","0.07907","1368.38245","0.00246","323.09027"
"95.16000","0.07915","1370.32471","0.00246","323.54886"
"95.28000","0.07926","1372.29089","0.00247","324.01312"
"95.40000","0.07937","1374.45532","0.00247","324.52417"
"95.52000","0.07947","1376.76843","0.00247","325.07031"
"95.64000","0.07958","1378.81226","0.00248","325.55289"
"95.76000","0.07968","1380.75867","0.00248","326.01245"
"95.88000","0.07977","1382.99805","0.00248","326.54120"
"96.00000","0.07988","1385.12903","0.00249","327.04434"
"96.12000","0.07998","1387.08582","0.00249","327.50635"
"96.24000","0.08006","1388.62805","0.00249","327.87048"
"96.36000","0.08017","1390.87598","0.00250","328.40125"
"96.48000","0.08025","1393.14270","0.00250","328.93646"
"96.60000","0.08036","1394.54443","0.00250","329.26743"
"96.72000","0.08044","1396.79126","0.00250","329.79791"
"96.84000","0.08054","1398.52490","0.00251","330.20724"
"96.96000","0.08063","1400.58179","0.00251","330.69290"
"97.08000","0.08073","1402.15491","0.00251","331.06433"
"97.20000","0.08081","1404.18835","0.00252","331.54446"
"97.32000","0.08092","1406.32019","0.00252","332.04779"
"97.44000","0.08103","1408.35144","0.00252","332.52740"
"97.56000","0.08113","1410.16931","0.00253","332.95663"
"97.68000","0.08121","1412.45825","0.00253","333.49707"
"97.80000","0.08132","1414.70129","0.00253","334.02667"
"97.92000","0.08143","1416.82361","0.00254","334.52777"
"98.04000","0.08154","1418.43347","0.00254","334.90790"
"98.16000","0.08162","1420.69080","0.00254","335.44086"
"98.28000","0.08172","1422.95483","0.00255","335.97543"
"98.40000","0.08183","1425.13611","0.00255","336.49045"
"98.52000","0.08194","1427.18848","0.00255","336.97504"
"98.64000","0.08205","1429.56372","0.00256","337.53586"
"98.76000","0.08218","1432.16956","0.00256","338.15112"
"98.88000","0.08229","1434.27808","0.00256","338.64899"
"99.00000","0.08239","1436.22034","0.00257","339.10757"
"99.12000","0.08247","1438.21899","0.00257","339.57947"
"99.24000","0.08258","1440.46838","0.00257","340.11057"
"99.36000","0.08269","1442.80920","0.00258","340.66327"
"99.48000","0.08279","1444.46753","0.00258","341.05481"
"99.60000","0.08288","1446.51526","0.00258","341.53830"
"99.72000","0.08298","1448.48560","0.00258","342.00354"
"99.84000","0.08306","1450.58264","0.00259","342.49866"
"99.96000","0.08317","1452.25635","0.00259","342.89383"
"100.08000","0.08328","1454.70544","0.00259","343.47211"
"100.20000","0.08337","1456.69202","0.00260","343.94116"
"100.32000","0.08346","1458.62988","0.00260","344.39871"
"100.44000","0.08357","1460.90002","0.00260","344.93472"
"100.56000","0.08368","1462.65015","0.00261","345.34793"
"100.68000","0.08376","1464.65454","0.00261","345.82120"
"100.80000","0.08384","1466.63245","0.00261","346.28821"
"100.92000","0.08395","1468.38574","0.00261","346.70218"
"101.04000","0.08405","1470.46863","0.00262","347.19397"
"101.16000","0.08413","1472.65149","0.00262","347.70935"
"101.28000","0.08424","1474.43372","0.00262","348.13016"
"101.40000","0.08435","1476.72180","0.00263","348.67041"
"101.52000","0.08446","1479.24927","0.00263","349.26718"
"101.64000","0.08456","1481.20911","0.00263","349.72992"
"101.76000","0.08467","1483.64087","0.00264","350.30408"
"101.88000","0.08478","1485.24707","0.00264","350.68332"
"102.00000","0.08488","1487.57776","0.00264","351.23361"
"102.12000","0.08496","1489.86853","0.00265","351.77451"
"102.24000","0.08507","1491.55493","0.00265","352.17267"
"102.36000","0.08518","1493.71777","0.00265","352.68335"
"102.48000","0.08526","1495.75757","0.00266","353.16495"
"102.60000","0.08537","1497.32910","0.00266","353.53601"
"102.72000","0.08545","1499.74390","0.00266","354.10617"
"102.84000","0.08555","1501.66479","0.00266","354.55972"
"102.96000","0.08563","1503.40442","0.00267","354.97046"
"103.08000","0.08571","1505.11206","0.00267","355.37366"
"103.20000","0.08582","1507.46667","0.00267","355.92963"
"103.32000","0.08593","1509.44495","0.00268","356.39670"
"103.44000","0.08601","1511.48584","0.00268","356.87857"
"103.56000","0.08612","1513.30933","0.00268","357.30911"
"103.68000","0.08622","1515.37097","0.00269","357.79590"
"103.79800","0.08636","1370.36267","0.00269","323.55783"
"103.80900","0.08652","908.96228","0.00269","214.61609"