File: samples/m5s4.csv
Time measurement,Displacement,Primary force measurement,Composite strain,Flexure stress
(s),(mm),(N),(mm/mm),(MPa)
"0.00000","0.00000","-0.05936","0.00000","-0.01402"
"0.12000","0.00000","0.24862","0.00000","0.05870"
"0.24000","0.00027","1.36751","0.00001","0.32288"
"0.36000","0.00027","2.62615","0.00001","0.62006"
"0.48000","0.00027","1.80783","0.00001","0.42685"
"0.60000","0.00027","2.17125","0.00001","0.51266"
"0.72000","0.00029","2.00038","0.00001","0.47231"
"0.84000","0.00043","3.14547","0.00001","0.74268"
"0.96000","0.00056","4.34875","0.00002","1.02679"
"1.08000","0.00070","5.85217","0.00002","1.38176"
"1.20000","0.00080","7.18423","0.00003","1.69628"
"1.32000","0.00091","8.00668","0.00003","1.89047"
"1.44000","0.00099","8.83203","0.00003","2.08534"
"1.56000","0.00110","10.12296","0.00003","2.39014"
"1.68000","0.00121","11.27261","0.00004","2.66159"
"1.80000","0.00129","12.30949","0.00004","2.90641"
"1.92000","0.00139","13.68396","0.00004","3.23093"
"2.04000","0.00150","14.44034","0.00005","3.40952"
"2.16000","0.00160","15.74498","0.00005","3.71757"
"2.28000","0.00169","16.49377","0.00005","3.89436"
"2.40000","0.00179","17.76188","0.00006","4.19378"
"2.52000","0.00190","19.05164","0.00006","4.49830"
"2.64000","0.00199","20.15857","0.00006","4.75966"
"2.76000","0.00209","21.33368","0.00007","5.03712"
"2.88000","0.00220","22.77991","0.00007","5.37859"
"3.00000","0.00230","23.84384","0.00007","5.62979"
"3.12000","0.00241","25.06098","0.00008","5.91718"
"3.24000","0.00252","26.18240","0.00008","6.18195"
"3.36000","0.00263","27.71573","0.00008","6.54399"
"3.48000","0.00273","28.61991","0.00009","6.75748"
"3.60000","0.00281","29.88399","0.00009","7.05594"
"3.72000","0.00292","31.32940","0.00009","7.39722"
"3.84000","0.00303","32.01294","0.00009","7.55861"
"3.96000","0.00313","33.69370","0.00010","7.95546"
"4.08000","0.00324","34.45958","0.00010","8.13629"
"4.20000","0.00335","36.04481","0.00010","8.51058"
"4.32000","0.00347","37.42263","0.00011","8.83590"
"4.44000","0.00356","38.38587","0.00011","9.06333"
"4.56000","0.00367","39.80734","0.00011","9.39895"
"4.68000","0.00375","40.75689","0.00012","9.62315"
"4.80000","0.00386","42.16114","0.00012","9.95471"
"4.92000","0.00397","43.81889","0.00012","10.34613"
"5.04000","0.00404","44.68467","0.00013","10.55055"
"5.16000","0.00415","45.68305","0.00013","10.78628"
"5.28000","0.00426","46.83995","0.00013","11.05943"
"5.40000","0.00434","48.04451","0.00014","11.34384"
"5.52000","0.00445","49.26574","0.00014","11.63219"
"5.64000","0.00455","50.42780","0.00014","11.90656"
"5.76000","0.00463","51.60863","0.00014","12.18537"
"5.88000","0.00472","52.49343","0.00015","12.39428"
"6.00000","0.00482","53.94278","0.00015","12.73649"
"6.12000","0.00493","55.11057","0.00015","13.01222"
"6.24000","0.00504","56.55212","0.00016","13.35258"
"6.36000","0.00512","57.26604","0.00016","13.52115"
"6.48000","0.00522","58.97995","0.00016","13.92582"
"6.60000","0.00533","60.10507","0.00017","14.19147"
"6.72000","0.00544","61.30138","0.00017","14.47394"
"6.84000","0.00554","62.27649","0.00017","14.70417"
"6.96000","0.00565","63.44355","0.00018","14.97973"
"7.08000","0.00574","65.30524","0.00018","15.41929"
"7.20000","0.00584","66.19868","0.00018","15.63024"
"7.32000","0.00595","67.86478","0.00019","16.02363"
"7.44000","0.00603","68.89135","0.00019","16.26601"
"7.56000","0.00613","70.07162","0.00019","16.54469"
"7.68000","0.00621","71.14159","0.00019","16.79732"
"7.80000","0.00632","72.23657","0.00020","17.05586"
"7.92000","0.00643","73.59457","0.00020","17.37650"
"8.04000","0.00651","74.66363","0.00020","17.62891"
"8.16000","0.00662","75.84851","0.00021","17.90868"
"8.28000","0.00672","77.15395","0.00021","18.21690"
"8.40000","0.00680","78.28574","0.00021","18.48413"
"8.52000","0.00691","80.16237","0.00022","18.92723"
"8.64000","0.00702","80.49778","0.00022","19.00642"
"8.76000","0.00710","81.97579","0.00022","19.35539"
"8.88000","0.00721","82.59333","0.00022","19.50120"
"9.00000","0.00731","84.03294","0.00023","19.84111"
"9.12000","0.00742","85.53114","0.00023","20.19485"
"9.24000","0.00753","87.27988","0.00023","20.60775"
"9.36000","0.00763","88.95400","0.00024","21.00303"
"9.48000","0.00773","90.23401","0.00024","21.30525"
"9.60000","0.00785","91.65288","0.00024","21.64026"
"9.72000","0.00796","93.02436","0.00025","21.96408"
"9.84000","0.00806","94.07385","0.00025","22.21188"
"9.96000","0.00817","95.31043","0.00025","22.50385"
"10.08000","0.00828","96.81765","0.00026","22.85972"
"10.20000","0.00836","97.96391","0.00026","23.13037"
"10.32000","0.00846","99.44131","0.00026","23.47920"
"10.44000","0.00857","100.68864","0.00027","23.77371"
"10.56000","0.00868","101.95583","0.00027","24.07290"
"10.68000","0.00876","103.32690","0.00027","24.39663"
"10.80000","0.00887","104.58750","0.00028","24.69427"
"10.92000","0.00897","105.79206","0.00028","24.97868"
"11.04000","0.00905","107.39438","0.00028","25.35700"
"11.16000","0.00916","108.14228","0.00029","25.53359"
"11.28000","0.00927","109.84973","0.00029","25.93674"
"11.40000","0.00938","111.18372","0.00029","26.25171"
"11.52000","0.00946","112.24758","0.00029","26.50290"
"11.64000","0.00956","113.67163","0.00030","26.83913"
"11.76000","0.00967","114.92199","0.00030","27.13436"
"11.88000","0.00975","116.59485","0.00030","27.52934"
"12.00000","0.00986","117.12934","0.00031","27.65554"
"12.12000","0.00995","119.01530","0.00031","28.10083"
"12.24000","0.01006","119.94642","0.00031","28.32068"
"12.36000","0.01017","121.76227","0.00032","28.74942"
"12.48000","0.01026","122.78161","0.00032","28.99010"
"12.60000","0.01037","124.32882","0.00032","29.35541"
"12.72000","0.01047","125.44590","0.00033","29.61917"
"12.84000","0.01055","127.23589","0.00033","30.04181"
"12.96000","0.01066","128.09930","0.00033","30.24567"
"13.08000","0.01077","129.65004","0.00034","30.61181"
"13.20000","0.01086","130.68619","0.00034","30.85646"
"13.32000","0.01096","132.14404","0.00034","31.20068"
"13.44000","0.01106","133.37952","0.00034","31.49238"
"13.56000","0.01115","134.47929","0.00035","31.75205"
"13.68000","0.01125","135.93555","0.00035","32.09589"
"13.80000","0.01133","137.13176","0.00035","32.37833"
"13.92000","0.01141","138.18929","0.00036","32.62803"
"14.04000","0.01152","139.49335","0.00036","32.93593"
"14.16000","0.01162","140.68555","0.00036","33.21742"
"14.28000","0.01171","142.21768","0.00036","33.57917"
"14.40000","0.01181","143.08618","0.00037","33.78424"
"14.52000","0.01192","144.54147","0.00037","34.12785"
"14.64000","0.01200","145.86903","0.00037","34.44130"
"14.76000","0.01211","147.32274","0.00038","34.78453"
"14.88000","0.01221","148.75252","0.00038","35.12212"
"15.00000","0.01232","150.10297","0.00038","35.44098"
"15.12000","0.01240","151.71419","0.00039","35.82140"
"15.24000","0.01251","153.29158","0.00039","36.19384"
"15.36000","0.01262","154.63448","0.00039","36.51092"
"15.48000","0.01272","156.10497","0.00040","36.85812"
"15.60000","0.01283","157.29356","0.00040","37.13876"
"15.72000","0.01294","158.88988","0.00040","37.51566"
"15.84000","0.01306","160.48981","0.00041","37.89342"
"15.96000","0.01318","162.18806","0.00041","38.29440"
"16.08000","0.01327","163.65854","0.00041","38.64160"
"16.20000","0.01337","164.87292","0.00042","38.92833"
"16.32000","0.01347","166.34253","0.00042","39.27532"
"16.44000","0.01358","167.71428","0.00042","39.59920"
"16.56000","0.01366","168.99278","0.00043","39.90107"
"16.68000","0.01377","170.41313","0.00043","40.23643"
"16.80000","0.01388","171.70483","0.00043","40.54142"
"16.92000","0.01396","173.57135","0.00043","40.98212"
"17.04000","0.01406","174.49261","0.00044","41.19964"
"17.16000","0.01417","175.98872","0.00044","41.55289"
"17.28000","0.01425","177.01288","0.00044","41.79470"
"17.40000","0.01436","179.08932","0.00045","42.28498"
"17.52000","0.01446","179.91800","0.00045","42.48064"
"17.64000","0.01457","181.74930","0.00045","42.91302"
"17.76000","0.01465","182.94856","0.00046","43.19619"
"17.88000","0.01476","184.52328","0.00046","43.56800"
"18.00000","0.01484","185.66132","0.00046","43.83670"
"18.12000","0.01492","187.27785","0.00046","44.21838"
"18.24000","0.01503","188.49994","0.00047","44.50693"
"18.36000","0.01513","189.72139","0.00047","44.79533"
"18.48000","0.01523","191.64240","0.00047","45.24890"
"18.60000","0.01532","193.40439","0.00048","45.66492"
"18.72000","0.01543","194.70914","0.00048","45.97299"
"18.84000","0.01554","195.99959","0.00048","46.27768"
"18.96000","0.01564","197.50728","0.00049","46.63366"
"19.08000","0.01575","199.33237","0.00049","47.06458"
"19.20000","0.01586","200.63503","0.00049","47.37216"
"19.32000","0.01596","202.53989","0.00050","47.82191"
"19.44000","0.01604","203.45428","0.00050","48.03782"
"19.56000","0.01615","205.14291","0.00050","48.43652"
"19.68000","0.01626","206.22984","0.00051","48.69315"
"19.80000","0.01634","207.69101","0.00051","49.03815"
"19.92000","0.01645","209.48085","0.00051","49.46075"
"20.04000","0.01653","210.44751","0.00051","49.68899"
"20.16000","0.01661","212.05870","0.00052","50.06941"
"20.28000","0.01671","213.17201","0.00052","50.33228"
"20.40000","0.01682","214.73212","0.00052","50.70064"
"20.52000","0.01690","216.31706","0.00053","51.07486"
"20.64000","0.01701","217.36111","0.00053","51.32137"
"20.76000","0.01712","219.10721","0.00053","51.73364"
"20.88000","0.01722","220.45967","0.00054","52.05297"
"21.00000","0.01730","222.32433","0.00054","52.49324"
"21.12000","0.01741","223.59535","0.00054","52.79334"
"21.24000","0.01752","225.35170","0.00055","53.20804"
"21.36000","0.01762","226.64096","0.00055","53.51245"
"21.48000","0.01773","228.27948","0.00055","53.89932"
"21.60000","0.01784","229.72871","0.00056","54.24150"
"21.72000","0.01794","231.22220","0.00056","54.59413"
"21.84000","0.01805","232.63588","0.00056","54.92791"
"21.96000","0.01816","234.55736","0.00057","55.38160"
"22.08000","0.01827","236.36792","0.00057","55.80909"
"22.20000","0.01838","238.20935","0.00057","56.24387"
"22.32000","0.01846","239.12733","0.00057","56.46062"
"22.44000","0.01856","240.96327","0.00058","56.89410"
"22.56000","0.01867","242.14610","0.00058","57.17338"
"22.68000","0.01878","243.70114","0.00058","57.54054"
"22.80000","0.01886","244.81294","0.00059","57.80305"
"22.92000","0.01896","246.55150","0.00059","58.21355"
"23.04000","0.01907","248.11461","0.00059","58.58261"
"23.16000","0.01915","249.50851","0.00060","58.91173"
"23.28000","0.01926","250.96773","0.00060","59.25627"
"23.40000","0.01937","252.17003","0.00060","59.54014"
"23.52000","0.01947","254.06645","0.00061","59.98791"
"23.64000","0.01955","255.28645","0.00061","60.27597"
"23.76000","0.01966","256.74341","0.00061","60.61997"
"23.88000","0.01977","258.49481","0.00062","61.03349"
"24.00000","0.01985","259.76736","0.00062","61.33396"
"24.12000","0.01996","261.67645","0.00062","61.78471"
"24.24000","0.02004","262.47961","0.00062","61.97435"
"24.36000","0.02014","264.18231","0.00063","62.37638"
"24.48000","0.02022","265.92944","0.00063","62.78889"
"24.60000","0.02033","267.02951","0.00063","63.04863"
"24.72000","0.02044","269.25516","0.00064","63.57413"
"24.84000","0.02054","270.32312","0.00064","63.82629"
"24.96000","0.02065","272.59479","0.00064","64.36266"
"25.08000","0.02076","273.74045","0.00065","64.63316"
"25.20000","0.02087","275.42300","0.00065","65.03043"
"25.32000","0.02097","277.28973","0.00065","65.47118"
"25.44000","0.02105","278.66202","0.00066","65.79520"
"25.56000","0.02116","280.40112","0.00066","66.20582"
"25.68000","0.02127","281.89188","0.00066","66.55780"
"25.80000","0.02135","283.26749","0.00066","66.88260"
"25.92000","0.02146","284.50082","0.00067","67.17381"
"26.04000","0.02154","285.99893","0.00067","67.52752"
"26.16000","0.02164","287.74625","0.00067","67.94008"
"26.28000","0.02172","289.25214","0.00068","68.29564"
"26.40000","0.02180","289.84024","0.00068","68.43449"
"26.52000","0.02191","291.79907","0.00068","68.89700"
"26.64000","0.02202","293.80862","0.00069","69.37148"
"26.76000","0.02210","294.66537","0.00069","69.57377"
"26.88000","0.02221","296.81317","0.00069","70.08089"
"27.00000","0.02231","298.69736","0.00069","70.52576"
"27.12000","0.02242","300.47177","0.00070","70.94472"
"27.24000","0.02250","302.29526","0.00070","71.37527"
"27.36000","0.02261","304.00156","0.00070","71.77814"
"27.48000","0.02271","305.43842","0.00071","72.11740"
"27.60000","0.02282","306.88406","0.00071","72.45873"
"27.72000","0.02293","308.59882","0.00071","72.86360"
"27.84000","0.02304","310.58826","0.00072","73.33334"
"27.96000","0.02314","312.18723","0.00072","73.71087"
"28.08000","0.02328","314.52179","0.00072","74.26208"
"28.20000","0.02338","315.99207","0.00073","74.60923"
"28.32000","0.02346","317.66083","0.00073","75.00325"
"28.44000","0.02357","319.09726","0.00073","75.34241"
"28.56000","0.02368","320.95001","0.00074","75.77986"
"28.68000","0.02379","322.38422","0.00074","76.11849"
"28.80000","0.02387","323.84583","0.00074","76.46359"
"28.92000","0.02397","325.77368","0.00075","76.91879"
"29.04000","0.02408","327.42923","0.00075","77.30968"
"29.16000","0.02416","328.69266","0.00075","77.60799"
"29.28000","0.02427","330.57925","0.00076","78.05343"
"29.40000","0.02438","332.08441","0.00076","78.40881"
"29.52000","0.02446","333.72583","0.00076","78.79637"
"29.64000","0.02456","335.20386","0.00076","79.14535"
"29.76000","0.02467","336.91803","0.00077","79.55009"
"29.88000","0.02475","338.46802","0.00077","79.91605"
"30.00000","0.02486","339.86115","0.00077","80.24499"
"30.12000","0.02494","341.40421","0.00078","80.60932"
"30.24000","0.02505","342.79935","0.00078","80.93873"
"30.36000","0.02512","344.33264","0.00078","81.30076"
"30.48000","0.02523","345.71024","0.00079","81.62602"
"30.60000","0.02534","347.47763","0.00079","82.04333"
"30.72000","0.02542","348.96597","0.00079","82.39474"
"30.84000","0.02553","350.98148","0.00079","82.87062"
"30.96000","0.02563","352.42279","0.00080","83.21093"
"31.08000","0.02574","354.07193","0.00080","83.60031"
"31.20000","0.02585","355.71899","0.00080","83.98920"
"31.32000","0.02596","357.35519","0.00081","84.37553"
"31.44000","0.02606","359.30856","0.00081","84.83674"
"31.56000","0.02617","361.04800","0.00081","85.24744"
"31.68000","0.02625","362.10590","0.00082","85.49722"
"31.80000","0.02636","364.13702","0.00082","85.97679"
"31.92000","0.02646","366.02841","0.00082","86.42337"
"32.04000","0.02654","367.16516","0.00083","86.69177"
"32.16000","0.02665","368.64603","0.00083","87.04142"
"32.28000","0.02673","369.76553","0.00083","87.30575"
"32.40000","0.02681","371.31696","0.00083","87.67206"
"32.52000","0.02692","372.87274","0.00084","88.03939"
"32.64000","0.02700","374.67847","0.00084","88.46574"
"32.76000","0.02711","376.19775","0.00084","88.82446"
"32.88000","0.02721","377.60565","0.00085","89.15688"
"33.00000","0.02732","379.34366","0.00085","89.56725"
"33.12000","0.02740","381.11661","0.00085","89.98586"
"33.24000","0.02751","382.64114","0.00086","90.34582"
"33.36000","0.02762","384.44940","0.00086","90.77277"
"33.48000","0.02772","386.17053","0.00086","91.17915"
"33.60000","0.02783","387.66431","0.00087","91.53185"
"33.72000","0.02793","389.09085","0.00087","91.86867"
"33.84000","0.02802","391.23279","0.00087","92.37440"
"33.96000","0.02813","392.86044","0.00088","92.75871"
"34.08000","0.02823","394.58972","0.00088","93.16702"
"34.20000","0.02834","396.57788","0.00088","93.63644"
"34.32000","0.02847","398.78152","0.00089","94.15675"
"34.44000","0.02858","400.35788","0.00089","94.52894"
"34.56000","0.02868","401.80060","0.00089","94.86958"
"34.68000","0.02877","403.56033","0.00090","95.28507"
"34.80000","0.02888","405.23535","0.00090","95.68056"
"34.92000","0.02897","407.14728","0.00090","96.13199"
"35.04000","0.02906","408.18307","0.00091","96.37656"
"35.16000","0.02917","410.08383","0.00091","96.82534"
"35.28000","0.02928","411.85849","0.00091","97.24436"
"35.40000","0.02936","413.53513","0.00091","97.64024"
"35.52000","0.02946","415.51901","0.00092","98.10865"
"35.64000","0.02957","416.75638","0.00092","98.40080"
"35.76000","0.02968","418.63538","0.00092","98.84446"
"35.88000","0.02976","420.07523","0.00093","99.18443"
"36.00000","0.02987","421.67651","0.00093","99.56251"
"36.12000","0.02997","423.35867","0.00093","99.95968"
"36.24000","0.03005","424.95410","0.00094","100.33638"
"36.36000","0.03016","426.72461","0.00094","100.75442"
"36.48000","0.03027","428.50110","0.00094","101.17387"
"36.60000","0.03035","430.38864","0.00095","101.61954"
"36.72000","0.03046","431.45477","0.00095","101.87126"
"36.84000","0.03056","433.41605","0.00095","102.33434"
"36.96000","0.03067","435.22073","0.00096","102.76044"
"37.08000","0.03075","437.11993","0.00096","103.20887"
"37.20000","0.03086","438.80820","0.00096","103.60748"
"37.32000","0.03096","440.08298","0.00096","103.90848"
"37.44000","0.03107","442.16342","0.00097","104.39969"
"37.56000","0.03115","443.47742","0.00097","104.70994"
"37.68000","0.03126","445.36371","0.00097","105.15531"
"37.80000","0.03137","447.06180","0.00098","105.55625"
"37.92000","0.03145","448.48196","0.00098","105.89157"
"38.04000","0.03155","450.29343","0.00098","106.31927"
"38.16000","0.03166","451.67178","0.00099","106.64472"
"38.28000","0.03174","453.35059","0.00099","107.04111"
"38.40000","0.03182","454.91550","0.00099","107.41060"
"38.52000","0.03190","456.05084","0.00099","107.67867"
"38.64000","0.03201","458.16083","0.00100","108.17686"
"38.76000","0.03212","459.63199","0.00100","108.52422"
"38.88000","0.03221","461.51904","0.00100","108.96976"
"39.00000","0.03230","463.17688","0.00101","109.36120"
"39.12000","0.03241","464.89505","0.00101","109.76688"
"39.24000","0.03252","466.68555","0.00101","110.18964"
"39.36000","0.03262","468.12012","0.00102","110.52836"
"39.48000","0.03271","469.78891","0.00102","110.92238"
"39.60000","0.03281","472.12463","0.00102","111.47387"
"39.72000","0.03292","473.67374","0.00103","111.83963"
"39.84000","0.03303","475.59515","0.00103","112.29330"
"39.96000","0.03313","476.95901","0.00103","112.61532"
"40.08000","0.03324","479.21710","0.00104","113.14848"
"40.20000","0.03335","480.74570","0.00104","113.50939"
"40.32000","0.03346","482.60886","0.00104","113.94931"
"40.44000","0.03356","484.87674","0.00105","114.48478"
"40.56000","0.03367","486.58972","0.00105","114.88924"
"40.68000","0.03378","488.27374","0.00105","115.28685"
"40.80000","0.03386","490.23093","0.00105","115.74896"
"40.92000","0.03396","491.76007","0.00106","116.11001"
"41.04000","0.03407","493.08688","0.00106","116.42329"
"41.16000","0.03418","494.95053","0.00106","116.86331"
"41.28000","0.03426","496.92862","0.00107","117.33036"
"41.40000","0.03437","498.42569","0.00107","117.68384"
"41.52000","0.03447","500.69440","0.00107","118.21951"
"41.64000","0.03457","502.26031","0.00108","118.58923"
"41.76000","0.03466","504.25784","0.00108","119.06087"
"41.88000","0.03477","505.42603","0.00108","119.33669"
"42.00000","0.03485","507.55502","0.00109","119.83937"
"42.12000","0.03496","509.05063","0.00109","120.19250"
"42.24000","0.03506","510.84338","0.00109","120.61579"
"42.36000","0.03515","512.71576","0.00109","121.05788"
"42.48000","0.03525","514.24286","0.00110","121.41845"
"42.60000","0.03533","515.63635","0.00110","121.74747"
"42.72000","0.03544","517.23138","0.00110","122.12407"
"42.84000","0.03554","519.14874","0.00111","122.57678"
"42.96000","0.03565","520.66870","0.00111","122.93566"
"43.08000","0.03576","522.40875","0.00111","123.34650"
"43.20000","0.03587","524.50366","0.00112","123.84113"
"43.32000","0.03597","526.08490","0.00112","124.21449"
"43.44000","0.03605","527.95026","0.00112","124.65491"
"43.56000","0.03616","529.45532","0.00113","125.01028"
"43.68000","0.03627","531.42181","0.00113","125.47459"
"43.80000","0.03636","532.97559","0.00113","125.84145"
"43.92000","0.03646","535.14355","0.00114","126.35333"
"44.04000","0.03656","536.38416","0.00114","126.64626"
"44.16000","0.03664","538.14386","0.00114","127.06174"
"44.28000","0.03675","539.42841","0.00114","127.36504"
"44.40000","0.03683","541.55493","0.00115","127.86713"
"44.52000","0.03691","542.96960","0.00115","128.20116"
"44.64000","0.03702","544.25006","0.00115","128.50348"
"44.76000","0.03713","546.13391","0.00116","128.94827"
"44.88000","0.03721","547.84607","0.00116","129.35254"
"45.00000","0.03731","549.43054","0.00116","129.72665"
"45.12000","0.03742","551.45300","0.00117","130.20418"
"45.24000","0.03750","553.26428","0.00117","130.63184"
"45.36000","0.03761","554.62921","0.00117","130.95412"
"45.48000","0.03771","556.86646","0.00117","131.48235"
"45.60000","0.03782","558.22571","0.00118","131.80328"
"45.72000","0.03792","560.24182","0.00118","132.27931"
"45.84000","0.03801","561.72626","0.00118","132.62981"
"45.96000","0.03812","564.05670","0.00119","133.18005"
"46.08000","0.03822","565.59082","0.00119","133.54227"
"46.20000","0.03833","567.11255","0.00119","133.90157"
"46.32000","0.03844","569.64539","0.00120","134.49960"
"46.44000","0.03854","571.33807","0.00120","134.89926"
"46.56000","0.03868","573.54218","0.00120","135.41968"
"46.68000","0.03877","575.25928","0.00121","135.82510"
"46.80000","0.03887","577.00214","0.00121","136.23660"
"46.92000","0.03897","578.81085","0.00121","136.66367"
"47.04000","0.03908","580.67603","0.00122","137.10405"
"47.16000","0.03916","582.42523","0.00122","137.51706"
"47.28000","0.03927","584.67322","0.00122","138.04784"
"47.40000","0.03938","585.93201","0.00123","138.34505"
"47.52000","0.03948","587.94177","0.00123","138.81958"
"47.64000","0.03956","589.65912","0.00123","139.22507"
"47.76000","0.03967","591.15472","0.00124","139.57819"
"47.88000","0.03977","593.02881","0.00124","140.02069"
"48.00000","0.03986","594.85852","0.00124","140.45270"
"48.12000","0.03996","596.83020","0.00124","140.91823"
"48.24000","0.04007","598.73468","0.00125","141.36790"
"48.36000","0.04015","600.43652","0.00125","141.76973"
"48.48000","0.04026","602.26923","0.00125","142.20245"
"48.60000","0.04037","604.01245","0.00126","142.61404"
"48.72000","0.04046","605.99109","0.00126","143.08122"
"48.84000","0.04055","607.61047","0.00126","143.46358"
"48.96000","0.04066","609.61304","0.00127","143.93640"
"49.08000","0.04077","611.19873","0.00127","144.31081"
"49.20000","0.04085","613.38440","0.00127","144.82686"
"49.32000","0.04096","614.84265","0.00128","145.17117"
"49.44000","0.04106","616.86340","0.00128","145.64830"
"49.56000","0.04117","618.78656","0.00128","146.10237"
"49.68000","0.04127","620.23462","0.00129","146.44427"
"49.80000","0.04136","622.62726","0.00129","147.00920"
"49.92000","0.04146","623.58105","0.00129","147.23441"
"50.04000","0.04157","626.30957","0.00129","147.87865"
"50.16000","0.04165","627.47314","0.00130","148.15337"
"50.28000","0.04176","629.54730","0.00130","148.64311"
"50.40000","0.04184","630.88513","0.00130","148.95898"
"50.52000","0.04195","632.50220","0.00131","149.34079"
"50.64000","0.04203","634.04443","0.00131","149.70493"
"50.76000","0.04211","636.02777","0.00131","150.17322"
"50.88000","0.04221","637.44958","0.00131","150.50893"
"51.00000","0.04232","639.55420","0.00132","151.00584"
"51.12000","0.04240","641.21375","0.00132","151.39767"
"51.24000","0.04251","642.99170","0.00132","151.81747"
"51.36000","0.04262","644.69910","0.00133","152.22061"
"51.48000","0.04272","646.52228","0.00133","152.65109"
"51.60000","0.04280","648.44708","0.00133","153.10556"
"51.72000","0.04291","650.12567","0.00134","153.50189"
"51.84000","0.04302","651.93823","0.00134","153.92986"
"51.96000","0.04312","653.53766","0.00134","154.30750"
"52.08000","0.04323","655.49048","0.00135","154.76857"
"52.20000","0.04333","657.33234","0.00135","155.20346"
"52.32000","0.04342","659.16907","0.00135","155.63713"
"52.44000","0.04353","660.83350","0.00136","156.03012"
"52.56000","0.04366","663.28796","0.00136","156.60965"
"52.68000","0.04377","665.46765","0.00136","157.12430"
"52.80000","0.04387","667.39526","0.00137","157.57942"
"52.92000","0.04398","669.08771","0.00137","157.97903"
"53.04000","0.04406","670.58350","0.00137","158.33220"
"53.16000","0.04417","672.57214","0.00138","158.80174"
"53.28000","0.04428","674.43719","0.00138","159.24211"
"53.40000","0.04436","675.97430","0.00138","159.60504"
"53.52000","0.04446","677.90240","0.00138","160.06029"
"53.64000","0.04457","679.85522","0.00139","160.52136"
"53.76000","0.04468","681.36084","0.00139","160.87686"
"53.88000","0.04476","682.68451","0.00139","161.18939"
"54.00000","0.04487","684.99683","0.00140","161.73535"
"54.12000","0.04497","686.56171","0.00140","162.10484"
"54.24000","0.04505","688.86981","0.00140","162.64981"
"54.36000","0.04516","690.28442","0.00141","162.98381"
"54.48000","0.04527","692.27087","0.00141","163.45284"
"54.60000","0.04535","694.04584","0.00141","163.87192"
"54.72000","0.04546","695.55743","0.00142","164.22884"
"54.84000","0.04554","697.19788","0.00142","164.61615"
"54.96000","0.04564","698.87286","0.00142","165.01164"
"55.08000","0.04572","700.54688","0.00142","165.40689"
"55.20000","0.04583","702.70172","0.00143","165.91568"
"55.32000","0.04594","704.29364","0.00143","166.29155"
"55.44000","0.04604","706.00684","0.00143","166.69604"
"55.56000","0.04615","708.15082","0.00144","167.20227"
"55.68000","0.04626","710.27435","0.00144","167.70366"
"55.80000","0.04637","712.09961","0.00144","168.13463"
"55.92000","0.04647","713.83527","0.00145","168.54443"
"56.04000","0.04655","715.96497","0.00145","169.04727"
"56.16000","0.04666","717.54706","0.00145","169.42082"
"56.28000","0.04676","719.43866","0.00146","169.86745"
"56.40000","0.04685","721.14325","0.00146","170.26993"
"56.52000","0.04694","723.14716","0.00146","170.74307"
"56.64000","0.04704","724.51385","0.00146","171.06577"
"56.76000","0.04712","726.37036","0.00147","171.50410"
"56.88000","0.04722","728.12970","0.00147","171.91951"
"57.00000","0.04730","729.77545","0.00147","172.30809"
"57.12000","0.04741","731.89136","0.00148","172.80768"
"57.24000","0.04752","733.10358","0.00148","173.09389"
"57.36000","0.04760","735.44897","0.00148","173.64766"
"57.48000","0.04771","736.89856","0.00149","173.98993"
"57.60000","0.04781","739.12146","0.00149","174.51479"
"57.72000","0.04792","740.98346","0.00149","174.95442"
"57.84000","0.04800","742.93677","0.00149","175.41562"
"57.96000","0.04811","744.86041","0.00150","175.86981"
"58.08000","0.04821","746.70892","0.00150","176.30626"
"58.20000","0.04832","748.48822","0.00150","176.72638"
"58.32000","0.04843","750.22272","0.00151","177.13591"
"58.44000","0.04854","752.63403","0.00151","177.70525"
"58.56000","0.04864","754.27502","0.00151","178.09270"
"58.68000","0.04875","756.44623","0.00152","178.60535"
"58.80000","0.04886","758.49976","0.00152","179.09021"
"58.92000","0.04896","760.67346","0.00152","179.60344"
"59.04000","0.04907","762.29132","0.00153","179.98544"
"59.16000","0.04918","764.31506","0.00153","180.46327"
"59.28000","0.04926","766.00488","0.00153","180.86226"
"59.40000","0.04937","767.85547","0.00154","181.29919"
"59.52000","0.04947","769.96710","0.00154","181.79778"
"59.64000","0.04958","771.74982","0.00154","182.21870"
"59.76000","0.04966","773.66571","0.00155","182.67107"
"59.88000","0.04977","775.22058","0.00155","183.03818"
"60.00000","0.04988","777.18152","0.00155","183.50117"
"60.12000","0.04996","779.18756","0.00156","183.97484"
"60.24000","0.05006","780.75043","0.00156","184.34384"
"60.36000","0.05017","782.52118","0.00156","184.76193"
"60.48000","0.05025","784.59595","0.00156","185.25182"
"60.60000","0.05036","786.23376","0.00157","185.63852"
"60.72000","0.05046","788.11188","0.00157","186.08195"
"60.84000","0.05056","789.39423","0.00157","186.38474"
"60.96000","0.05065","791.88562","0.00158","186.97298"
"61.08000","0.05076","794.01538","0.00158","187.47585"
"61.20000","0.05087","794.93530","0.00158","187.69305"
"61.32000","0.05095","798.27875","0.00159","188.48247"
"61.44000","0.05105","799.37872","0.00159","188.74219"
"61.56000","0.05116","801.34033","0.00159","189.20535"
"61.68000","0.05127","803.16205","0.00160","189.63547"
"61.80000","0.05138","804.98724","0.00160","190.06642"
"61.92000","0.05146","806.71564","0.00160","190.47452"
"62.04000","0.05156","808.99225","0.00161","191.01205"
"62.16000","0.05167","810.84576","0.00161","191.44969"
"62.28000","0.05175","812.64655","0.00161","191.87486"
"62.40000","0.05186","814.66644","0.00161","192.35179"
"62.52000","0.05196","816.38367","0.00162","192.75725"
"62.64000","0.05204","818.40393","0.00162","193.23425"
"62.76000","0.05214","819.74652","0.00162","193.55125"
"62.88000","0.05223","821.55542","0.00163","193.97835"
"63.00000","0.05231","822.91870","0.00163","194.30023"
"63.12000","0.05242","825.06183","0.00163","194.80626"
"63.24000","0.05253","826.73853","0.00164","195.20215"
"63.36000","0.05261","828.85828","0.00164","195.70264"
"63.48000","0.05271","830.21497","0.00164","196.02296"
"63.60000","0.05281","832.42896","0.00164","196.54572"
"63.72000","0.05290","834.28894","0.00165","196.98488"
"63.84000","0.05301","836.00049","0.00165","197.38899"
"63.96000","0.05312","838.04547","0.00165","197.87184"
"64.08000","0.05322","840.18799","0.00166","198.37772"
"64.20000","0.05333","842.42419","0.00166","198.90570"
"64.32000","0.05342","843.95819","0.00166","199.26790"
"64.44000","0.05352","846.23572","0.00167","199.80565"
"64.56000","0.05364","847.45221","0.00167","200.09286"
"64.68000","0.05376","850.21741","0.00167","200.74577"
"64.80000","0.05387","852.07733","0.00168","201.18492"
"64.92000","0.05397","854.23926","0.00168","201.69537"
"65.04000","0.05408","856.21179","0.00168","202.16110"
"65.16000","0.05416","857.96228","0.00169","202.57442"
"65.28000","0.05427","859.85931","0.00169","203.02232"
"65.40000","0.05437","861.60571","0.00169","203.43468"
"65.52000","0.05446","863.32166","0.00170","203.83983"
"65.64000","0.05456","865.36652","0.00170","204.32263"
"65.76000","0.05467","867.24066","0.00170","204.76515"
"65.88000","0.05478","869.14301","0.00171","205.21431"
"66.00000","0.05486","870.87469","0.00171","205.62318"
"66.12000","0.05496","872.87036","0.00171","206.09438"
"66.24000","0.05506","874.54340","0.00171","206.48940"
"66.36000","0.05515","876.00977","0.00172","206.83563"
"66.48000","0.05526","877.99652","0.00172","207.30472"
"66.60000","0.05537","880.24792","0.00172","207.83630"
"66.72000","0.05545","881.81213","0.00173","208.20563"
"66.84000","0.05555","883.76038","0.00173","208.66563"
"66.96000","0.05563","885.48047","0.00173","209.07176"
"67.08000","0.05571","887.24615","0.00174","209.48866"
"67.20000","0.05582","888.74353","0.00174","209.84221"
"67.32000","0.05593","890.90735","0.00174","210.35312"
"67.44000","0.05604","892.50012","0.00175","210.72919"
"67.56000","0.05614","895.25787","0.00175","211.38033"
"67.68000","0.05625","896.97308","0.00175","211.78529"
"67.80000","0.05636","899.18982","0.00176","212.30870"
"67.92000","0.05647","901.08325","0.00176","212.75575"
"68.04000","0.05657","902.98328","0.00176","213.20438"
"68.16000","0.05665","905.28473","0.00176","213.74777"
"68.28000","0.05676","907.05994","0.00177","214.16692"
"68.40000","0.05687","908.67950","0.00177","214.54932"
"68.52000","0.05695","910.71277","0.00177","215.02939"
"68.64000","0.05705","912.47705","0.00178","215.44595"
"68.76000","0.05713","914.38696","0.00178","215.89691"
"68.88000","0.05724","915.96057","0.00178","216.26846"
"69.00000","0.05732","917.70746","0.00179","216.68092"
"69.12000","0.05740","919.61511","0.00179","217.13133"
"69.24000","0.05751","921.10022","0.00179","217.48198"
"69.36000","0.05762","923.26245","0.00179","217.99251"
"69.48000","0.05772","925.05792","0.00180","218.41644"
"69.60000","0.05780","926.84033","0.00180","218.83730"
"69.72000","0.05791","928.89362","0.00180","219.32210"
"69.84000","0.05802","930.71851","0.00181","219.75298"
"69.96000","0.05810","932.78412","0.00181","220.24068"
"70.08000","0.05821","934.65039","0.00181","220.68134"
"70.20000","0.05831","936.94086","0.00182","221.22214"
"70.32000","0.05842","938.55237","0.00182","221.60263"
"70.44000","0.05853","940.91791","0.00182","222.16116"
"70.56000","0.05864","942.58356","0.00183","222.55444"
"70.68000","0.05873","944.34180","0.00183","222.96957"
"70.80000","0.05884","946.66974","0.00183","223.51923"
"70.92000","0.05896","948.95557","0.00184","224.05894"
"71.04000","0.05906","951.14929","0.00184","224.57690"
"71.16000","0.05917","953.13696","0.00184","225.04622"
"71.28000","0.05928","955.00427","0.00185","225.48711"
"71.40000","0.05936","956.67157","0.00185","225.88077"
"71.52000","0.05946","959.08649","0.00185","226.45096"
"71.64000","0.05957","960.59796","0.00186","226.80785"
"71.76000","0.05968","962.72028","0.00186","227.30894"
"71.88000","0.05976","964.47302","0.00186","227.72278"
"72.00000","0.05987","966.36627","0.00186","228.16980"
"72.12000","0.05997","968.20575","0.00187","228.60413"
"72.24000","0.06006","970.11554","0.00187","229.05504"
"72.36000","0.06016","971.52863","0.00187","229.38869"
"72.48000","0.06027","973.51215","0.00188","229.85703"
"72.60000","0.06035","975.33807","0.00188","230.28815"
"72.72000","0.06046","977.43860","0.00188","230.78410"
"72.84000","0.06056","979.05695","0.00189","231.16621"
"72.96000","0.06064","980.70093","0.00189","231.55437"
"73.08000","0.06075","982.73242","0.00189","232.03403"
"73.20000","0.06083","984.40686","0.00189","232.42938"
"73.32000","0.06094","986.49121","0.00190","232.92152"
"73.44000","0.06102","988.02612","0.00190","233.28394"
"73.56000","0.06113","990.17743","0.00190","233.79189"
"73.68000","0.06126","992.14783","0.00191","234.25711"
"73.80000","0.06137","994.62189","0.00191","234.84126"
"73.92000","0.06147","996.69861","0.00191","235.33160"
"74.04000","0.06155","998.71692","0.00192","235.80815"
"74.16000","0.06166","1000.42865","0.00192","236.21231"
"74.28000","0.06177","1002.81799","0.00192","236.77646"
"74.40000","0.06185","1004.67230","0.00193","237.21428"
"74.52000","0.06196","1006.35907","0.00193","237.61255"
"74.64000","0.06206","1007.84192","0.00193","237.96266"
"74.76000","0.06214","1009.88068","0.00194","238.44403"
"74.88000","0.06225","1011.74005","0.00194","238.88306"
"75.00000","0.06233","1013.68866","0.00194","239.34314"
"75.12000","0.06241","1015.24432","0.00194","239.71045"
"75.24000","0.06252","1016.99774","0.00195","240.12445"
"75.36000","0.06262","1019.11163","0.00195","240.62357"
"75.48000","0.06271","1020.97577","0.00195","241.06371"
"75.60000","0.06281","1023.02710","0.00196","241.54805"
"75.72000","0.06292","1025.32300","0.00196","242.09013"
"75.84000","0.06300","1026.83386","0.00196","242.44687"
"75.96000","0.06311","1028.93286","0.00197","242.94247"
"76.08000","0.06321","1030.96912","0.00197","243.42325"
"76.20000","0.06332","1032.61743","0.00197","243.81244"
"76.32000","0.06341","1034.86438","0.00197","244.34297"
"76.44000","0.06351","1036.94055","0.00198","244.83318"
"76.56000","0.06362","1038.66699","0.00198","245.24080"
"76.68000","0.06372","1040.92310","0.00198","245.77350"
"76.80000","0.06383","1042.85083","0.00199","246.22865"
"76.92000","0.06394","1044.85840","0.00199","246.70267"
"77.04000","0.06407","1047.37329","0.00200","247.29646"
"77.16000","0.06418","1049.42615","0.00200","247.78116"
"77.28000","0.06426","1051.25378","0.00200","248.21269"
"77.40000","0.06437","1053.27734","0.00200","248.69048"
"77.52000","0.06447","1055.19666","0.00201","249.14365"
"77.64000","0.06458","1057.22729","0.00201","249.62309"
"77.76000","0.06466","1059.21716","0.00201","250.09293"
"77.88000","0.06477","1061.53259","0.00202","250.63963"
"78.00000","0.06488","1063.01978","0.00202","250.99077"
"78.12000","0.06496","1064.63171","0.00202","251.37137"
"78.24000","0.06506","1066.74377","0.00203","251.87004"
"78.36000","0.06517","1068.36292","0.00203","252.25233"
"78.48000","0.06525","1070.76038","0.00203","252.81841"
"78.60000","0.06536","1072.08093","0.00204","253.13020"
"78.72000","0.06546","1074.63855","0.00204","253.73409"
"78.84000","0.06557","1076.09253","0.00204","254.07739"
"78.96000","0.06565","1078.36938","0.00204","254.61497"
"79.08000","0.06576","1080.29724","0.00205","255.07018"
"79.20000","0.06584","1081.71753","0.00205","255.40552"
"79.32000","0.06592","1083.41870","0.00205","255.80717"
"79.44000","0.06603","1085.52808","0.00206","256.30524"
"79.56000","0.06613","1087.47009","0.00206","256.76376"
"79.68000","0.06624","1089.80371","0.00206","257.31476"
"79.80000","0.06632","1090.93091","0.00207","257.58090"
"79.92000","0.06643","1093.52783","0.00207","258.19406"
"80.04000","0.06654","1095.56787","0.00207","258.67572"
"80.16000","0.06664","1098.06775","0.00208","259.26599"
"80.28000","0.06675","1100.13440","0.00208","259.75394"
"80.40000","0.06686","1102.30566","0.00208","260.26660"
"80.52000","0.06696","1104.47900","0.00209","260.77975"
"80.64000","0.06707","1106.11768","0.00209","261.16666"
"80.76000","0.06715","1108.49854","0.00209","261.72882"
"80.88000","0.06726","1109.88440","0.00209","262.05603"
"81.00000","0.06734","1112.21033","0.00210","262.60519"
"81.12000","0.06745","1114.04382","0.00210","263.03812"
"81.24000","0.06753","1115.74231","0.00210","263.43915"
"81.36000","0.06761","1117.58569","0.00211","263.87439"
"81.48000","0.06771","1119.55347","0.00211","264.33899"
"81.60000","0.06782","1121.65613","0.00211","264.83545"
"81.72000","0.06790","1123.67151","0.00211","265.31131"
"81.84000","0.06801","1125.30566","0.00212","265.69714"
"81.96000","0.06812","1127.74878","0.00212","266.27402"
"82.08000","0.06820","1129.76294","0.00212","266.74957"
"82.20000","0.06830","1131.62683","0.00213","267.18967"
"82.32000","0.06841","1133.82373","0.00213","267.70837"
"82.44000","0.06852","1135.84656","0.00213","268.18597"
"82.56000","0.06862","1138.08008","0.00214","268.71335"
"82.68000","0.06873","1139.68005","0.00214","269.09109"
"82.80000","0.06883","1141.82434","0.00214","269.59741"
"82.92000","0.06894","1144.17090","0.00215","270.15146"
"83.04000","0.06905","1146.18982","0.00215","270.62814"
"83.16000","0.06916","1148.81543","0.00215","271.24808"
"83.28000","0.06927","1150.78638","0.00216","271.71344"
"83.40000","0.06937","1153.00525","0.00216","272.23734"
"83.52000","0.06948","1154.82996","0.00216","272.66818"
"83.64000","0.06956","1156.72192","0.00217","273.11490"
"83.76000","0.06967","1158.59985","0.00217","273.55829"
"83.88000","0.06978","1160.30005","0.00217","273.95972"
"84.00000","0.06988","1162.91016","0.00218","274.57599"
"84.12000","0.06996","1164.50537","0.00218","274.95264"
"84.24000","0.07007","1166.54089","0.00218","275.43326"
"84.36000","0.07017","1168.49536","0.00219","275.89471"
"84.48000","0.07026","1170.26721","0.00219","276.31308"
"84.60000","0.07037","1172.30127","0.00219","276.79333"
"84.72000","0.07047","1173.70349","0.00219","277.12442"
"84.84000","0.07055","1175.92761","0.00220","277.64957"
"84.96000","0.07066","1177.89478","0.00220","278.11404"
"85.08000","0.07077","1179.64880","0.00220","278.52817"
"85.20000","0.07085","1181.79492","0.00221","279.03491"
"85.32000","0.07096","1183.65601","0.00221","279.47433"
"85.44000","0.07104","1185.39062","0.00221","279.88388"
"85.56000","0.07114","1187.21594","0.00222","280.31485"
"85.68000","0.07122","1188.69873","0.00222","280.66498"
"85.80000","0.07133","1190.95593","0.00222","281.19791"
"85.92000","0.07144","1193.26990","0.00222","281.74426"
"86.04000","0.07154","1195.25671","0.00223","282.21338"
"86.16000","0.07165","1197.57739","0.00223","282.76132"
"86.28000","0.07176","1199.64612","0.00223","283.24976"
"86.40000","0.07187","1201.46106","0.00224","283.67828"
"86.52000","0.07197","1203.56860","0.00224","284.17590"
"86.64000","0.07205","1205.40991","0.00224","284.61066"
"86.76000","0.07216","1207.35925","0.00225","285.07092"
"86.88000","0.07227","1209.20862","0.00225","285.50757"
"87.00000","0.07235","1211.39124","0.00225","286.02292"
"87.12000","0.07246","1213.28479","0.00226","286.47000"
"87.24000","0.07254","1214.63049","0.00226","286.78775"
"87.36000","0.07262","1216.53589","0.00226","287.23764"
"87.48000","0.07272","1218.72314","0.00226","287.75406"
"87.60000","0.07283","1220.68640","0.00227","288.21762"
"87.72000","0.07291","1222.67358","0.00227","288.68680"
"87.84000","0.07302","1224.57739","0.00227","289.13632"
"87.96000","0.07312","1226.52222","0.00228","289.59552"
"88.08000","0.07321","1228.81580","0.00228","290.13705"
"88.20000","0.07331","1230.76599","0.00228","290.59750"
"88.32000","0.07341","1232.52271","0.00229","291.01230"
"88.44000","0.07350","1234.59790","0.00229","291.50226"
"88.56000","0.07361","1237.20166","0.00229","292.11703"
"88.68000","0.07371","1238.88501","0.00230","292.51450"
"88.80000","0.07382","1240.80420","0.00230","292.96765"
"88.92000","0.07393","1243.25793","0.00230","293.54700"
"89.04000","0.07404","1245.44971","0.00231","294.06448"
"89.16000","0.07414","1247.69421","0.00231","294.59445"
"89.28000","0.07425","1249.88342","0.00231","295.11136"
"89.40000","0.07438","1252.43201","0.00232","295.71310"
"89.52000","0.07446","1254.45984","0.00232","296.19189"
"89.64000","0.07457","1256.40540","0.00232","296.65125"
"89.76000","0.07468","1258.02478","0.00233","297.03360"
"89.88000","0.07478","1260.79944","0.00233","297.68875"
"90.00000","0.07487","1262.09534","0.00233","297.99472"
"90.12000","0.07497","1264.72900","0.00233","298.61655"
"90.24000","0.07508","1266.66980","0.00234","299.07480"
"90.36000","0.07516","1268.57471","0.00234","299.52457"
"90.48000","0.07527","1270.73401","0.00234","300.03439"
"90.60000","0.07538","1272.37732","0.00235","300.42239"
"90.72000","0.07546","1274.49060","0.00235","300.92139"
"90.84000","0.07556","1276.22705","0.00235","301.33136"
"90.96000","0.07567","1278.06165","0.00236","301.76453"
"91.08000","0.07575","1280.28198","0.00236","302.28879"
"91.20000","0.07586","1281.84729","0.00236","302.65839"
"91.32000","0.07594","1283.68750","0.00236","303.09286"
"91.44000","0.07602","1285.58057","0.00237","303.53983"
"91.56000","0.07612","1287.15808","0.00237","303.91232"
"91.68000","0.07623","1289.85657","0.00237","304.54944"
"91.80000","0.07634","1291.56860","0.00238","304.95367"
"91.92000","0.07645","1293.96863","0.00238","305.52036"
"92.04000","0.07655","1296.12878","0.00238","306.03040"
"92.16000","0.07666","1298.18237","0.00239","306.51526"
"92.28000","0.07674","1300.25610","0.00239","307.00488"
"92.40000","0.07688","1302.31079","0.00239","307.49002"
"92.52000","0.07696","1304.62280","0.00240","308.03592"
"92.64000","0.07706","1306.25830","0.00240","308.42209"
"92.76000","0.07717","1308.25488","0.00240","308.89349"
"92.88000","0.07725","1310.61462","0.00241","309.45065"
"93.00000","0.07736","1312.48486","0.00241","309.89224"
"93.12000","0.07746","1314.05286","0.00241","310.26245"
"93.24000","0.07754","1316.14319","0.00241","310.75601"
"93.36000","0.07765","1317.98022","0.00242","311.18976"
"93.48000","0.07773","1319.86157","0.00242","311.63397"
"93.60000","0.07784","1321.87170","0.00242","312.10858"
"93.72000","0.07792","1323.62048","0.00243","312.52148"
"93.84000","0.07800","1325.35730","0.00243","312.93158"
"93.96000","0.07811","1327.45557","0.00243","313.42700"
"94.08000","0.07821","1329.71570","0.00244","313.96063"
"94.20000","0.07829","1331.62842","0.00244","314.41226"
"94.32000","0.07840","1334.07959","0.00244","314.99100"
"94.44000","0.07851","1336.15747","0.00244","315.48160"
"94.56000","0.07862","1337.98389","0.00245","315.91284"
"94.68000","0.07872","1340.17859","0.00245","316.43103"
"94.80000","0.07881","1342.01514","0.00245","316.86465"
"94.92000","0.07891","1344.40186","0.00246","317.42819"
"95.04000","0.07902","1346.25208","0.00246","317.86505"
"95.16000","0.07913","1348.58521","0.00246","318.41592"
"95.28000","0.07923","1350.55334","0.00247","318.88065"
"95.40000","0.07934","1352.57483","0.00247","319.35794"
"95.52000","0.07947","1355.12402","0.00247","319.95981"
"95.64000","0.07958","1357.56616","0.00248","320.53644"
"95.76000","0.07966","1359.26172","0.00248","320.93677"
"95.88000","0.07977","1361.20691","0.00248","321.39606"
"96.00000","0.07987","1363.15747","0.00249","321.85660"
"96.12000","0.07998","1365.42554","0.00249","322.39212"
"96.24000","0.08006","1367.54602","0.00249","322.89279"
"96.36000","0.08017","1369.60022","0.00250","323.37781"
"96.48000","0.08028","1371.39783","0.00250","323.80225"
"96.60000","0.08036","1373.62805","0.00250","324.32883"
"96.72000","0.08046","1375.43616","0.00251","324.75574"
"96.84000","0.08057","1377.30811","0.00251","325.19772"
"96.96000","0.08065","1379.39502","0.00251","325.69046"
"97.08000","0.08076","1381.26941","0.00251","326.13303"
"97.20000","0.08087","1383.32617","0.00252","326.61865"
"97.32000","0.08097","1385.06812","0.00252","327.02997"
"97.44000","0.08105","1387.30774","0.00252","327.55875"
"97.56000","0.08116","1389.40295","0.00253","328.05347"
"97.68000","0.08124","1391.05090","0.00253","328.44257"
"97.80000","0.08132","1393.16687","0.00253","328.94217"
"97.92000","0.08143","1394.65222","0.00254","329.29288"
"98.04000","0.08154","1396.78467","0.00254","329.79636"
"98.16000","0.08164","1398.89209","0.00254","330.29395"
"98.28000","0.08175","1401.15210","0.00255","330.82758"
"98.40000","0.08186","1403.47046","0.00255","331.37494"
"98.52000","0.08196","1405.37317","0.00255","331.82419"
"98.64000","0.08207","1407.76782","0.00256","332.38962"
"98.76000","0.08215","1409.68323","0.00256","332.84186"
"98.88000","0.08226","1411.63879","0.00256","333.30359"
"98.91500","0.08248","804.35748","0.00257","189.91772"