File: samples/m5s5.csv
Time measurement,Displacement,Primary force measurement,Composite strain,Flexure stress
(s),(mm),(N),(mm/mm),(MPa)
"0.00000","0.00000","-0.20664","0.00000","-0.04879"
"0.10000","0.00000","-0.18882","0.00000","-0.04458"
"0.20000","0.00000","-0.03122","0.00000","-0.00737"
"0.30000","0.00024","2.18921","0.00001","0.51690"
"0.40000","0.00024","2.13545","0.00001","0.50420"
"0.50000","0.00024","1.95016","0.00001","0.46045"
"0.60000","0.00024","2.06236","0.00001","0.48695"
"0.70000","0.00027","2.14445","0.00001","0.50633"
"0.80000","0.00038","3.12749","0.00001","0.73844"
"0.90000","0.00049","4.43972","0.00002","1.04827"
"1.00000","0.00062","5.39573","0.00002","1.27399"
"1.10000","0.00070","6.56251","0.00002","1.54948"
"1.20000","0.00078","7.44272","0.00002","1.75731"
"1.30000","0.00088","8.74866","0.00003","2.06566"
"1.40000","0.00096","9.83723","0.00003","2.32268"
"1.50000","0.00104","10.70428","0.00003","2.52740"
"1.60000","0.00113","12.05390","0.00004","2.84606"
"1.70000","0.00121","13.15864","0.00004","3.10690"
"1.80000","0.00131","14.30192","0.00004","3.37684"
"1.90000","0.00139","15.09925","0.00004","3.56510"
"2.00000","0.00147","16.24491","0.00005","3.83560"
"2.10000","0.00155","17.61915","0.00005","4.16008"
"2.20000","0.00163","18.64875","0.00005","4.40318"
"2.30000","0.00171","19.86036","0.00005","4.68925"
"2.40000","0.00182","20.98519","0.00006","4.95484"
"2.50000","0.00190","22.09671","0.00006","5.21728"
"2.60000","0.00198","23.43794","0.00006","5.53396"
"2.70000","0.00206","24.28074","0.00006","5.73295"
"2.80000","0.00214","25.52587","0.00007","6.02694"
"2.90000","0.00222","27.05625","0.00007","6.38828"
"3.00000","0.00230","28.21248","0.00007","6.66128"
"3.10000","0.00238","28.99798","0.00007","6.84675"
"3.20000","0.00246","30.09071","0.00008","7.10475"
"3.30000","0.00254","31.62949","0.00008","7.46807"
"3.40000","0.00264","32.76875","0.00008","7.73706"
"3.50000","0.00273","33.94386","0.00009","8.01452"
"3.60000","0.00281","35.24077","0.00009","8.32074"
"3.70000","0.00289","36.24050","0.00009","8.55678"
"3.80000","0.00297","37.31222","0.00009","8.80983"
"3.90000","0.00305","38.43960","0.00010","9.07602"
"4.00000","0.00313","39.86798","0.00010","9.41327"
"4.10000","0.00321","40.61697","0.00010","9.59012"
"4.20000","0.00329","42.44369","0.00010","10.02143"
"4.30000","0.00338","43.42512","0.00011","10.25315"
"4.40000","0.00346","44.58062","0.00011","10.52598"
"4.50000","0.00354","45.84165","0.00011","10.82372"
"4.60000","0.00364","47.07644","0.00011","11.11527"
"4.70000","0.00372","48.37570","0.00012","11.42204"
"4.80000","0.00380","49.36068","0.00012","11.65460"
"4.90000","0.00388","50.30630","0.00012","11.87788"
"5.00000","0.00399","51.91714","0.00012","12.25821"
"5.10000","0.00407","53.54644","0.00013","12.64291"
"5.20000","0.00415","54.34139","0.00013","12.83061"
"5.30000","0.00423","56.04909","0.00013","13.23381"
"5.40000","0.00434","57.43450","0.00014","13.56092"
"5.50000","0.00444","58.78780","0.00014","13.88045"
"5.60000","0.00453","60.09357","0.00014","14.18876"
"5.70000","0.00461","61.30264","0.00014","14.47423"
"5.80000","0.00469","62.53728","0.00015","14.76575"
"5.90000","0.00477","63.63787","0.00015","15.02561"
"6.00000","0.00488","65.18898","0.00015","15.39184"
"6.10000","0.00495","66.31602","0.00015","15.65795"
"6.20000","0.00504","66.92440","0.00016","15.80159"
"6.30000","0.00512","68.56859","0.00016","16.18980"
"6.40000","0.00520","69.60189","0.00016","16.43378"
"6.50000","0.00528","70.71341","0.00016","16.69622"
"6.60000","0.00536","72.28349","0.00017","17.06693"
"6.70000","0.00544","73.27331","0.00017","17.30064"
"6.80000","0.00552","74.61449","0.00017","17.61731"
"6.90000","0.00560","75.28445","0.00017","17.77549"
"7.00000","0.00568","77.01960","0.00018","18.18518"
"7.10000","0.00576","77.93954","0.00018","18.40239"
"7.20000","0.00584","79.33393","0.00018","18.73162"
"7.30000","0.00593","80.22540","0.00018","18.94211"
"7.40000","0.00600","81.59731","0.00019","19.26603"
"7.50000","0.00608","82.67096","0.00019","19.51953"
"7.60000","0.00616","83.55777","0.00019","19.72892"
"7.70000","0.00624","85.06339","0.00019","20.08441"
"7.80000","0.00632","86.27820","0.00020","20.37124"
"7.90000","0.00640","87.52106","0.00020","20.66469"
"8.00000","0.00648","88.75826","0.00020","20.95681"
"8.10000","0.00656","89.82793","0.00020","21.20937"
"8.20000","0.00667","90.92169","0.00021","21.46762"
"8.30000","0.00675","92.38767","0.00021","21.81376"
"8.40000","0.00683","93.33794","0.00021","22.03812"
"8.50000","0.00691","94.92864","0.00022","22.41371"
"8.60000","0.00702","96.24458","0.00022","22.72441"
"8.70000","0.00710","97.83997","0.00022","23.10110"
"8.80000","0.00718","98.89641","0.00022","23.35054"
"8.90000","0.00726","100.12464","0.00023","23.64054"
"9.00000","0.00734","101.15630","0.00023","23.88413"
"9.10000","0.00742","102.31444","0.00023","24.15757"
"9.20000","0.00750","103.31512","0.00023","24.39385"
"9.30000","0.00758","104.58732","0.00024","24.69423"
"9.40000","0.00766","105.67147","0.00024","24.95021"
"9.50000","0.00774","106.84641","0.00024","25.22762"
"9.60000","0.00782","108.01244","0.00024","25.50294"
"9.70000","0.00790","109.13474","0.00025","25.76792"
"9.80000","0.00798","110.14677","0.00025","26.00688"
"9.90000","0.00806","111.49922","0.00025","26.32620"
"10.00000","0.00814","112.72924","0.00025","26.61662"
"10.10000","0.00822","113.78649","0.00026","26.86625"
"10.20000","0.00830","115.27746","0.00026","27.21829"
"10.30000","0.00838","116.42898","0.00026","27.49017"
"10.40000","0.00846","117.89960","0.00026","27.83741"
"10.50000","0.00854","119.10146","0.00027","28.12118"
"10.60000","0.00863","120.35067","0.00027","28.41613"
"10.70000","0.00873","121.53900","0.00027","28.69671"
"10.80000","0.00881","122.92546","0.00027","29.02407"
"10.90000","0.00889","124.32201","0.00028","29.35381"
"11.00000","0.00897","125.58659","0.00028","29.65239"
"11.10000","0.00905","126.74227","0.00028","29.92526"
"11.20000","0.00916","128.17020","0.00029","30.26241"
"11.30000","0.00924","129.64806","0.00029","30.61135"
"11.40000","0.00932","130.74849","0.00029","30.87117"
"11.50000","0.00943","132.38397","0.00029","31.25732"
"11.60000","0.00954","133.74863","0.00030","31.57953"
"11.70000","0.00962","135.53194","0.00030","32.00060"
"11.80000","0.00970","136.44844","0.00030","32.21699"
"11.90000","0.00978","137.84987","0.00030","32.54788"
"12.00000","0.00986","138.98129","0.00031","32.81503"
"12.10000","0.00994","140.39107","0.00031","33.14789"
"12.20000","0.01002","141.82219","0.00031","33.48579"
"12.30000","0.01012","143.16278","0.00032","33.80232"
"12.40000","0.01020","144.07817","0.00032","34.01846"
"12.50000","0.01029","145.48148","0.00032","34.34979"
"12.60000","0.01037","146.87334","0.00032","34.67842"
"12.70000","0.01045","148.05684","0.00033","34.95786"
"12.80000","0.01053","149.27957","0.00033","35.24656"
"12.90000","0.01061","150.78720","0.00033","35.60253"
"13.00000","0.01069","151.68544","0.00033","35.81462"
"13.10000","0.01077","153.47205","0.00034","36.23645"
"13.20000","0.01085","154.33693","0.00034","36.44066"
"13.30000","0.01093","156.32399","0.00034","36.90983"
"13.40000","0.01101","157.17834","0.00034","37.11155"
"13.50000","0.01109","158.72414","0.00035","37.47653"
"13.60000","0.01117","159.84796","0.00035","37.74188"
"13.70000","0.01125","161.15007","0.00035","38.04932"
"13.80000","0.01133","162.28244","0.00035","38.31668"
"13.90000","0.01141","163.49619","0.00036","38.60326"
"14.00000","0.01152","165.23515","0.00036","39.01385"
"14.10000","0.01160","166.42284","0.00036","39.29428"
"14.20000","0.01168","167.84918","0.00036","39.63105"
"14.30000","0.01177","168.77756","0.00037","39.85025"
"14.40000","0.01187","170.34560","0.00037","40.22049"
"14.50000","0.01195","171.76527","0.00037","40.55569"
"14.60000","0.01203","172.67857","0.00037","40.77133"
"14.70000","0.01211","174.29840","0.00038","41.15379"
"14.80000","0.01219","175.27324","0.00038","41.38396"
"14.90000","0.01227","177.18689","0.00038","41.83579"
"15.00000","0.01235","178.28265","0.00038","42.09451"
"15.10000","0.01243","179.59982","0.00039","42.40551"
"15.20000","0.01251","180.94843","0.00039","42.72393"
"15.30000","0.01259","181.97426","0.00039","42.96614"
"15.40000","0.01267","183.04256","0.00039","43.21838"
"15.50000","0.01275","184.41544","0.00040","43.54253"
"15.60000","0.01283","185.62213","0.00040","43.82745"
"15.70000","0.01288","186.92290","0.00040","44.13457"
"15.80000","0.01296","187.76736","0.00040","44.33396"
"15.90000","0.01304","189.26549","0.00041","44.68768"
"16.00000","0.01313","190.42670","0.00041","44.96186"
"16.10000","0.01323","192.16394","0.00041","45.37204"
"16.20000","0.01331","193.19112","0.00041","45.61457"
"16.30000","0.01339","194.66956","0.00042","45.96364"
"16.40000","0.01347","195.81528","0.00042","46.23416"
"16.50000","0.01355","197.19221","0.00042","46.55927"
"16.60000","0.01363","198.53329","0.00042","46.87592"
"16.70000","0.01371","199.72154","0.00043","47.15647"
"16.80000","0.01379","201.10651","0.00043","47.48348"
"16.90000","0.01390","202.38770","0.00043","47.78598"
"17.00000","0.01398","203.75381","0.00044","48.10854"
"17.10000","0.01406","205.37151","0.00044","48.49049"
"17.20000","0.01414","206.88326","0.00044","48.84743"
"17.30000","0.01425","207.99438","0.00044","49.10978"
"17.40000","0.01433","209.40820","0.00045","49.44360"
"17.50000","0.01441","210.45294","0.00045","49.69028"
"17.60000","0.01452","212.27089","0.00045","50.11951"
"17.70000","0.01462","213.72745","0.00046","50.46342"
"17.80000","0.01471","215.24367","0.00046","50.82142"
"17.90000","0.01479","216.51395","0.00046","51.12135"
"18.00000","0.01487","217.78259","0.00046","51.42089"
"18.10000","0.01495","219.33348","0.00047","51.78707"
"18.20000","0.01503","220.53766","0.00047","52.07139"
"18.30000","0.01511","221.59637","0.00047","52.32136"
"18.40000","0.01519","222.85393","0.00047","52.61829"
"18.50000","0.01527","224.44693","0.00048","52.99441"
"18.60000","0.01535","225.59529","0.00048","53.26555"
"18.70000","0.01543","226.85928","0.00048","53.56400"
"18.80000","0.01554","228.06963","0.00048","53.84977"
"18.90000","0.01562","229.61444","0.00049","54.21452"
"19.00000","0.01570","231.18442","0.00049","54.58521"
"19.10000","0.01578","232.41251","0.00049","54.87517"
"19.20000","0.01586","233.55280","0.00049","55.14441"
"19.30000","0.01594","234.65021","0.00050","55.40352"
"19.40000","0.01602","236.40724","0.00050","55.81837"
"19.50000","0.01610","237.64334","0.00050","56.11023"
"19.60000","0.01618","239.01965","0.00050","56.43519"
"19.70000","0.01626","240.15083","0.00051","56.70228"
"19.80000","0.01634","241.13457","0.00051","56.93455"
"19.90000","0.01639","242.72632","0.00051","57.31038"
"20.00000","0.01647","243.67508","0.00051","57.53439"
"20.10000","0.01658","245.47638","0.00052","57.95970"
"20.20000","0.01666","246.54071","0.00052","58.21100"
"20.30000","0.01674","247.83702","0.00052","58.51707"
"20.40000","0.01682","249.13533","0.00052","58.82362"
"20.50000","0.01692","250.88210","0.00053","59.23605"
"20.60000","0.01701","252.19739","0.00053","59.54660"
"20.70000","0.01709","253.85689","0.00053","59.93843"
"20.80000","0.01717","255.10359","0.00053","60.23279"
"20.90000","0.01725","256.76083","0.00054","60.62408"
"21.00000","0.01736","258.49738","0.00054","61.03410"
"21.10000","0.01744","259.81021","0.00054","61.34407"
"21.20000","0.01752","261.21030","0.00055","61.67465"
"21.30000","0.01760","262.50757","0.00055","61.98095"
"21.40000","0.01768","263.85895","0.00055","62.30003"
"21.50000","0.01776","264.95905","0.00055","62.55977"
"21.60000","0.01784","266.31750","0.00056","62.88052"
"21.70000","0.01789","267.36850","0.00056","63.12867"
"21.80000","0.01797","268.68570","0.00056","63.43967"
"21.90000","0.01805","270.20334","0.00056","63.79801"
"22.00000","0.01813","271.47449","0.00056","64.09814"
"22.10000","0.01821","272.76132","0.00057","64.40198"
"22.20000","0.01829","274.18262","0.00057","64.73756"
"22.30000","0.01837","275.34653","0.00057","65.01237"
"22.40000","0.01846","276.63849","0.00057","65.31742"
"22.50000","0.01854","278.36740","0.00058","65.72563"
"22.60000","0.01864","279.51187","0.00058","65.99586"
"22.70000","0.01872","281.10886","0.00058","66.37292"
"22.80000","0.01880","282.62845","0.00059","66.73171"
"22.90000","0.01888","284.04465","0.00059","67.06609"
"23.00000","0.01896","285.43707","0.00059","67.39486"
"23.10000","0.01906","286.72784","0.00059","67.69962"
"23.20000","0.01915","288.29736","0.00060","68.07021"
"23.30000","0.01923","289.58752","0.00060","68.37483"
"23.40000","0.01931","290.89154","0.00060","68.68272"
"23.50000","0.01939","292.55276","0.00060","69.07495"
"23.60000","0.01950","294.05615","0.00061","69.42992"
"23.70000","0.01958","295.83633","0.00061","69.85024"
"23.80000","0.01969","296.96082","0.00061","70.11575"
"23.90000","0.01977","298.65085","0.00062","70.51478"
"24.00000","0.01987","300.49255","0.00062","70.94963"
"24.10000","0.01996","301.74759","0.00062","71.24596"
"24.20000","0.02004","302.92676","0.00062","71.52437"
"24.30000","0.02012","304.51910","0.00063","71.90034"
"24.40000","0.02020","305.91791","0.00063","72.23061"
"24.50000","0.02028","307.50974","0.00063","72.60646"
"24.60000","0.02036","308.66986","0.00063","72.88038"
"24.70000","0.02044","309.89142","0.00064","73.16880"
"24.80000","0.02052","311.29739","0.00064","73.50077"
"24.90000","0.02060","312.77060","0.00064","73.84861"
"25.00000","0.02070","313.91302","0.00064","74.11835"
"25.10000","0.02079","315.36710","0.00065","74.46167"
"25.20000","0.02087","316.54303","0.00065","74.73932"
"25.30000","0.02095","318.30817","0.00065","75.15609"
"25.40000","0.02103","319.67630","0.00065","75.47913"
"25.50000","0.02111","320.96378","0.00066","75.78311"
"25.60000","0.02119","322.24268","0.00066","76.08508"
"25.70000","0.02127","323.65924","0.00066","76.41954"
"25.80000","0.02135","325.03479","0.00066","76.74432"
"25.90000","0.02143","326.31970","0.00067","77.04771"
"26.00000","0.02151","327.65842","0.00067","77.36379"
"26.10000","0.02159","328.95621","0.00067","77.67021"
"26.20000","0.02167","330.15021","0.00067","77.95213"
"26.30000","0.02175","331.93463","0.00068","78.37345"
"26.40000","0.02186","333.26385","0.00068","78.68729"
"26.50000","0.02194","334.91083","0.00068","79.07616"
"26.60000","0.02202","336.36334","0.00069","79.41912"
"26.70000","0.02210","337.92386","0.00069","79.78757"
"26.80000","0.02218","339.30295","0.00069","80.11319"
"26.90000","0.02227","340.73923","0.00069","80.45232"
"27.00000","0.02237","342.22220","0.00070","80.80246"
"27.10000","0.02245","343.40335","0.00070","81.08134"
"27.20000","0.02253","345.20261","0.00070","81.50616"
"27.30000","0.02261","346.36713","0.00070","81.78112"
"27.40000","0.02269","347.64249","0.00071","82.08225"
"27.50000","0.02277","349.17715","0.00071","82.44460"
"27.60000","0.02285","350.42090","0.00071","82.73827"
"27.70000","0.02293","351.78900","0.00071","83.06129"
"27.80000","0.02301","352.85599","0.00072","83.31322"
"27.90000","0.02306","354.63547","0.00072","83.73337"
"28.00000","0.02314","355.61575","0.00072","83.96483"
"28.10000","0.02322","356.49924","0.00072","84.17342"
"28.20000","0.02330","358.30148","0.00073","84.59895"
"28.30000","0.02338","359.73563","0.00073","84.93758"
"28.40000","0.02346","361.20352","0.00073","85.28416"
"28.50000","0.02354","362.42474","0.00073","85.57250"
"28.60000","0.02364","364.10153","0.00074","85.96841"
"28.70000","0.02373","365.51984","0.00074","86.30329"
"28.80000","0.02381","366.81097","0.00074","86.60814"
"28.90000","0.02389","368.44461","0.00074","86.99386"
"29.00000","0.02397","369.79010","0.00075","87.31155"
"29.10000","0.02405","371.14310","0.00075","87.63100"
"29.20000","0.02413","372.97913","0.00075","88.06451"
"29.30000","0.02424","374.49533","0.00075","88.42250"
"29.40000","0.02432","375.87375","0.00076","88.74796"
"29.50000","0.02440","377.32239","0.00076","89.09000"
"29.60000","0.02448","378.76590","0.00076","89.43083"
"29.70000","0.02459","380.58368","0.00077","89.86003"
"29.80000","0.02467","382.01410","0.00077","90.19777"
"29.90000","0.02478","383.72278","0.00077","90.60120"
"30.00000","0.02486","385.30493","0.00077","90.97477"
"30.10000","0.02494","387.14520","0.00078","91.40928"
"30.20000","0.02503","388.31128","0.00078","91.68460"
"30.30000","0.02513","389.78287","0.00078","92.03206"
"30.40000","0.02521","391.41495","0.00078","92.41741"
"30.50000","0.02529","392.49072","0.00079","92.67142"
"30.60000","0.02537","394.22415","0.00079","93.08070"
"30.70000","0.02545","395.66254","0.00079","93.42032"
"30.80000","0.02553","396.86243","0.00079","93.70362"
"30.90000","0.02561","398.29501","0.00080","94.04187"
"31.00000","0.02569","399.63931","0.00080","94.35928"
"31.10000","0.02577","401.29242","0.00080","94.74960"
"31.20000","0.02585","402.70197","0.00080","95.08241"
"31.30000","0.02593","404.10776","0.00081","95.41433"
"31.40000","0.02602","405.54547","0.00081","95.75378"
"31.50000","0.02610","407.05121","0.00081","96.10931"
"31.60000","0.02619","408.49908","0.00082","96.45116"
"31.70000","0.02626","409.76691","0.00082","96.75051"
"31.80000","0.02633","411.45990","0.00082","97.15025"
"31.90000","0.02641","412.71313","0.00082","97.44615"
"32.00000","0.02649","414.02652","0.00082","97.75626"
"32.10000","0.02657","414.98566","0.00083","97.98272"
"32.20000","0.02665","416.55759","0.00083","98.35387"
"32.30000","0.02673","418.42825","0.00083","98.79556"
"32.40000","0.02681","419.85614","0.00083","99.13270"
"32.50000","0.02692","421.42676","0.00084","99.50353"
"32.60000","0.02700","422.79218","0.00084","99.82593"
"32.70000","0.02708","424.46008","0.00084","100.21973"
"32.80000","0.02716","425.99860","0.00085","100.58300"
"32.90000","0.02726","427.52893","0.00085","100.94433"
"33.00000","0.02735","429.02264","0.00085","101.29700"
"33.10000","0.02743","430.52988","0.00085","101.65289"
"33.20000","0.02753","432.22205","0.00086","102.05242"
"33.30000","0.02759","433.93030","0.00086","102.45576"
"33.40000","0.02769","435.05054","0.00086","102.72026"
"33.50000","0.02778","436.54135","0.00087","103.07226"
"33.60000","0.02786","438.29422","0.00087","103.48613"
"33.70000","0.02794","439.46350","0.00087","103.76221"
"33.80000","0.02802","440.63739","0.00087","104.03938"
"33.90000","0.02808","442.68253","0.00087","104.52225"
"34.00000","0.02815","443.43100","0.00088","104.69898"
"34.10000","0.02823","445.18658","0.00088","105.11349"
"34.20000","0.02831","446.44876","0.00088","105.41151"
"34.30000","0.02839","447.94971","0.00088","105.76590"
"34.40000","0.02847","449.42331","0.00089","106.11383"
"34.50000","0.02855","451.08176","0.00089","106.50541"
"34.60000","0.02863","452.21439","0.00089","106.77283"
"34.70000","0.02871","453.75012","0.00089","107.13544"
"34.80000","0.02879","455.06476","0.00090","107.44584"
"34.90000","0.02887","456.54437","0.00090","107.79520"
"35.00000","0.02898","458.04031","0.00090","108.14840"
"35.10000","0.02906","459.61523","0.00091","108.52026"
"35.20000","0.02914","461.05780","0.00091","108.86086"
"35.30000","0.02922","462.59836","0.00091","109.22461"
"35.40000","0.02930","464.43423","0.00091","109.65808"
"35.50000","0.02940","466.04401","0.00092","110.03816"
"35.60000","0.02949","467.31885","0.00092","110.33916"
"35.70000","0.02957","469.14780","0.00092","110.77100"
"35.80000","0.02965","470.65756","0.00092","111.12747"
"35.90000","0.02976","472.31723","0.00093","111.51934"
"36.00000","0.02984","473.71588","0.00093","111.84958"
"36.10000","0.02995","475.97803","0.00093","112.38370"
"36.20000","0.03003","477.65970","0.00094","112.78075"
"36.30000","0.03011","478.80276","0.00094","113.05064"
"36.40000","0.03019","480.59732","0.00094","113.47436"
"36.50000","0.03027","482.02817","0.00094","113.81220"
"36.60000","0.03037","483.44559","0.00095","114.14687"
"36.70000","0.03046","485.09009","0.00095","114.53516"
"36.80000","0.03054","486.31778","0.00095","114.82503"
"36.90000","0.03062","487.93433","0.00095","115.20671"
"37.00000","0.03070","489.40372","0.00096","115.55365"
"37.10000","0.03078","490.74185","0.00096","115.86960"
"37.20000","0.03086","492.18652","0.00096","116.21070"
"37.30000","0.03094","493.90710","0.00096","116.61695"
"37.40000","0.03102","495.26041","0.00097","116.93648"
"37.50000","0.03110","496.70181","0.00097","117.27681"
"37.60000","0.03118","498.02679","0.00097","117.58965"
"37.70000","0.03126","499.46158","0.00097","117.92842"
"37.80000","0.03134","500.65616","0.00098","118.21047"
"37.90000","0.03144","502.57272","0.00098","118.66299"
"38.00000","0.03152","504.02213","0.00098","119.00522"
"38.10000","0.03160","505.58545","0.00098","119.37434"
"38.20000","0.03166","506.83435","0.00099","119.66921"
"38.30000","0.03174","508.05466","0.00099","119.95734"
"38.40000","0.03182","509.60355","0.00099","120.32305"
"38.50000","0.03190","511.02988","0.00099","120.65983"
"38.60000","0.03198","512.76624","0.00100","121.06980"
"38.70000","0.03209","514.12482","0.00100","121.39057"
"38.80000","0.03217","515.65143","0.00100","121.75102"
"38.90000","0.03225","517.26770","0.00100","122.13264"
"39.00000","0.03236","518.84021","0.00101","122.50393"
"39.10000","0.03244","520.25922","0.00101","122.83897"
"39.20000","0.03252","522.08923","0.00101","123.27106"
"39.30000","0.03260","523.58911","0.00102","123.62520"
"39.40000","0.03268","525.26459","0.00102","124.02080"
"39.50000","0.03277","526.88336","0.00102","124.40301"
"39.60000","0.03287","527.93286","0.00102","124.65081"
"39.70000","0.03295","529.55450","0.00103","125.03370"
"39.80000","0.03303","530.75922","0.00103","125.31814"
"39.90000","0.03311","532.55975","0.00103","125.74327"
"40.00000","0.03316","534.00446","0.00103","126.08438"
"40.10000","0.03324","535.21405","0.00104","126.36998"
"40.20000","0.03332","536.69287","0.00104","126.71915"
"40.30000","0.03340","537.97815","0.00104","127.02261"
"40.40000","0.03348","539.42914","0.00104","127.36520"
"40.50000","0.03356","540.93677","0.00105","127.72118"
"40.60000","0.03364","542.52985","0.00105","128.09732"
"40.70000","0.03372","544.21222","0.00105","128.49454"
"40.80000","0.03380","545.59918","0.00105","128.82202"
"40.90000","0.03388","547.27045","0.00106","129.21663"
"41.00000","0.03396","548.62378","0.00106","129.53616"
"41.10000","0.03404","550.48035","0.00106","129.97452"
"41.20000","0.03414","551.87921","0.00106","130.30481"
"41.30000","0.03423","553.66663","0.00107","130.72684"
"41.40000","0.03431","555.16370","0.00107","131.08031"
"41.50000","0.03439","556.61292","0.00107","131.42249"
"41.60000","0.03447","558.38416","0.00107","131.84070"
"41.70000","0.03455","559.72168","0.00108","132.15649"
"41.80000","0.03466","561.52185","0.00108","132.58154"
"41.90000","0.03474","562.99500","0.00108","132.92937"
"42.00000","0.03482","564.69452","0.00108","133.33064"
"42.10000","0.03493","566.58014","0.00109","133.77586"
"42.20000","0.03502","568.52582","0.00109","134.23526"
"42.30000","0.03512","570.17926","0.00109","134.62566"
"42.40000","0.03520","572.12482","0.00110","135.08502"
"42.50000","0.03528","573.40723","0.00110","135.38782"
"42.60000","0.03536","575.04010","0.00110","135.77335"
"42.70000","0.03544","576.60077","0.00110","136.14185"
"42.80000","0.03554","578.14880","0.00111","136.50735"
"42.90000","0.03563","579.66437","0.00111","136.86519"
"43.00000","0.03571","581.25305","0.00111","137.24030"
"43.10000","0.03579","582.92871","0.00111","137.63594"
"43.20000","0.03587","584.25830","0.00112","137.94987"
"43.30000","0.03595","586.02148","0.00112","138.36618"
"43.40000","0.03603","587.65363","0.00112","138.75154"
"43.50000","0.03611","589.24255","0.00112","139.12671"
"43.60000","0.03619","590.61462","0.00113","139.45067"
"43.70000","0.03627","591.98450","0.00113","139.77411"
"43.80000","0.03635","593.71503","0.00113","140.18271"
"43.90000","0.03643","595.23859","0.00113","140.54243"
"44.00000","0.03651","596.75458","0.00114","140.90038"
"44.10000","0.03659","598.29010","0.00114","141.26294"
"44.20000","0.03667","599.51990","0.00114","141.55330"
"44.30000","0.03675","601.47064","0.00114","142.01390"
"44.40000","0.03683","602.63843","0.00115","142.28963"
"44.50000","0.03691","604.08026","0.00115","142.63005"
"44.60000","0.03699","605.60687","0.00115","142.99051"
"44.70000","0.03707","607.24786","0.00115","143.37796"
"44.80000","0.03715","609.13733","0.00116","143.82408"
"44.90000","0.03723","610.43585","0.00116","144.13068"
"45.00000","0.03734","611.93372","0.00116","144.48434"
"45.10000","0.03742","613.66980","0.00117","144.89426"
"45.20000","0.03750","615.61212","0.00117","145.35286"
"45.30000","0.03761","617.17609","0.00117","145.72212"
"45.40000","0.03769","618.85492","0.00117","146.11852"
"45.50000","0.03777","620.18811","0.00118","146.43329"
"45.60000","0.03785","621.68677","0.00118","146.78714"
"45.70000","0.03793","623.11420","0.00118","147.12418"
"45.80000","0.03801","624.81439","0.00118","147.52562"
"45.90000","0.03809","626.12946","0.00119","147.83612"
"46.00000","0.03817","627.83350","0.00119","148.23845"
"46.10000","0.03825","629.64551","0.00119","148.66629"
"46.20000","0.03833","630.75580","0.00119","148.92845"
"46.30000","0.03841","632.08734","0.00120","149.24284"
"46.40000","0.03848","633.03455","0.00120","149.46648"
"46.50000","0.03854","634.47498","0.00120","149.80658"
"46.60000","0.03865","636.24719","0.00120","150.22502"
"46.70000","0.03873","637.83160","0.00121","150.59912"
"46.80000","0.03881","639.38116","0.00121","150.96500"
"46.90000","0.03889","641.02679","0.00121","151.35355"
"47.00000","0.03897","642.62207","0.00121","151.73021"
"47.10000","0.03905","644.23077","0.00122","152.11003"
"47.20000","0.03913","645.77783","0.00122","152.47531"
"47.30000","0.03921","647.13940","0.00122","152.79680"
"47.40000","0.03929","649.12408","0.00122","153.26540"
"47.50000","0.03940","650.78284","0.00123","153.65704"
"47.60000","0.03948","652.00360","0.00123","153.94528"
"47.70000","0.03956","653.75000","0.00123","154.35764"
"47.80000","0.03964","656.04669","0.00123","154.89990"
"47.90000","0.03972","656.88739","0.00124","155.09840"
"48.00000","0.03983","658.59955","0.00124","155.50267"
"48.10000","0.03991","660.59595","0.00124","155.97403"
"48.20000","0.04001","661.98718","0.00125","156.30252"
"48.30000","0.04010","663.99652","0.00125","156.77695"
"48.40000","0.04021","665.89636","0.00125","157.22552"
"48.50000","0.04029","667.43915","0.00125","157.58980"
"48.60000","0.04037","669.00824","0.00126","157.96027"
"48.70000","0.04045","670.63379","0.00126","158.34409"
"48.80000","0.04053","672.01465","0.00126","158.67012"
"48.90000","0.04061","673.58075","0.00126","159.03989"
"49.00000","0.04069","675.16913","0.00127","159.41493"
"49.10000","0.04077","676.69342","0.00127","159.77483"
"49.20000","0.04087","678.54272","0.00127","160.21147"
"49.30000","0.04096","679.98315","0.00128","160.55157"
"49.40000","0.04104","681.47516","0.00128","160.90385"
"49.50000","0.04112","683.30304","0.00128","161.33543"
"49.60000","0.04120","684.73395","0.00128","161.67328"
"49.70000","0.04128","686.30798","0.00129","162.04494"
"49.80000","0.04136","688.02789","0.00129","162.45102"
"49.90000","0.04144","689.79889","0.00129","162.86917"
"50.00000","0.04152","690.88373","0.00129","163.12532"
"50.10000","0.04160","692.58362","0.00130","163.52667"
"50.20000","0.04168","694.34247","0.00130","163.94196"
"50.30000","0.04176","695.93365","0.00130","164.31766"
"50.40000","0.04184","697.39117","0.00130","164.66179"
"50.50000","0.04192","699.02106","0.00131","165.04663"
"50.60000","0.04200","700.53400","0.00131","165.40385"
"50.70000","0.04208","701.68604","0.00131","165.67586"
"50.80000","0.04216","703.24780","0.00131","166.04462"
"50.90000","0.04224","705.06927","0.00132","166.47469"
"51.00000","0.04232","706.57739","0.00132","166.83076"
"51.10000","0.04240","708.13086","0.00132","167.19756"
"51.20000","0.04251","710.00427","0.00132","167.63989"
"51.30000","0.04259","711.88409","0.00133","168.08374"
"51.40000","0.04270","713.75873","0.00133","168.52635"
"51.50000","0.04278","715.43237","0.00133","168.92152"
"51.60000","0.04286","716.81085","0.00133","169.24699"
"51.70000","0.04294","718.32037","0.00134","169.60341"
"51.80000","0.04302","719.97864","0.00134","169.99495"
"51.90000","0.04310","721.53864","0.00134","170.36328"
"52.00000","0.04318","722.98901","0.00134","170.70573"
"52.10000","0.04326","724.56250","0.00135","171.07726"
"52.20000","0.04334","726.05750","0.00135","171.43024"
"52.30000","0.04342","727.53436","0.00135","171.77893"
"52.40000","0.04350","728.79382","0.00135","172.07631"
"52.50000","0.04355","730.19189","0.00136","172.40642"
"52.60000","0.04363","731.57892","0.00136","172.73390"
"52.70000","0.04371","733.32794","0.00136","173.14687"
"52.80000","0.04380","735.04028","0.00136","173.55116"
"52.90000","0.04388","736.59778","0.00137","173.91891"
"53.00000","0.04398","738.17059","0.00137","174.29027"
"53.10000","0.04406","739.97632","0.00137","174.71663"
"53.20000","0.04414","741.59473","0.00137","175.09874"
"53.30000","0.04422","743.00488","0.00138","175.43170"
"53.40000","0.04430","744.53162","0.00138","175.79218"
"53.50000","0.04438","746.32800","0.00138","176.21632"
"53.60000","0.04446","747.86029","0.00138","176.57811"
"53.70000","0.04454","749.53363","0.00139","176.97321"
"53.80000","0.04465","750.93933","0.00139","177.30511"
"53.90000","0.04473","752.76086","0.00139","177.73520"
"54.00000","0.04481","754.65735","0.00140","178.18297"
"54.10000","0.04489","756.29932","0.00140","178.57066"
"54.20000","0.04500","757.87439","0.00140","178.94255"
"54.30000","0.04508","759.65051","0.00140","179.36192"
"54.40000","0.04519","761.62860","0.00141","179.82896"
"54.50000","0.04528","763.49744","0.00141","180.27022"
"54.60000","0.04538","765.40497","0.00141","180.72061"
"54.70000","0.04546","767.05695","0.00142","181.11066"
"54.80000","0.04554","768.73773","0.00142","181.50751"
"54.90000","0.04562","770.03192","0.00142","181.81308"
"55.00000","0.04570","771.88275","0.00142","182.25009"
"55.10000","0.04578","773.57068","0.00143","182.64862"
"55.20000","0.04586","775.11127","0.00143","183.01237"
"55.30000","0.04594","776.88995","0.00143","183.43234"
"55.40000","0.04602","778.36371","0.00143","183.78030"
"55.50000","0.04610","780.07776","0.00144","184.18501"
"55.60000","0.04620","781.82233","0.00144","184.59692"
"55.70000","0.04629","783.53046","0.00144","185.00024"
"55.80000","0.04637","785.38434","0.00144","185.43796"
"55.90000","0.04645","787.05920","0.00145","185.83342"
"56.00000","0.04653","788.66107","0.00145","186.21164"
"56.10000","0.04661","790.08704","0.00145","186.54832"
"56.20000","0.04669","791.41797","0.00145","186.86256"
"56.30000","0.04674","792.74622","0.00146","187.17618"
"56.40000","0.04682","794.50348","0.00146","187.59109"
"56.50000","0.04690","795.70312","0.00146","187.87434"
"56.60000","0.04698","797.19733","0.00146","188.22714"
"56.70000","0.04706","799.08557","0.00147","188.67297"
"56.80000","0.04714","800.61340","0.00147","189.03371"
"56.90000","0.04724","802.70673","0.00147","189.52797"
"57.00000","0.04733","803.95471","0.00147","189.82263"
"57.10000","0.04741","805.78241","0.00148","190.25417"
"57.20000","0.04749","807.77631","0.00148","190.72495"
"57.30000","0.04760","809.52338","0.00148","191.13745"
"57.40000","0.04768","811.35779","0.00148","191.57057"
"57.50000","0.04776","813.08276","0.00149","191.97786"
"57.60000","0.04787","815.05139","0.00149","192.44267"
"57.70000","0.04795","816.40771","0.00149","192.76292"
"57.80000","0.04803","817.96899","0.00150","193.13156"
"57.90000","0.04811","819.65771","0.00150","193.53029"
"58.00000","0.04819","821.12036","0.00150","193.87563"
"58.10000","0.04827","823.05121","0.00150","194.33153"
"58.20000","0.04835","824.58112","0.00151","194.69275"
"58.30000","0.04843","826.11359","0.00151","195.05458"
"58.40000","0.04851","827.61615","0.00151","195.40936"
"58.50000","0.04859","829.02844","0.00151","195.74281"
"58.60000","0.04867","830.18420","0.00152","196.01570"
"58.70000","0.04872","832.10040","0.00152","196.46814"
"58.80000","0.04880","833.13574","0.00152","196.71260"
"58.90000","0.04888","834.98883","0.00152","197.15013"
"59.00000","0.04897","836.80536","0.00152","197.57903"
"59.10000","0.04904","838.07849","0.00153","197.87964"
"59.20000","0.04913","839.91663","0.00153","198.31364"
"59.30000","0.04921","840.89972","0.00153","198.54576"
"59.40000","0.04931","842.99261","0.00154","199.03992"
"59.50000","0.04939","844.77319","0.00154","199.46033"
"59.60000","0.04947","846.71210","0.00154","199.91812"
"59.70000","0.04955","847.89954","0.00154","200.19849"
"59.80000","0.04963","850.01941","0.00155","200.69902"
"59.90000","0.04974","851.75848","0.00155","201.10963"
"60.00000","0.04982","853.54810","0.00155","201.53218"
"60.10000","0.04990","854.68262","0.00155","201.80005"
"60.20000","0.04998","856.42261","0.00156","202.21088"
"60.30000","0.05006","858.42358","0.00156","202.68333"
"60.40000","0.05017","860.32758","0.00156","203.13289"
"60.50000","0.05025","862.17932","0.00156","203.57011"
"60.60000","0.05036","864.13025","0.00157","204.03075"
"60.70000","0.05044","866.04327","0.00157","204.48242"
"60.80000","0.05055","867.78662","0.00157","204.89406"
"60.90000","0.05063","869.60431","0.00158","205.32323"
"61.00000","0.05071","870.55182","0.00158","205.54695"
"61.10000","0.05079","872.78540","0.00158","206.07433"
"61.20000","0.05087","874.44086","0.00158","206.46519"
"61.30000","0.05095","875.97266","0.00159","206.82687"
"61.40000","0.05103","877.67645","0.00159","207.22916"
"61.50000","0.05111","879.26147","0.00159","207.60339"
"61.60000","0.05119","880.84143","0.00159","207.97644"
"61.70000","0.05127","882.45459","0.00160","208.35732"
"61.80000","0.05135","884.37262","0.00160","208.81020"
"61.90000","0.05143","885.86670","0.00160","209.16296"
"62.00000","0.05153","887.56757","0.00160","209.56456"
"62.10000","0.05162","889.05933","0.00161","209.91678"
"62.20000","0.05170","890.92462","0.00161","210.35719"
"62.30000","0.05178","892.64301","0.00161","210.76292"
"62.40000","0.05186","894.08795","0.00161","211.10410"
"62.50000","0.05194","895.62891","0.00162","211.46793"
"62.60000","0.05202","897.56775","0.00162","211.92570"
"62.70000","0.05210","899.22894","0.00162","212.31793"
"62.80000","0.05218","900.10150","0.00162","212.52396"
"62.90000","0.05224","902.01001","0.00163","212.97458"
"63.00000","0.05234","903.62354","0.00163","213.35555"
"63.10000","0.05242","905.22253","0.00163","213.73309"
"63.20000","0.05250","906.84015","0.00163","214.11502"
"63.30000","0.05258","908.88153","0.00164","214.59702"
"63.40000","0.05269","910.89215","0.00164","215.07175"
"63.50000","0.05277","912.42755","0.00164","215.43427"
"63.60000","0.05285","914.19623","0.00165","215.85188"
"63.70000","0.05294","916.20740","0.00165","216.32674"
"63.80000","0.05304","917.64264","0.00165","216.66562"
"63.90000","0.05312","919.19543","0.00165","217.03224"
"64.00000","0.05320","920.91608","0.00166","217.43851"
"64.10000","0.05328","922.55548","0.00166","217.82559"
"64.20000","0.05336","924.30396","0.00166","218.23842"
"64.30000","0.05344","925.72662","0.00166","218.57433"
"64.40000","0.05352","927.66235","0.00167","219.03137"
"64.50000","0.05360","929.39764","0.00167","219.44110"
"64.60000","0.05365","930.46722","0.00167","219.69363"
"64.70000","0.05373","932.11316","0.00167","220.08226"
"64.80000","0.05381","933.16034","0.00168","220.32951"
"64.90000","0.05389","935.00085","0.00168","220.76408"
"65.00000","0.05397","936.33167","0.00168","221.07829"
"65.10000","0.05405","938.40637","0.00168","221.56816"
"65.20000","0.05413","939.78119","0.00169","221.89278"
"65.30000","0.05421","941.39484","0.00169","222.27377"
"65.40000","0.05429","943.04828","0.00169","222.66417"
"65.50000","0.05438","944.62018","0.00169","223.03531"
"65.60000","0.05448","946.31183","0.00170","223.43472"
"65.70000","0.05456","947.89575","0.00170","223.80870"
"65.80000","0.05464","949.86707","0.00170","224.27415"
"65.90000","0.05472","951.69934","0.00170","224.70677"
"66.00000","0.05480","953.00171","0.00171","225.01428"
"66.10000","0.05488","955.12793","0.00171","225.51631"
"66.20000","0.05499","956.72009","0.00171","225.89223"
"66.30000","0.05507","958.83246","0.00172","226.39099"
"66.40000","0.05515","960.18713","0.00172","226.71085"
"66.50000","0.05525","962.34467","0.00172","227.22026"
"66.60000","0.05534","964.16504","0.00172","227.65007"
"66.70000","0.05545","966.14429","0.00173","228.11739"
"66.80000","0.05553","968.09027","0.00173","228.57686"
"66.90000","0.05561","969.63263","0.00173","228.94102"
"67.00000","0.05569","971.46527","0.00173","229.37373"
"67.10000","0.05577","972.72961","0.00174","229.67226"
"67.20000","0.05587","974.63300","0.00174","230.12167"
"67.30000","0.05596","976.33282","0.00174","230.52301"
"67.40000","0.05604","977.91803","0.00175","230.89729"
"67.50000","0.05612","979.79791","0.00175","231.34116"
"67.60000","0.05620","981.64081","0.00175","231.77629"
"67.70000","0.05628","982.94263","0.00175","232.08366"
"67.80000","0.05636","984.84766","0.00176","232.53346"
"67.90000","0.05644","986.62872","0.00176","232.95399"
"68.00000","0.05652","987.97260","0.00176","233.27130"
"68.10000","0.05660","989.94580","0.00176","233.73720"
"68.20000","0.05668","991.51910","0.00177","234.10866"
"68.30000","0.05677","993.08032","0.00177","234.47728"
"68.40000","0.05684","994.73773","0.00177","234.86862"
"68.50000","0.05693","996.22302","0.00177","235.21931"
"68.60000","0.05700","997.84399","0.00178","235.60204"
"68.70000","0.05708","999.41260","0.00178","235.97241"
"68.80000","0.05716","1001.20941","0.00178","236.39665"
"68.90000","0.05724","1002.49677","0.00178","236.70061"
"69.00000","0.05732","1003.99561","0.00179","237.05450"
"69.10000","0.05740","1005.96442","0.00179","237.51936"
"69.20000","0.05748","1007.47150","0.00179","237.87520"
"69.30000","0.05756","1009.12537","0.00179","238.26570"
"69.40000","0.05765","1010.94794","0.00180","238.69603"
"69.50000","0.05775","1012.47308","0.00180","239.05614"
"69.60000","0.05783","1014.56818","0.00180","239.55081"
"69.70000","0.05791","1016.25623","0.00180","239.94937"
"69.80000","0.05801","1017.71008","0.00181","240.29265"
"69.90000","0.05810","1019.62146","0.00181","240.74394"
"70.00000","0.05818","1021.69293","0.00181","241.23305"
"70.10000","0.05828","1023.26788","0.00182","241.60490"
"70.20000","0.05837","1025.09009","0.00182","242.03514"
"70.30000","0.05844","1026.40149","0.00182","242.34479"
"70.40000","0.05853","1028.04541","0.00182","242.73293"
"70.50000","0.05861","1029.89319","0.00183","243.16920"
"70.60000","0.05869","1031.15845","0.00183","243.46796"
"70.70000","0.05876","1033.03589","0.00183","243.91124"
"70.80000","0.05882","1034.57703","0.00183","244.27512"
"70.90000","0.05890","1035.65063","0.00183","244.52861"
"71.00000","0.05898","1037.32922","0.00184","244.92494"
"71.10000","0.05906","1038.92627","0.00184","245.30202"
"71.20000","0.05914","1040.61133","0.00184","245.69989"
"71.30000","0.05922","1042.32202","0.00184","246.10379"
"71.40000","0.05930","1043.67871","0.00185","246.42413"
"71.50000","0.05938","1045.40393","0.00185","246.83147"
"71.60000","0.05946","1046.96301","0.00185","247.19958"
"71.70000","0.05954","1048.72815","0.00185","247.61635"
"71.80000","0.05962","1050.57239","0.00186","248.05180"
"71.90000","0.05973","1052.26758","0.00186","248.45206"
"72.00000","0.05981","1054.34705","0.00186","248.94304"
"72.10000","0.05989","1056.01672","0.00187","249.33727"
"72.20000","0.05997","1057.55750","0.00187","249.70107"
"72.30000","0.06005","1059.15735","0.00187","250.07881"
"72.40000","0.06016","1061.05530","0.00187","250.52693"
"72.50000","0.06024","1062.93201","0.00188","250.97005"
"72.60000","0.06032","1064.76160","0.00188","251.40202"
"72.70000","0.06043","1066.36365","0.00188","251.78029"
"72.80000","0.06051","1068.47083","0.00188","252.27782"
"72.90000","0.06062","1070.90417","0.00189","252.85236"
"73.00000","0.06070","1072.25452","0.00189","253.17119"
"73.10000","0.06078","1074.12256","0.00189","253.61226"
"73.20000","0.06086","1075.88757","0.00190","254.02899"
"73.30000","0.06094","1077.97644","0.00190","254.52220"
"73.40000","0.06103","1079.45142","0.00190","254.87045"
"73.50000","0.06112","1081.00562","0.00190","255.23743"
"73.60000","0.06121","1082.82300","0.00191","255.66653"
"73.70000","0.06129","1084.71790","0.00191","256.11392"
"73.80000","0.06137","1086.33374","0.00191","256.49545"
"73.90000","0.06145","1088.16284","0.00191","256.92734"
"74.00000","0.06153","1089.71240","0.00192","257.29318"
"74.10000","0.06161","1091.72998","0.00192","257.76956"
"74.20000","0.06169","1093.51440","0.00192","258.19089"
"74.30000","0.06177","1095.19153","0.00192","258.58688"
"74.40000","0.06185","1096.83618","0.00193","258.97519"
"74.50000","0.06193","1098.51196","0.00193","259.37088"
"74.60000","0.06201","1099.96570","0.00193","259.71411"
"74.70000","0.06211","1101.68970","0.00193","260.12115"
"74.80000","0.06218","1103.46606","0.00194","260.54059"
"74.90000","0.06226","1104.99109","0.00194","260.90067"
"75.00000","0.06233","1106.61792","0.00194","261.28476"
"75.10000","0.06241","1108.09814","0.00194","261.63428"
"75.14300","0.06260","647.22870","0.00195","152.81789"