File: samples/m5s6.csv
Time measurement,Displacement,Primary force measurement,Composite strain,Flexure stress
(s),(mm),(N),(mm/mm),(MPa)
"0.00000","0.00000","-0.37019","0.00000","-0.08741"
"0.12000","0.00000","0.23671","0.00000","0.05589"
"0.24000","0.00027","0.17094","0.00001","0.04036"
"0.36000","0.00027","2.06008","0.00001","0.48641"
"0.48000","0.00027","1.61213","0.00001","0.38064"
"0.60000","0.00027","1.81638","0.00001","0.42887"
"0.72000","0.00027","1.81338","0.00001","0.42816"
"0.84000","0.00040","2.54072","0.00001","0.59989"
"0.96000","0.00054","3.59200","0.00002","0.84811"
"1.08000","0.00067","4.56715","0.00002","1.07836"
"1.20000","0.00078","5.65123","0.00002","1.33432"
"1.32000","0.00088","6.65162","0.00003","1.57052"
"1.44000","0.00099","7.56243","0.00003","1.78557"
"1.56000","0.00110","8.50645","0.00003","2.00847"
"1.68000","0.00121","9.44547","0.00004","2.23018"
"1.80000","0.00130","10.21340","0.00004","2.41150"
"1.92000","0.00139","10.84548","0.00004","2.56074"
"2.04000","0.00150","11.89668","0.00005","2.80894"
"2.16000","0.00161","12.76363","0.00005","3.01364"
"2.28000","0.00169","14.03497","0.00005","3.31381"
"2.40000","0.00179","14.69948","0.00006","3.47071"
"2.52000","0.00190","16.13809","0.00006","3.81038"
"2.64000","0.00198","16.94346","0.00006","4.00054"
"2.76000","0.00209","17.94593","0.00007","4.23723"
"2.88000","0.00220","18.90214","0.00007","4.46301"
"3.00000","0.00230","20.03765","0.00007","4.73111"
"3.12000","0.00238","20.93741","0.00007","4.94355"
"3.24000","0.00249","21.79274","0.00008","5.14551"
"3.36000","0.00260","23.04407","0.00008","5.44096"
"3.48000","0.00271","23.96866","0.00008","5.65927"
"3.60000","0.00279","25.45935","0.00009","6.01123"
"3.72000","0.00289","26.36396","0.00009","6.22482"
"3.84000","0.00300","27.22002","0.00009","6.42695"
"3.96000","0.00311","28.80699","0.00010","6.80165"
"4.08000","0.00321","29.57274","0.00010","6.98245"
"4.20000","0.00332","30.82033","0.00010","7.27702"
"4.32000","0.00341","32.01294","0.00011","7.55861"
"4.44000","0.00351","33.28901","0.00011","7.85990"
"4.56000","0.00364","34.25071","0.00011","8.08697"
"4.68000","0.00375","35.50610","0.00012","8.38338"
"4.80000","0.00386","36.58472","0.00012","8.63806"
"4.92000","0.00396","37.73701","0.00012","8.91013"
"5.04000","0.00405","38.91309","0.00013","9.18781"
"5.16000","0.00415","39.83929","0.00013","9.40650"
"5.28000","0.00426","41.02013","0.00013","9.68531"
"5.40000","0.00436","41.87797","0.00014","9.88785"
"5.52000","0.00445","42.98234","0.00014","10.14861"
"5.64000","0.00455","44.19408","0.00014","10.43471"
"5.76000","0.00466","45.27037","0.00015","10.68884"
"5.88000","0.00474","46.45784","0.00015","10.96921"
"6.00000","0.00485","47.24076","0.00015","11.15407"
"6.12000","0.00496","48.27875","0.00015","11.39915"
"6.24000","0.00504","49.54259","0.00016","11.69755"
"6.36000","0.00514","50.41786","0.00016","11.90422"
"6.48000","0.00522","51.41833","0.00016","12.14044"
"6.60000","0.00531","52.15554","0.00017","12.31450"
"6.72000","0.00541","53.43896","0.00017","12.61753"
"6.84000","0.00552","54.59796","0.00017","12.89118"
"6.96000","0.00562","55.76794","0.00018","13.16743"
"7.08000","0.00571","56.98540","0.00018","13.45488"
"7.20000","0.00581","58.13274","0.00018","13.72579"
"7.32000","0.00592","59.64388","0.00018","14.08258"
"7.44000","0.00603","60.97205","0.00019","14.39618"
"7.56000","0.00613","61.84824","0.00019","14.60306"
"7.68000","0.00624","63.38637","0.00019","14.96623"
"7.80000","0.00635","64.29129","0.00020","15.17989"
"7.92000","0.00646","65.54346","0.00020","15.47554"
"8.04000","0.00654","66.71931","0.00020","15.75317"
"8.16000","0.00664","67.54623","0.00021","15.94842"
"8.28000","0.00675","69.12856","0.00021","16.32202"
"8.40000","0.00683","70.09129","0.00021","16.54933"
"8.52000","0.00691","71.18074","0.00022","16.80656"
"8.64000","0.00701","72.27883","0.00022","17.06583"
"8.76000","0.00710","73.25484","0.00022","17.29628"
"8.88000","0.00721","74.58454","0.00022","17.61024"
"9.00000","0.00731","75.42518","0.00023","17.80872"
"9.12000","0.00739","76.64578","0.00023","18.09692"
"9.24000","0.00750","77.67681","0.00023","18.34036"
"9.36000","0.00761","79.04649","0.00024","18.66375"
"9.48000","0.00769","80.10814","0.00024","18.91442"
"9.60000","0.00779","81.29286","0.00024","19.19415"
"9.72000","0.00790","82.61446","0.00025","19.50619"
"9.84000","0.00801","83.94314","0.00025","19.81991"
"9.96000","0.00812","85.46516","0.00025","20.17927"
"10.08000","0.00822","86.87872","0.00026","20.51303"
"10.20000","0.00833","87.97039","0.00026","20.77079"
"10.32000","0.00844","89.18029","0.00026","21.05646"
"10.44000","0.00854","90.78951","0.00027","21.43641"
"10.56000","0.00865","92.28188","0.00027","21.78877"
"10.68000","0.00876","93.30338","0.00027","22.02996"
"10.80000","0.00887","94.38438","0.00028","22.28520"
"10.92000","0.00895","95.87426","0.00028","22.63698"
"11.04000","0.00905","97.23629","0.00028","22.95857"
"11.16000","0.00916","98.47082","0.00029","23.25005"
"11.28000","0.00927","99.55570","0.00029","23.50621"
"11.40000","0.00935","100.97992","0.00029","23.84248"
"11.52000","0.00946","101.89622","0.00029","24.05883"
"11.64000","0.00956","103.41921","0.00030","24.41842"
"11.76000","0.00964","104.36047","0.00030","24.64067"
"11.88000","0.00975","106.00608","0.00030","25.02921"
"12.00000","0.00986","107.31894","0.00031","25.33919"
"12.12000","0.00995","108.57971","0.00031","25.63688"
"12.24000","0.01004","109.70792","0.00031","25.90326"
"12.36000","0.01015","111.09270","0.00032","26.23022"
"12.48000","0.01026","112.14672","0.00032","26.47909"
"12.60000","0.01034","113.25140","0.00032","26.73991"
"12.72000","0.01042","114.30070","0.00032","26.98767"
"12.84000","0.01053","115.81848","0.00033","27.34603"
"12.96000","0.01063","117.12586","0.00033","27.65472"
"13.08000","0.01074","118.42225","0.00033","27.96081"
"13.20000","0.01085","120.13753","0.00034","28.36580"
"13.32000","0.01096","121.42213","0.00034","28.66911"
"13.44000","0.01106","122.45674","0.00034","28.91339"
"13.56000","0.01114","123.80798","0.00035","29.23244"
"13.68000","0.01125","125.23481","0.00035","29.56933"
"13.80000","0.01136","126.91187","0.00035","29.96530"
"13.92000","0.01147","127.98364","0.00036","30.21836"
"14.04000","0.01154","129.17238","0.00036","30.49903"
"14.16000","0.01165","130.53784","0.00036","30.82143"
"14.28000","0.01175","131.84161","0.00037","31.12927"
"14.40000","0.01184","133.29475","0.00037","31.47237"
"14.52000","0.01193","134.16866","0.00037","31.67871"
"14.64000","0.01203","135.93770","0.00037","32.09640"
"14.76000","0.01211","136.73030","0.00038","32.28354"
"14.88000","0.01220","138.65747","0.00038","32.73857"
"15.00000","0.01229","139.67775","0.00038","32.97947"
"15.12000","0.01240","140.76057","0.00039","33.23513"
"15.24000","0.01251","142.09248","0.00039","33.54961"
"15.36000","0.01261","143.91261","0.00039","33.97937"
"15.48000","0.01270","145.26794","0.00040","34.29937"
"15.60000","0.01280","146.54832","0.00040","34.60168"
"15.72000","0.01291","147.96306","0.00040","34.93572"
"15.84000","0.01299","149.33527","0.00040","35.25971"
"15.96000","0.01310","150.64182","0.00041","35.56820"
"16.08000","0.01321","152.25320","0.00041","35.94867"
"16.20000","0.01331","153.70824","0.00041","36.29222"
"16.32000","0.01342","154.91217","0.00042","36.57648"
"16.44000","0.01353","156.58405","0.00042","36.97123"
"16.56000","0.01363","158.32025","0.00042","37.38117"
"16.68000","0.01375","159.84393","0.00043","37.74092"
"16.80000","0.01385","161.56503","0.00043","38.14730"
"16.92000","0.01396","162.92252","0.00043","38.46782"
"17.04000","0.01406","164.38077","0.00044","38.81212"
"17.16000","0.01417","165.88438","0.00044","39.16714"
"17.28000","0.01425","167.32037","0.00044","39.50620"
"17.40000","0.01436","168.82910","0.00045","39.86242"
"17.52000","0.01447","170.36739","0.00045","40.22563"
"17.64000","0.01454","171.53549","0.00045","40.50143"
"17.76000","0.01465","172.81635","0.00046","40.80386"
"17.88000","0.01476","174.46355","0.00046","41.19278"
"18.00000","0.01486","175.71526","0.00046","41.48832"
"18.12000","0.01495","176.79764","0.00047","41.74389"
"18.24000","0.01505","178.25748","0.00047","42.08857"
"18.36000","0.01513","179.73618","0.00047","42.43771"
"18.48000","0.01524","181.53368","0.00047","42.86211"
"18.60000","0.01535","182.49236","0.00048","43.08847"
"18.72000","0.01543","184.01036","0.00048","43.44689"
"18.84000","0.01554","185.67778","0.00048","43.84058"
"18.96000","0.01562","186.78990","0.00049","44.10317"
"19.08000","0.01572","187.99167","0.00049","44.38692"
"19.20000","0.01580","189.56470","0.00049","44.75833"
"19.32000","0.01591","191.25912","0.00050","45.15840"
"19.44000","0.01602","192.68301","0.00050","45.49460"
"19.56000","0.01613","194.08263","0.00050","45.82506"
"19.68000","0.01623","195.75661","0.00051","46.22031"
"19.80000","0.01634","197.31888","0.00051","46.58918"
"19.92000","0.01645","198.91267","0.00051","46.96549"
"20.04000","0.01655","200.26201","0.00052","47.28408"
"20.16000","0.01663","201.77841","0.00052","47.64212"
"20.28000","0.01674","203.46672","0.00052","48.04075"
"20.40000","0.01682","204.29156","0.00052","48.23550"
"20.52000","0.01693","205.91440","0.00053","48.61868"
"20.64000","0.01701","207.21405","0.00053","48.92554"
"20.76000","0.01712","208.69647","0.00053","49.27555"
"20.88000","0.01720","209.91000","0.00054","49.56208"
"21.00000","0.01730","211.47569","0.00054","49.93176"
"21.12000","0.01741","212.92537","0.00054","50.27404"
"21.24000","0.01749","214.07404","0.00054","50.54526"
"21.36000","0.01760","215.51614","0.00055","50.88575"
"21.48000","0.01771","217.04910","0.00055","51.24770"
"21.60000","0.01779","218.50990","0.00055","51.59261"
"21.72000","0.01789","219.83127","0.00056","51.90460"
"21.84000","0.01800","221.34276","0.00056","52.26148"
"21.96000","0.01811","223.04848","0.00056","52.66422"
"22.08000","0.01821","224.70975","0.00057","53.05647"
"22.20000","0.01829","225.99438","0.00057","53.35978"
"22.32000","0.01840","227.60094","0.00057","53.73911"
"22.44000","0.01851","229.00935","0.00058","54.07165"
"22.56000","0.01862","230.59142","0.00058","54.44519"
"22.68000","0.01872","232.09187","0.00058","54.79947"
"22.80000","0.01886","234.20076","0.00059","55.29740"
"22.92000","0.01896","236.02457","0.00059","55.72802"
"23.04000","0.01904","237.20595","0.00059","56.00696"
"23.16000","0.01915","238.72218","0.00060","56.36496"
"23.28000","0.01926","240.61266","0.00060","56.81132"
"23.40000","0.01937","241.97144","0.00060","57.13214"
"23.52000","0.01945","243.50902","0.00061","57.49518"
"23.64000","0.01955","244.66333","0.00061","57.76773"
"23.76000","0.01966","246.33492","0.00061","58.16241"
"23.88000","0.01974","247.56561","0.00061","58.45299"
"24.00000","0.01985","249.50328","0.00062","58.91049"
"24.12000","0.01996","250.55602","0.00062","59.15906"
"24.24000","0.02006","252.24797","0.00062","59.55854"
"24.36000","0.02014","253.84706","0.00063","59.93611"
"24.48000","0.02025","255.71909","0.00063","60.37811"
"24.60000","0.02036","256.92798","0.00063","60.66355"
"24.72000","0.02044","258.43579","0.00064","61.01956"
"24.84000","0.02054","259.97253","0.00064","61.38240"
"24.96000","0.02063","261.40652","0.00064","61.72098"
"25.08000","0.02073","262.97394","0.00065","62.09106"
"25.20000","0.02084","264.76959","0.00065","62.51504"
"25.32000","0.02095","266.62833","0.00065","62.95391"
"25.44000","0.02105","268.00870","0.00066","63.27983"
"25.56000","0.02116","269.60760","0.00066","63.65735"
"25.68000","0.02124","271.33047","0.00066","64.06413"
"25.80000","0.02135","272.98364","0.00066","64.45447"
"25.92000","0.02146","274.40967","0.00067","64.79117"
"26.04000","0.02156","275.59012","0.00067","65.06989"
"26.16000","0.02164","277.46890","0.00067","65.51349"
"26.28000","0.02175","279.18979","0.00068","65.91981"
"26.40000","0.02186","280.56705","0.00068","66.24500"
"26.52000","0.02194","281.99622","0.00068","66.58244"
"26.64000","0.02204","283.87711","0.00069","67.02654"
"26.76000","0.02213","285.29245","0.00069","67.36071"
"26.88000","0.02223","286.38358","0.00069","67.61834"
"27.00000","0.02231","287.83035","0.00069","67.95994"
"27.12000","0.02239","289.33148","0.00070","68.31438"
"27.24000","0.02250","291.02139","0.00070","68.71338"
"27.36000","0.02261","292.52078","0.00070","69.06741"
"27.48000","0.02269","293.87189","0.00071","69.38641"
"27.60000","0.02279","295.29257","0.00071","69.72186"
"27.72000","0.02290","297.00024","0.00071","70.12505"
"27.84000","0.02301","298.75555","0.00072","70.53951"
"27.96000","0.02311","300.27930","0.00072","70.89928"
"28.08000","0.02320","301.75787","0.00072","71.24838"
"28.20000","0.02330","303.39841","0.00073","71.63573"
"28.32000","0.02341","305.07678","0.00073","72.03201"
"28.44000","0.02352","306.75165","0.00073","72.42747"
"28.56000","0.02362","308.61398","0.00074","72.86719"
"28.68000","0.02373","310.52484","0.00074","73.31836"
"28.80000","0.02384","311.97354","0.00074","73.66042"
"28.92000","0.02397","314.06705","0.00075","74.15472"
"29.04000","0.02405","315.55841","0.00075","74.50684"
"29.16000","0.02416","316.89450","0.00075","74.82231"
"29.28000","0.02427","318.58096","0.00076","75.22050"
"29.40000","0.02435","320.45258","0.00076","75.66241"
"29.52000","0.02446","321.64618","0.00076","75.94423"
"29.64000","0.02456","323.20224","0.00076","76.31164"
"29.76000","0.02467","325.06885","0.00077","76.75237"
"29.88000","0.02475","326.58600","0.00077","77.11058"
"30.00000","0.02486","328.03278","0.00077","77.45218"
"30.12000","0.02496","329.35904","0.00078","77.76533"
"30.24000","0.02504","331.31918","0.00078","78.22813"
"30.36000","0.02515","332.70590","0.00078","78.55556"
"30.48000","0.02526","334.24811","0.00079","78.91969"
"30.60000","0.02534","335.65543","0.00079","79.25197"
"30.72000","0.02545","337.25443","0.00079","79.62952"
"30.84000","0.02555","338.93710","0.00080","80.02681"
"30.96000","0.02563","340.62225","0.00080","80.42470"
"31.08000","0.02571","341.98083","0.00080","80.74547"
"31.20000","0.02582","343.27606","0.00080","81.05128"
"31.32000","0.02590","345.06094","0.00081","81.47272"
"31.44000","0.02601","346.41513","0.00081","81.79246"
"31.56000","0.02612","347.98230","0.00081","82.16248"
"31.68000","0.02622","350.01657","0.00082","82.64280"
"31.80000","0.02633","351.70190","0.00082","83.04073"
"31.92000","0.02644","353.46677","0.00082","83.45743"
"32.04000","0.02654","355.06534","0.00083","83.83487"
"32.16000","0.02665","357.03525","0.00083","84.29999"
"32.28000","0.02676","358.54242","0.00083","84.65585"
"32.40000","0.02684","360.12869","0.00084","85.03038"
"32.52000","0.02695","361.73529","0.00084","85.40971"
"32.64000","0.02705","363.12170","0.00084","85.73707"
"32.76000","0.02713","364.92206","0.00085","86.16215"
"32.88000","0.02724","366.41629","0.00085","86.51495"
"33.00000","0.02732","368.07278","0.00085","86.90607"
"33.12000","0.02740","369.44382","0.00085","87.22978"
"33.24000","0.02751","371.13312","0.00086","87.62865"
"33.36000","0.02761","372.58542","0.00086","87.97155"
"33.48000","0.02770","374.43939","0.00086","88.40929"
"33.60000","0.02780","376.19864","0.00087","88.82468"
"33.72000","0.02788","377.65366","0.00087","89.16822"
"33.84000","0.02799","379.23801","0.00087","89.54230"
"33.96000","0.02810","381.08160","0.00088","89.97759"
"34.08000","0.02821","382.77811","0.00088","90.37816"
"34.20000","0.02831","384.40405","0.00088","90.76206"
"34.32000","0.02842","386.22949","0.00088","91.19307"
"34.44000","0.02850","387.98953","0.00089","91.60863"
"34.56000","0.02861","389.63235","0.00089","91.99652"
"34.68000","0.02871","391.17090","0.00089","92.35979"
"34.80000","0.02882","393.12454","0.00090","92.82107"
"34.92000","0.02893","394.76642","0.00090","93.20873"
"35.04000","0.02904","396.63562","0.00090","93.65007"
"35.16000","0.02917","398.57608","0.00091","94.10824"
"35.28000","0.02925","400.73712","0.00091","94.61848"
"35.40000","0.02936","402.06351","0.00091","94.93166"
"35.52000","0.02946","403.63773","0.00092","95.30334"
"35.64000","0.02954","405.49747","0.00092","95.74245"
"35.76000","0.02965","406.86517","0.00092","96.06538"
"35.88000","0.02976","408.57956","0.00093","96.47017"
"36.00000","0.02987","410.43689","0.00093","96.90871"
"36.12000","0.02995","412.14920","0.00093","97.31300"
"36.24000","0.03005","413.35071","0.00094","97.59669"
"36.36000","0.03016","415.30792","0.00094","98.05881"
"36.48000","0.03024","416.76691","0.00094","98.40329"
"36.60000","0.03035","418.73242","0.00095","98.86737"
"36.72000","0.03046","420.15656","0.00095","99.20363"
"36.84000","0.03056","421.87054","0.00095","99.60831"
"36.96000","0.03064","423.47046","0.00095","99.98608"
"37.08000","0.03072","424.71848","0.00096","100.28075"
"37.20000","0.03083","426.11047","0.00096","100.60941"
"37.32000","0.03092","427.88641","0.00096","101.02873"
"37.44000","0.03102","429.78482","0.00097","101.47697"
"37.56000","0.03112","431.38702","0.00097","101.85526"
"37.68000","0.03123","433.16763","0.00097","102.27569"
"37.80000","0.03134","435.02463","0.00098","102.71414"
"37.92000","0.03145","436.69351","0.00098","103.10818"
"38.04000","0.03155","438.61969","0.00098","103.56298"
"38.16000","0.03166","440.21094","0.00099","103.93869"
"38.28000","0.03175","441.75574","0.00099","104.30343"
"38.40000","0.03185","443.48520","0.00099","104.71178"
"38.52000","0.03196","445.56619","0.00100","105.20312"
"38.64000","0.03206","446.97318","0.00100","105.53532"
"38.76000","0.03214","448.59058","0.00100","105.91721"
"38.88000","0.03225","450.10889","0.00100","106.27570"
"39.00000","0.03233","451.54462","0.00101","106.61469"
"39.12000","0.03241","453.33920","0.00101","107.03841"
"39.24000","0.03249","454.63654","0.00101","107.34473"
"39.36000","0.03260","456.08673","0.00102","107.68714"
"39.48000","0.03271","458.08121","0.00102","108.15806"
"39.60000","0.03279","459.60532","0.00102","108.51791"
"39.72000","0.03289","461.33072","0.00102","108.92530"
"39.84000","0.03300","463.12622","0.00103","109.34924"
"39.96000","0.03311","464.73761","0.00103","109.72971"
"40.08000","0.03319","466.28253","0.00103","110.09448"
"40.20000","0.03329","468.08127","0.00104","110.51918"
"40.32000","0.03340","470.06741","0.00104","110.98814"
"40.44000","0.03351","471.86087","0.00104","111.41159"
"40.56000","0.03362","473.42999","0.00105","111.78207"
"40.68000","0.03372","475.28781","0.00105","112.22073"
"40.80000","0.03383","477.00638","0.00105","112.62650"
"40.92000","0.03394","479.06445","0.00106","113.11243"
"41.04000","0.03404","481.39886","0.00106","113.66361"
"41.16000","0.03415","483.18143","0.00106","114.08450"
"41.28000","0.03426","485.06638","0.00107","114.52956"
"41.40000","0.03437","486.59546","0.00107","114.89059"
"41.52000","0.03447","488.33923","0.00107","115.30231"
"41.64000","0.03455","490.06961","0.00108","115.71088"
"41.76000","0.03466","491.57230","0.00108","116.06567"
"41.88000","0.03477","493.66708","0.00108","116.56028"
"42.00000","0.03485","495.48816","0.00109","116.99026"
"42.12000","0.03496","496.78915","0.00109","117.29743"
"42.24000","0.03506","498.59973","0.00109","117.72493"
"42.36000","0.03514","500.40930","0.00109","118.15219"
"42.48000","0.03525","501.99741","0.00110","118.52716"
"42.60000","0.03536","503.72607","0.00110","118.93532"
"42.72000","0.03544","505.27161","0.00110","119.30023"
"42.84000","0.03554","507.04880","0.00111","119.71985"
"42.96000","0.03565","508.79190","0.00111","120.13142"
"43.08000","0.03573","510.62674","0.00111","120.56464"
"43.20000","0.03584","512.38416","0.00112","120.97958"
"43.32000","0.03592","514.00378","0.00112","121.36200"
"43.44000","0.03602","515.29102","0.00112","121.66592"
"43.56000","0.03611","516.90082","0.00112","122.04602"
"43.68000","0.03621","519.28339","0.00113","122.60857"
"43.80000","0.03632","520.63147","0.00113","122.92686"
"43.92000","0.03643","522.50281","0.00113","123.36871"
"44.04000","0.03654","524.44287","0.00114","123.82678"
"44.16000","0.03664","526.31226","0.00114","124.26817"
"44.28000","0.03675","528.24298","0.00114","124.72403"
"44.40000","0.03686","529.76880","0.00115","125.08429"
"44.52000","0.03694","531.69427","0.00115","125.53892"
"44.64000","0.03704","533.38519","0.00115","125.93816"
"44.76000","0.03715","535.29187","0.00116","126.38835"
"44.88000","0.03724","537.03674","0.00116","126.80034"
"45.00000","0.03734","538.57825","0.00116","127.16430"
"45.12000","0.03745","540.42889","0.00117","127.60126"
"45.24000","0.03753","541.74347","0.00117","127.91164"
"45.36000","0.03761","543.47491","0.00117","128.32047"
"45.48000","0.03771","545.06573","0.00117","128.69608"
"45.60000","0.03779","546.26501","0.00118","128.97923"
"45.72000","0.03790","548.55695","0.00118","129.52039"
"45.84000","0.03799","550.13226","0.00118","129.89233"
"45.96000","0.03809","552.08923","0.00119","130.35440"
"46.08000","0.03820","553.66864","0.00119","130.72731"
"46.20000","0.03830","555.14484","0.00119","131.07585"
"46.32000","0.03841","557.18896","0.00120","131.55850"
"46.44000","0.03851","559.06879","0.00120","132.00235"
"46.56000","0.03860","560.96899","0.00120","132.45100"
"46.68000","0.03871","562.87109","0.00121","132.90012"
"46.80000","0.03881","564.70074","0.00121","133.33211"
"46.92000","0.03892","566.60248","0.00121","133.78113"
"47.04000","0.03903","568.26605","0.00122","134.17392"
"47.16000","0.03913","570.46448","0.00122","134.69299"
"47.28000","0.03927","572.20227","0.00122","135.10330"
"47.40000","0.03935","574.40857","0.00123","135.62424"
"47.52000","0.03946","576.16626","0.00123","136.03925"
"47.64000","0.03956","577.91199","0.00123","136.45143"
"47.76000","0.03967","579.81226","0.00124","136.90012"
"47.88000","0.03975","581.72864","0.00124","137.35258"
"48.00000","0.03986","583.27826","0.00124","137.71848"
"48.12000","0.03996","585.12103","0.00124","138.15356"
"48.24000","0.04005","587.22070","0.00125","138.64932"
"48.36000","0.04015","588.73334","0.00125","139.00647"
"48.48000","0.04026","590.52362","0.00125","139.42918"
"48.60000","0.04034","592.24554","0.00126","139.83574"
"48.72000","0.04045","593.91077","0.00126","140.22893"
"48.84000","0.04055","596.06598","0.00126","140.73779"
"48.96000","0.04066","597.94714","0.00127","141.18196"
"49.08000","0.04074","599.66364","0.00127","141.58723"
"49.20000","0.04085","601.11676","0.00127","141.93034"
"49.32000","0.04093","602.66730","0.00127","142.29643"
"49.44000","0.04104","604.24072","0.00128","142.66794"
"49.56000","0.04114","606.23999","0.00128","143.13998"
"49.68000","0.04125","607.80731","0.00128","143.51006"
"49.80000","0.04134","609.76324","0.00129","143.97186"
"49.92000","0.04146","611.74774","0.00129","144.44043"
"50.04000","0.04154","613.87695","0.00129","144.94316"
"50.16000","0.04165","615.37299","0.00130","145.29639"
"50.28000","0.04176","617.11475","0.00130","145.70764"
"50.40000","0.04184","618.99194","0.00130","146.15086"
"50.52000","0.04195","620.61169","0.00131","146.53331"
"50.64000","0.04205","622.20392","0.00131","146.90926"
"50.76000","0.04215","624.27509","0.00131","147.39827"
"50.88000","0.04224","626.17181","0.00132","147.84612"
"51.00000","0.04235","627.82611","0.00132","148.23671"
"51.12000","0.04243","629.44427","0.00132","148.61877"
"51.24000","0.04254","630.88318","0.00132","148.95853"
"51.36000","0.04262","632.59491","0.00133","149.36269"
"51.48000","0.04270","634.29913","0.00133","149.76506"
"51.60000","0.04280","635.69489","0.00133","150.09462"
"51.72000","0.04291","637.53784","0.00134","150.52975"
"51.84000","0.04299","639.34705","0.00134","150.95694"
"51.96000","0.04310","641.34351","0.00134","151.42831"
"52.08000","0.04321","643.08484","0.00135","151.83946"
"52.20000","0.04331","645.18817","0.00135","152.33609"
"52.32000","0.04339","646.64801","0.00135","152.68077"
"52.44000","0.04350","648.14752","0.00135","153.03482"
"52.56000","0.04361","650.57880","0.00136","153.60887"
"52.68000","0.04371","652.47064","0.00136","154.05556"
"52.80000","0.04382","654.24280","0.00136","154.47398"
"52.92000","0.04390","656.34460","0.00137","154.97025"
"53.04000","0.04401","658.03125","0.00137","155.36848"
"53.16000","0.04412","659.83472","0.00137","155.79430"
"53.28000","0.04422","662.14777","0.00138","156.34044"
"53.40000","0.04436","664.46979","0.00138","156.88869"
"53.52000","0.04446","666.33051","0.00138","157.32803"
"53.64000","0.04457","668.26953","0.00139","157.78586"
"53.76000","0.04466","670.14362","0.00139","158.22835"
"53.88000","0.04476","671.88727","0.00139","158.64005"
"54.00000","0.04487","673.61676","0.00140","159.04840"
"54.12000","0.04495","675.69928","0.00140","159.54010"
"54.24000","0.04505","677.55878","0.00140","159.97914"
"54.36000","0.04516","679.24457","0.00141","160.37718"
"54.48000","0.04527","681.35297","0.00141","160.87500"
"54.60000","0.04535","683.19318","0.00141","161.30949"
"54.72000","0.04546","685.07690","0.00142","161.75426"
"54.84000","0.04556","687.00256","0.00142","162.20892"
"54.96000","0.04564","688.50946","0.00142","162.56473"
"55.08000","0.04575","690.46954","0.00142","163.02753"
"55.20000","0.04586","692.39124","0.00143","163.48126"
"55.32000","0.04594","694.01440","0.00143","163.86450"
"55.44000","0.04602","695.86450","0.00143","164.30133"
"55.56000","0.04612","697.68896","0.00144","164.73210"
"55.68000","0.04621","699.42188","0.00144","165.14127"
"55.80000","0.04631","701.26324","0.00144","165.57603"
"55.92000","0.04642","703.04614","0.00145","165.99699"
"56.04000","0.04653","704.85181","0.00145","166.42334"
"56.16000","0.04663","706.80457","0.00145","166.88440"
"56.28000","0.04674","708.79291","0.00146","167.35387"
"56.40000","0.04685","710.73724","0.00146","167.81296"
"56.52000","0.04696","712.76080","0.00146","168.29074"
"56.64000","0.04706","714.72687","0.00147","168.75494"
"56.76000","0.04714","716.71021","0.00147","169.22324"
"56.88000","0.04725","718.30731","0.00147","169.60033"
"57.00000","0.04735","720.38812","0.00147","170.09163"
"57.12000","0.04744","721.98877","0.00148","170.46956"
"57.24000","0.04755","723.62262","0.00148","170.85533"
"57.36000","0.04762","725.34039","0.00148","171.26091"
"57.48000","0.04771","726.95282","0.00149","171.64163"
"57.60000","0.04781","728.51630","0.00149","172.01079"
"57.72000","0.04789","730.46234","0.00149","172.47026"
"57.84000","0.04800","731.95453","0.00149","172.82259"
"57.96000","0.04811","733.86499","0.00150","173.27367"
"58.08000","0.04819","735.61627","0.00150","173.68716"
"58.20000","0.04829","737.17932","0.00150","174.05621"
"58.32000","0.04840","739.12012","0.00151","174.51447"
"58.44000","0.04851","741.25690","0.00151","175.01898"
"58.56000","0.04859","743.12280","0.00151","175.45955"
"58.68000","0.04870","744.91913","0.00152","175.88367"
"58.80000","0.04880","746.70831","0.00152","176.30612"
"58.92000","0.04891","748.74603","0.00152","176.78725"
"59.04000","0.04902","750.59503","0.00153","177.22382"
"59.16000","0.04912","752.93567","0.00153","177.77647"
"59.28000","0.04923","754.54590","0.00153","178.15666"
"59.40000","0.04934","756.59784","0.00154","178.64114"
"59.52000","0.04945","759.04327","0.00154","179.21854"
"59.64000","0.04955","761.02472","0.00154","179.68639"
"59.76000","0.04966","762.76660","0.00155","180.09766"
"59.88000","0.04976","765.02106","0.00155","180.62996"
"60.00000","0.04985","766.49390","0.00155","180.97772"
"60.12000","0.04996","768.43512","0.00156","181.43607"
"60.24000","0.05006","770.42371","0.00156","181.90559"
"60.36000","0.05014","771.77954","0.00156","182.22571"
"60.48000","0.05025","774.00031","0.00156","182.75006"
"60.60000","0.05036","775.63940","0.00157","183.13707"
"60.72000","0.05047","777.57190","0.00157","183.59335"
"60.84000","0.05054","779.28784","0.00157","183.99850"
"60.96000","0.05065","781.29785","0.00158","184.47310"
"61.08000","0.05076","783.07788","0.00158","184.89337"
"61.20000","0.05084","785.17999","0.00158","185.38971"
"61.32000","0.05095","786.82208","0.00159","185.77742"
"61.44000","0.05105","788.53809","0.00159","186.18259"
"61.56000","0.05113","790.54144","0.00159","186.65561"
"61.68000","0.05124","792.58093","0.00160","187.13716"
"61.80000","0.05132","794.35266","0.00160","187.55548"
"61.92000","0.05143","796.24347","0.00160","188.00192"
"62.04000","0.05155","798.68658","0.00161","188.57877"
"62.16000","0.05164","800.47522","0.00161","189.00108"
"62.28000","0.05175","802.18811","0.00161","189.40552"
"62.40000","0.05186","804.06146","0.00161","189.84784"
"62.52000","0.05196","806.15485","0.00162","190.34210"
"62.64000","0.05204","807.95355","0.00162","190.76680"
"62.76000","0.05215","809.78094","0.00162","191.19827"
"62.88000","0.05226","811.90906","0.00163","191.70074"
"63.00000","0.05234","813.78992","0.00163","192.14484"
"63.12000","0.05245","815.23230","0.00163","192.48540"
"63.24000","0.05255","817.23083","0.00164","192.95728"
"63.36000","0.05263","819.11047","0.00164","193.40108"
"63.48000","0.05271","820.74420","0.00164","193.78682"
"63.60000","0.05282","822.16223","0.00164","194.12163"
"63.72000","0.05290","824.00256","0.00165","194.55615"
"63.84000","0.05301","825.85809","0.00165","194.99426"
"63.96000","0.05309","827.67188","0.00165","195.42252"
"64.08000","0.05320","829.82520","0.00166","195.93094"
"64.20000","0.05330","831.58740","0.00166","196.34702"
"64.32000","0.05341","833.50391","0.00166","196.79953"
"64.44000","0.05349","835.13855","0.00167","197.18549"
"64.56000","0.05360","837.04095","0.00167","197.63466"
"64.68000","0.05371","838.72180","0.00167","198.03152"
"64.80000","0.05381","841.05560","0.00168","198.58257"
"64.92000","0.05392","843.04071","0.00168","199.05127"
"65.04000","0.05400","844.88104","0.00168","199.48579"
"65.16000","0.05411","846.76190","0.00168","199.92989"
"65.28000","0.05421","848.91022","0.00169","200.43712"
"65.40000","0.05432","850.89459","0.00169","200.90565"
"65.52000","0.05446","852.89319","0.00170","201.37755"
"65.64000","0.05456","855.22998","0.00170","201.92929"
"65.76000","0.05467","857.32080","0.00170","202.42296"
"65.88000","0.05475","859.08594","0.00171","202.83972"
"66.00000","0.05486","861.00751","0.00171","203.29343"
"66.12000","0.05496","863.10461","0.00171","203.78857"
"66.24000","0.05507","864.96686","0.00172","204.22827"
"66.36000","0.05515","866.68964","0.00172","204.63504"
"66.48000","0.05526","868.55444","0.00172","205.07535"
"66.60000","0.05537","870.56311","0.00172","205.54961"
"66.72000","0.05545","872.25067","0.00173","205.94806"
"66.84000","0.05555","873.96680","0.00173","206.35326"
"66.96000","0.05566","875.92194","0.00173","206.81490"
"67.08000","0.05574","878.04858","0.00174","207.31702"
"67.20000","0.05585","880.01843","0.00174","207.78212"
"67.32000","0.05596","881.81470","0.00174","208.20624"
"67.44000","0.05604","883.68884","0.00175","208.64874"
"67.56000","0.05614","885.49268","0.00175","209.07465"
"67.68000","0.05622","887.02069","0.00175","209.43542"
"67.80000","0.05630","888.91479","0.00175","209.88264"
"67.92000","0.05641","890.82159","0.00176","210.33287"
"68.04000","0.05652","893.03467","0.00176","210.85539"
"68.16000","0.05663","894.99634","0.00176","211.31857"
"68.28000","0.05673","896.93713","0.00177","211.77681"
"68.40000","0.05684","898.89362","0.00177","212.23875"
"68.52000","0.05695","901.13470","0.00177","212.76790"
"68.64000","0.05705","903.35040","0.00178","213.29106"
"68.76000","0.05716","905.19965","0.00178","213.72768"
"68.88000","0.05724","907.00153","0.00178","214.15312"
"69.00000","0.05735","909.23401","0.00179","214.68024"
"69.12000","0.05746","910.94629","0.00179","215.08453"
"69.24000","0.05754","912.62006","0.00179","215.47972"
"69.36000","0.05764","914.77002","0.00180","215.98735"
"69.48000","0.05774","916.51306","0.00180","216.39891"
"69.60000","0.05783","918.37415","0.00180","216.83833"
"69.72000","0.05791","920.03839","0.00180","217.23128"
"69.84000","0.05799","921.79694","0.00181","217.64648"
"69.96000","0.05810","923.75427","0.00181","218.10864"
"70.08000","0.05821","925.49890","0.00181","218.52057"
"70.20000","0.05831","927.69720","0.00182","219.03961"
"70.32000","0.05839","929.21283","0.00182","219.39746"
"70.44000","0.05850","931.26276","0.00182","219.88147"
"70.56000","0.05861","933.34998","0.00183","220.37428"
"70.68000","0.05869","935.14893","0.00183","220.79904"
"70.80000","0.05879","936.99487","0.00183","221.23489"
"70.92000","0.05890","939.11707","0.00183","221.73596"
"71.04000","0.05901","941.05310","0.00184","222.19308"
"71.16000","0.05912","942.79443","0.00184","222.60423"
"71.28000","0.05922","944.80042","0.00184","223.07787"
"71.40000","0.05933","947.32025","0.00185","223.67282"
"71.52000","0.05944","949.15295","0.00185","224.10555"
"71.64000","0.05954","951.27301","0.00185","224.60611"
"71.76000","0.05965","953.66278","0.00186","225.17036"
"71.88000","0.05976","955.54248","0.00186","225.61418"
"72.00000","0.05987","957.59045","0.00186","226.09773"
"72.12000","0.05995","959.60852","0.00187","226.57422"
"72.24000","0.06005","961.33954","0.00187","226.98294"
"72.36000","0.06016","963.56525","0.00187","227.50845"
"72.48000","0.06027","965.45398","0.00188","227.95441"
"72.60000","0.06035","967.26593","0.00188","228.38222"
"72.72000","0.06046","969.16937","0.00188","228.83165"
"72.84000","0.06056","971.16492","0.00189","229.30281"
"72.96000","0.06064","973.07507","0.00189","229.75383"
"73.08000","0.06075","974.78723","0.00189","230.15808"
"73.20000","0.06086","976.80670","0.00190","230.63490"
"73.32000","0.06094","978.80084","0.00190","231.10574"
"73.44000","0.06104","980.82202","0.00190","231.58296"
"73.56000","0.06115","982.61859","0.00190","232.00716"
"73.68000","0.06126","984.66827","0.00191","232.49110"
"73.80000","0.06134","986.82263","0.00191","232.99977"
"73.92000","0.06142","988.25861","0.00191","233.33882"
"74.04000","0.06153","990.35071","0.00192","233.83279"
"74.16000","0.06163","992.14539","0.00192","234.25653"
"74.28000","0.06174","994.40265","0.00192","234.78951"
"74.40000","0.06185","996.44006","0.00193","235.27055"
"74.52000","0.06196","998.74225","0.00193","235.81413"
"74.64000","0.06206","1000.68738","0.00193","236.27339"
"74.76000","0.06214","1002.54651","0.00194","236.71236"
"74.88000","0.06225","1004.49335","0.00194","237.17203"
"75.00000","0.06236","1006.16125","0.00194","237.56584"
"75.12000","0.06245","1008.31940","0.00194","238.07539"
"75.24000","0.06254","1010.30255","0.00195","238.54364"
"75.36000","0.06265","1012.10345","0.00195","238.96886"
"75.48000","0.06275","1013.95612","0.00195","239.40630"
"75.60000","0.06284","1016.05402","0.00196","239.90163"
"75.72000","0.06293","1017.73639","0.00196","240.29886"
"75.84000","0.06303","1019.76208","0.00196","240.77715"
"75.96000","0.06311","1021.18335","0.00197","241.11272"
"76.08000","0.06321","1023.12787","0.00197","241.57184"
"76.20000","0.06329","1025.05493","0.00197","242.02684"
"76.32000","0.06340","1027.21509","0.00197","242.53688"
"76.44000","0.06350","1029.02710","0.00198","242.96472"
"76.56000","0.06359","1030.87952","0.00198","243.40210"
"76.68000","0.06370","1033.07886","0.00198","243.92139"
"76.80000","0.06380","1034.76404","0.00199","244.31927"
"76.92000","0.06390","1036.69312","0.00199","244.77475"
"77.04000","0.06399","1038.82312","0.00199","245.27766"
"77.16000","0.06410","1040.91541","0.00200","245.77168"
"77.28000","0.06421","1043.07751","0.00200","246.28218"
"77.40000","0.06431","1044.66882","0.00200","246.65790"
"77.52000","0.06442","1046.84644","0.00201","247.17206"
"77.64000","0.06453","1048.86279","0.00201","247.64815"
"77.76000","0.06463","1051.26172","0.00201","248.21455"
"77.88000","0.06477","1053.27917","0.00202","248.69090"
"78.00000","0.06485","1055.01953","0.00202","249.10182"
"78.12000","0.06496","1057.16675","0.00202","249.60880"
"78.24000","0.06506","1059.10266","0.00203","250.06589"
"78.36000","0.06517","1061.15723","0.00203","250.55099"
"78.48000","0.06525","1063.49194","0.00203","251.10225"
"78.60000","0.06536","1065.47168","0.00204","251.56969"
"78.72000","0.06546","1067.33643","0.00204","252.00998"
"78.84000","0.06557","1069.16199","0.00204","252.44101"
"78.96000","0.06565","1071.57715","0.00204","253.01126"
"79.08000","0.06576","1072.89661","0.00205","253.32280"
"79.20000","0.06584","1075.04163","0.00205","253.82925"
"79.32000","0.06595","1076.96265","0.00205","254.28284"
"79.44000","0.06605","1079.03992","0.00206","254.77330"
"79.56000","0.06613","1080.82849","0.00206","255.19560"
"79.68000","0.06624","1082.85791","0.00206","255.67477"
"79.80000","0.06632","1084.53479","0.00207","256.07071"
"79.92000","0.06642","1086.15491","0.00207","256.45322"
"80.04000","0.06651","1087.95593","0.00207","256.87848"
"80.16000","0.06662","1089.98840","0.00207","257.35837"
"80.28000","0.06672","1092.21436","0.00208","257.88394"
"80.40000","0.06683","1094.33240","0.00208","258.38403"
"80.52000","0.06693","1096.53992","0.00208","258.90524"
"80.64000","0.06702","1098.35352","0.00209","259.33347"
"80.76000","0.06713","1100.79944","0.00209","259.91095"
"80.88000","0.06723","1102.80505","0.00209","260.38452"
"81.00000","0.06734","1104.87439","0.00210","260.87311"
"81.12000","0.06745","1106.95325","0.00210","261.36395"
"81.24000","0.06755","1108.98804","0.00210","261.84439"
"81.36000","0.06763","1110.72754","0.00211","262.25510"
"81.48000","0.06774","1112.67615","0.00211","262.71518"
"81.60000","0.06785","1114.91687","0.00211","263.24423"
"81.72000","0.06793","1116.47424","0.00212","263.61197"
"81.84000","0.06804","1118.65210","0.00212","264.12619"
"81.96000","0.06812","1119.94287","0.00212","264.43094"
"82.08000","0.06820","1121.90479","0.00212","264.89417"
"82.20000","0.06830","1123.78650","0.00213","265.33847"
"82.32000","0.06841","1125.82190","0.00213","265.81903"
"82.44000","0.06849","1127.68494","0.00213","266.25894"
"82.56000","0.06860","1129.64062","0.00214","266.72070"
"82.68000","0.06871","1131.52466","0.00214","267.16553"
"82.80000","0.06881","1133.60046","0.00214","267.65564"
"82.92000","0.06889","1135.34949","0.00215","268.06860"
"83.04000","0.06900","1137.67920","0.00215","268.61868"
"83.16000","0.06911","1139.44019","0.00215","269.03448"
"83.28000","0.06921","1141.64172","0.00216","269.55429"
"83.40000","0.06930","1143.65112","0.00216","270.02872"
"83.52000","0.06940","1145.85352","0.00216","270.54874"
"83.64000","0.06951","1147.56140","0.00216","270.95200"
"83.76000","0.06962","1149.55945","0.00217","271.42374"
"83.88000","0.06972","1151.82471","0.00217","271.95859"
"84.00000","0.06985","1154.00598","0.00218","272.47363"
"84.12000","0.06996","1156.43347","0.00218","273.04678"
"84.24000","0.07007","1158.50879","0.00218","273.53677"
"84.36000","0.07015","1160.46301","0.00218","273.99820"
"84.48000","0.07026","1162.28540","0.00219","274.42850"
"84.60000","0.07037","1164.38428","0.00219","274.92404"
"84.72000","0.07045","1166.29138","0.00219","275.37433"
"84.84000","0.07055","1168.25818","0.00220","275.83871"
"84.96000","0.07066","1170.17761","0.00220","276.29193"
"85.08000","0.07077","1172.12695","0.00220","276.75220"
"85.20000","0.07085","1174.41711","0.00221","277.29291"
"85.32000","0.07096","1176.34985","0.00221","277.74927"
"85.44000","0.07106","1178.04114","0.00221","278.14859"
"85.56000","0.07114","1180.23999","0.00222","278.66776"
"85.68000","0.07125","1182.11487","0.00222","279.11044"
"85.80000","0.07135","1184.21899","0.00222","279.60724"
"85.92000","0.07144","1186.32568","0.00222","280.10468"
"86.04000","0.07154","1188.11572","0.00223","280.52731"
"86.16000","0.07163","1190.24500","0.00223","281.03006"
"86.28000","0.07172","1191.99780","0.00223","281.44391"
"86.40000","0.07181","1194.00867","0.00224","281.91870"
"86.52000","0.07192","1195.87573","0.00224","282.35953"
"86.64000","0.07203","1198.45154","0.00224","282.96771"
"86.76000","0.07213","1200.53003","0.00225","283.45847"
"86.88000","0.07224","1202.87231","0.00225","284.01151"
"87.00000","0.07235","1205.01636","0.00225","284.51773"
"87.12000","0.07246","1207.18140","0.00226","285.02893"
"87.24000","0.07255","1209.19995","0.00226","285.50552"
"87.36000","0.07264","1210.98389","0.00226","285.92673"
"87.48000","0.07275","1213.00012","0.00227","286.40280"
"87.60000","0.07286","1215.07764","0.00227","286.89331"
"87.72000","0.07294","1216.93970","0.00227","287.33298"
"87.84000","0.07304","1218.56067","0.00227","287.71570"
"87.96000","0.07313","1220.58020","0.00228","288.19254"
"88.08000","0.07321","1222.32385","0.00228","288.60422"
"88.20000","0.07331","1224.42651","0.00228","289.10068"
"88.32000","0.07339","1225.99963","0.00229","289.47211"
"88.44000","0.07350","1228.19043","0.00229","289.98938"
"88.56000","0.07361","1230.23499","0.00229","290.47214"
"88.68000","0.07371","1232.17761","0.00230","290.93082"
"88.80000","0.07379","1234.31628","0.00230","291.43576"
"88.92000","0.07390","1236.06567","0.00230","291.84882"
"89.04000","0.07401","1237.96777","0.00230","292.29794"
"89.16000","0.07409","1240.37207","0.00231","292.86560"
"89.28000","0.07420","1242.22278","0.00231","293.30258"
"89.40000","0.07430","1244.24438","0.00231","293.77991"
"89.52000","0.07441","1246.41040","0.00232","294.29132"
"89.64000","0.07452","1248.45056","0.00232","294.77304"
"89.76000","0.07463","1250.49121","0.00232","295.25485"
"89.88000","0.07472","1252.80017","0.00233","295.80002"
"90.00000","0.07484","1254.47070","0.00233","296.19446"
"90.12000","0.07495","1256.92651","0.00233","296.77429"
"90.24000","0.07505","1259.16272","0.00234","297.30231"
"90.36000","0.07516","1261.40503","0.00234","297.83173"
"90.48000","0.07527","1263.45154","0.00234","298.31494"
"90.60000","0.07535","1265.43237","0.00235","298.78262"
"90.72000","0.07546","1267.07800","0.00235","299.17117"
"90.84000","0.07556","1269.47046","0.00235","299.73605"
"90.96000","0.07565","1271.29700","0.00236","300.16733"
"91.08000","0.07575","1273.24890","0.00236","300.62820"
"91.20000","0.07586","1275.12048","0.00236","301.07010"
"91.32000","0.07596","1277.14978","0.00237","301.54922"
"91.44000","0.07604","1279.16785","0.00237","302.02573"
"91.56000","0.07615","1281.29700","0.00237","302.52844"
"91.68000","0.07626","1283.25745","0.00237","302.99133"
"91.80000","0.07634","1285.37793","0.00238","303.49200"
"91.92000","0.07645","1287.24573","0.00238","303.93301"
"92.04000","0.07653","1288.86877","0.00238","304.31622"
"92.16000","0.07663","1290.81189","0.00239","304.77502"
"92.28000","0.07671","1292.88269","0.00239","305.26395"
"92.40000","0.07682","1294.70300","0.00239","305.69376"
"92.52000","0.07692","1296.86389","0.00240","306.20395"
"92.64000","0.07701","1298.90015","0.00240","306.68475"
"92.76000","0.07712","1301.33020","0.00240","307.25851"
"92.88000","0.07722","1303.34961","0.00240","307.73532"
"93.00000","0.07733","1305.20557","0.00241","308.17352"
"93.12000","0.07744","1307.68591","0.00241","308.75916"
"93.24000","0.07754","1309.69031","0.00241","309.23242"
"93.36000","0.07765","1311.96375","0.00242","309.76920"
"93.48000","0.07776","1313.92908","0.00242","310.23325"
"93.60000","0.07784","1315.88806","0.00242","310.69577"
"93.72000","0.07795","1318.28430","0.00243","311.26157"
"93.84000","0.07805","1320.33472","0.00243","311.74567"
"93.96000","0.07813","1322.45813","0.00243","312.24704"
"94.08000","0.07824","1324.16370","0.00244","312.64975"
"94.20000","0.07832","1326.12817","0.00244","313.11359"
"94.32000","0.07840","1327.99402","0.00244","313.55414"
"94.44000","0.07851","1329.70190","0.00244","313.95737"
"94.56000","0.07859","1331.88037","0.00245","314.47174"
"94.68000","0.07870","1333.97717","0.00245","314.96683"
"94.80000","0.07880","1335.80859","0.00245","315.39923"
"94.92000","0.07890","1338.08728","0.00246","315.93726"
"95.04000","0.07899","1339.63074","0.00246","316.30170"
"95.16000","0.07910","1342.14502","0.00246","316.89532"
"95.28000","0.07921","1344.10510","0.00247","317.35812"
"95.40000","0.07931","1346.53052","0.00247","317.93079"
"95.52000","0.07940","1348.39331","0.00247","318.37064"
"95.64000","0.07950","1350.44910","0.00248","318.85602"
"95.76000","0.07961","1352.46875","0.00248","319.33289"
"95.88000","0.07971","1354.70679","0.00248","319.86130"
"96.00000","0.07982","1356.86719","0.00249","320.37140"
"96.12000","0.07993","1359.13611","0.00249","320.90710"
"96.24000","0.08006","1361.39294","0.00249","321.43997"
"96.36000","0.08015","1363.50037","0.00250","321.93756"
"96.48000","0.08025","1365.62476","0.00250","322.43915"
"96.60000","0.08036","1367.75403","0.00250","322.94189"
"96.72000","0.08046","1369.77417","0.00251","323.41888"
"96.84000","0.08057","1371.89966","0.00251","323.92075"
"96.96000","0.08065","1373.71948","0.00251","324.35040"
"97.08000","0.08076","1375.98840","0.00251","324.88614"
"97.20000","0.08087","1377.84656","0.00252","325.32486"
"97.32000","0.08095","1379.86499","0.00252","325.80145"
"97.44000","0.08105","1382.10791","0.00252","326.33102"
"97.56000","0.08116","1383.97595","0.00253","326.77209"
"97.68000","0.08124","1385.68445","0.00253","327.17548"
"97.80000","0.08135","1387.88647","0.00253","327.69540"
"97.92000","0.08146","1389.83057","0.00254","328.15442"
"98.04000","0.08154","1391.67639","0.00254","328.59024"
"98.16000","0.08164","1393.67908","0.00254","329.06311"
"98.28000","0.08175","1395.63074","0.00255","329.52390"
"98.40000","0.08183","1397.71838","0.00255","330.01682"
"98.52000","0.08191","1399.50952","0.00255","330.43973"
"98.64000","0.08202","1401.59204","0.00255","330.93143"
"98.76000","0.08213","1403.69006","0.00256","331.42679"
"98.88000","0.08223","1405.56860","0.00256","331.87036"
"99.00000","0.08234","1408.23938","0.00256","332.50095"
"99.12000","0.08245","1410.42712","0.00257","333.01749"
"99.24000","0.08255","1412.42029","0.00257","333.48810"
"99.36000","0.08266","1414.86487","0.00257","334.06531"
"99.48000","0.08274","1416.98462","0.00258","334.56580"
"99.60000","0.08285","1419.04211","0.00258","335.05161"
"99.72000","0.08296","1420.92261","0.00258","335.49561"
"99.84000","0.08304","1422.95337","0.00259","335.97510"
"99.96000","0.08314","1424.85779","0.00259","336.42474"
"100.08000","0.08322","1426.74463","0.00259","336.87024"
"100.20000","0.08333","1428.63550","0.00260","337.31671"
"100.32000","0.08341","1430.30957","0.00260","337.71198"
"100.44000","0.08349","1432.32104","0.00260","338.18689"
"100.56000","0.08360","1434.37109","0.00260","338.67093"
"100.68000","0.08371","1436.05078","0.00261","339.06754"
"100.80000","0.08381","1438.32312","0.00261","339.60406"
"100.92000","0.08389","1440.45581","0.00261","340.10760"
"101.04000","0.08400","1442.35889","0.00262","340.55695"
"101.16000","0.08411","1444.63184","0.00262","341.09360"
"101.28000","0.08419","1446.38953","0.00262","341.50861"
"101.40000","0.08429","1448.39062","0.00263","341.98111"
"101.52000","0.08440","1450.79480","0.00263","342.54877"
"101.64000","0.08451","1452.85181","0.00263","343.03442"
"101.76000","0.08462","1454.82385","0.00264","343.50006"
"101.88000","0.08472","1456.97729","0.00264","344.00851"
"101.90700","0.08492","857.35980","0.00264","202.43216"